Workbook

Sheet Dashboard
A1: WBS DASHBOARD — PM QLKHCN
A3: Nguồn: wbs_khcn_platform_v1.0.md | Cập nhật các cột editable tại sheet WBS để dashboard tự tính.
A5: Tổng work package | D5: Hoàn thành | G5: Tiến độ trung bình
A6: =COUNTA(WBS!A5:A92) -> 88 | D6: =COUNTIF(WBS!N5:N92,"Done") -> 0 | G6: =IFERROR(AVERAGE(WBS!O5:O92),0) -> 0
A10: Nhóm WBS | B10: Số work package | D10: Trạng thái | E10: Số lượng
A11: 1 | B11: =COUNTIF(WBS!B5:B92,A11&"*") -> 8 | D11: Not Started | E11: =COUNTIF(WBS!N5:N92,D11) -> 88
A12: 2 | B12: =COUNTIF(WBS!B5:B92,A12&"*") -> 9 | D12: In Progress | E12: =COUNTIF(WBS!N5:N92,D12) -> 0
A13: 3 | B13: =COUNTIF(WBS!B5:B92,A13&"*") -> 15 | D13: Blocked | E13: =COUNTIF(WBS!N5:N92,D13) -> 0
A14: 4 | B14: =COUNTIF(WBS!B5:B92,A14&"*") -> 12 | D14: Done | E14: =COUNTIF(WBS!N5:N92,D14) -> 0
A15: 5 | B15: =COUNTIF(WBS!B5:B92,A15&"*") -> 5 | D15: Deferred | E15: =COUNTIF(WBS!N5:N92,D15) -> 0
A16: 6 | B16: =COUNTIF(WBS!B5:B92,A16&"*") -> 8
A17: 7 | B17: =COUNTIF(WBS!B5:B92,A17&"*") -> 6 | D17: Tổng effort (PD) | E17: =SUM(WBS!J5:J92) -> 0
A18: 8 | B18: =COUNTIF(WBS!B5:B92,A18&"*") -> 10 | D18: Gate đang mở | E18: =COUNTIF('Gates & Decisions'!F4:F8,"Open") -> 5
A19: 9 | B19: =COUNTIF(WBS!B5:B92,A19&"*") -> 15

Sheet WBS
A1: WORK BREAKDOWN STRUCTURE — PM QLKHCN
A2: Các cột Owner, Effort, Duration, Start, Status, % Complete và Notes có thể cập nhật để lập kế hoạch.
A4: WBS ID | B4: Nhóm WBS | C4: Work Package | D4: Đầu ra bàn giao | E4: Scope | F4: Truy vết BR/CAP/RD | G4: Phụ thuộc | H4: Điều kiện hoàn thành | I4: Owner | J4: Effort (person-day) | K4: Duration (workday) | L4: Planned Start | M4: Planned Finish | N4: Status | O4: % Complete | P4: Notes / Evidence
A5: 1.1 | B5: 1.0 — Quản trị dự án và khóa baseline | C5: Khởi động và cơ chế quản trị | D5: Project Charter, RACI, lịch họp, kênh báo cáo | E5: ALL | G5: — | H5: Sponsor/PO xác nhận cơ chế quản trị và đầu mối | M5: =IF(OR(L5="",K5=""),"",WORKDAY(L5,K5-1)) | N5: Not Started | O5: 0
A6: 1.2 | B6: 1.0 — Quản trị dự án và khóa baseline | C6: Chốt quyết định nhóm A | D6: Biên bản quyết định A1–A7 | E6: ALL | G6: 1.1 | H6: Mỗi mục có quyết định, owner và ngày hiệu lực | M6: =IF(OR(L6="",K6=""),"",WORKDAY(L6,K6-1)) | N6: Not Started | O6: 0
A7: 1.3 | B7: 1.0 — Quản trị dự án và khóa baseline | C7: Chốt quy tắc nghiệp vụ và lỗi nguồn | D7: Decision Log cho B1–B9, D1–D6 | E7: P1 | G7: 1.1 | H7: Không còn câu hỏi P0 chặn đặc tả Pha 1 | M7: =IF(OR(L7="",K7=""),"",WORKDAY(L7,K7-1)) | N7: Not Started | O7: 0
A8: 1.4 | B8: 1.0 — Quản trị dự án và khóa baseline | C8: Workshop NFR và tuân thủ | D8: NFR baseline cho C1–C5; tiêu chí đo | E8: ALL | G8: 1.1 | H8: Kiến trúc, bảo mật, tải và lưu trữ có ngưỡng được duyệt | M8: =IF(OR(L8="",K8=""),"",WORKDAY(L8,K8-1)) | N8: Not Started | O8: 0
A9: 1.5 | B9: 1.0 — Quản trị dự án và khóa baseline | C9: Khóa phạm vi và truy vết | D9: BRD/HLD baseline; scope statement; RTM | E9: ALL | G9: 1.2–1.4 | H9: BR-001–BR-021 có trạng thái và phạm vi rõ ràng | M9: =IF(OR(L9="",K9=""),"",WORKDAY(L9,K9-1)) | N9: Not Started | O9: 0
A10: 1.6 | B10: 1.0 — Quản trị dự án và khóa baseline | C10: Kế hoạch quản lý chất lượng | D10: Quality Plan, review gate, Definition of Done | E10: ALL | G10: 1.5 | H10: PM, BA, Tech Lead và QA Lead phê duyệt | M10: =IF(OR(L10="",K10=""),"",WORKDAY(L10,K10-1)) | N10: Not Started | O10: 0
A11: 1.7 | B11: 1.0 — Quản trị dự án và khóa baseline | C11: Kế hoạch release và thay đổi | D11: Release Plan, Change Control, Configuration Plan | E11: ALL | G11: 1.5 | H11: Có quy tắc version, rollback và phê duyệt thay đổi | M11: =IF(OR(L11="",K11=""),"",WORKDAY(L11,K11-1)) | N11: Not Started | O11: 0
A12: 1.8 | B12: 1.0 — Quản trị dự án và khóa baseline | C12: Quản lý tiến độ, rủi ro và báo cáo | D12: RAID Log, báo cáo định kỳ, biên bản gate | E12: ALL | G12: 1.1 | H12: Duy trì xuyên suốt; mọi rủi ro P0/P1 có owner | M12: =IF(OR(L12="",K12=""),"",WORKDAY(L12,K12-1)) | N12: Not Started | O12: 0
A13: 2.1 | B13: 2.0 — Phân tích chi tiết và thiết kế | C13: Catalogue yêu cầu chi tiết | D13: Catalogue REQ-001–REQ-063; cập nhật REQ-064–REQ-068 nếu AI được duyệt | E13: ALL | F13: BR-001–BR-021 | G13: 1.5 | H13: Mỗi REQ có nguồn, priority và acceptance criteria | M13: =IF(OR(L13="",K13=""),"",WORKDAY(L13,K13-1)) | N13: Not Started | O13: 0
A14: 2.2 | B14: 2.0 — Phân tích chi tiết và thiết kế | C14: Mô hình quy trình và business rules | D14: BPMN/flow, rule catalogue, ma trận trạng thái/cột mốc | E14: P1 | F14: BR-001–BR-003, BR-014 | G14: 1.3, 2.1 | H14: BA và nghiệp vụ walkthrough, xử lý hết lỗi critical | M14: =IF(OR(L14="",K14=""),"",WORKDAY(L14,K14-1)) | N14: Not Started | O14: 0
A15: 2.3 | B15: 2.0 — Phân tích chi tiết và thiết kế | C15: Thiết kế trải nghiệm người dùng | D15: Sitemap, wireframe, prototype, UI states | E15: P1 | F15: BR-004–BR-013, BR-016–BR-018 | G15: 2.1 | H15: Đại diện sáu nhóm người dùng xác nhận luồng chính | M15: =IF(OR(L15="",K15=""),"",WORKDAY(L15,K15-1)) | N15: Not Started | O15: 0
A16: 2.4 | B16: 2.0 — Phân tích chi tiết và thiết kế | C16: Thiết kế eForm và biểu mẫu | D16: Form catalogue, data dictionary, validation rules, mapping bước–form | E16: P1 | F16: BR-004, BR-005, BR-009 | G16: 2.1, 2.2 | H16: Mỗi bước Pha 1 có form/đầu vào/đầu ra xác định | M16: =IF(OR(L16="",K16=""),"",WORKDAY(L16,K16-1)) | N16: Not Started | O16: 0
A17: 2.5 | B17: 2.0 — Phân tích chi tiết và thiết kế | C17: Thiết kế dữ liệu và hồ sơ điện tử | D17: Logical data model, metadata, versioning, retention | E17: P1 | F17: BR-004, BR-006, BR-019 | G17: 1.4, 2.1 | H17: Data owner và kiến trúc sư phê duyệt | M17: =IF(OR(L17="",K17=""),"",WORKDAY(L17,K17-1)) | N17: Not Started | O17: 0
A18: 2.6 | B18: 2.0 — Phân tích chi tiết và thiết kế | C18: Thiết kế định danh và phân quyền | D18: Role-permission matrix, SSO/IAM flow, SoD rules | E18: P1 | F18: BR-007, BR-008, BR-010–BR-013, BR-020 | G18: 1.3, 1.4 | H18: Bao phủ sáu nhóm người dùng và negative access cases | M18: =IF(OR(L18="",K18=""),"",WORKDAY(L18,K18-1)) | N18: Not Started | O18: 0
A19: 2.7 | B19: 2.0 — Phân tích chi tiết và thiết kế | C19: Thiết kế tích hợp | D19: Interface catalogue, API/event/file contract, error/retry/reconcile | E19: ALL | F19: BR-015–BR-018, BR-020 | G19: 1.4, 2.1 | H19: Mỗi interface có owner hai phía và môi trường test | M19: =IF(OR(L19="",K19=""),"",WORKDAY(L19,K19-1)) | N19: Not Started | O19: 0
A20: 2.8 | B20: 2.0 — Phân tích chi tiết và thiết kế | C20: Thiết kế kiến trúc và triển khai | D20: LLD, deployment topology, observability, backup/restore | E20: ALL | F20: NFR baseline | G20: 1.4, 2.1, 2.7 | H20: Architecture Review phê duyệt, không còn issue critical | M20: =IF(OR(L20="",K20=""),"",WORKDAY(L20,K20-1)) | N20: Not Started | O20: 0
A21: 2.9 | B21: 2.0 — Phân tích chi tiết và thiết kế | C21: Chiến lược kiểm thử | D21: Master Test Plan, test levels, test data, UAT plan | E21: ALL | F21: Toàn bộ BR/AC | G21: 1.6, 2.1–2.8 | H21: QA Lead và PO phê duyệt độ phủ | M21: =IF(OR(L21="",K21=""),"",WORKDAY(L21,K21-1)) | N21: Not Started | O21: 0
A22: 3.1 | B22: 3.0 — Nền tảng và năng lực dùng chung | C22: Môi trường và CI/CD | D22: Dev/Test/UAT pipeline, quality gate, artifact repository | E22: P1 | F22: CON/NFR | G22: 2.8 | H22: Build, deploy và rollback tự động được kiểm chứng | M22: =IF(OR(L22="",K22=""),"",WORKDAY(L22,K22-1)) | N22: Not Started | O22: 0
A23: 3.2 | B23: 3.0 — Nền tảng và năng lực dùng chung | C23: Workflow runtime và cấu hình động | D23: Runtime, process deployment, rule/condition execution | E23: P1 | F23: BR-001, BR-002 | G23: 2.2, 3.1 | H23: Đạt AC-CAP-01, AC-CAP-02 trên luồng mẫu | M23: =IF(OR(L23="",K23=""),"",WORKDAY(L23,K23-1)) | N23: Not Started | O23: 0
A24: 3.3 | B24: 3.0 — Nền tảng và năng lực dùng chung | C24: Quản trị phiên bản quy trình | D24: Version lifecycle, effective dates, approval, history | E24: P1 | F24: BR-003 | G24: 2.2, 3.2 | H24: Đạt AC-CAP-03 | M24: =IF(OR(L24="",K24=""),"",WORKDAY(L24,K24-1)) | N24: Not Started | O24: 0
A25: 3.4 | B25: 3.0 — Nền tảng và năng lực dùng chung | C25: Hồ sơ điện tử và data services | D25: Case/dossier API, lifecycle, export, cross-stage persistence | E25: P1 | F25: BR-004 | G25: 2.5, 3.1 | H25: Đạt AC-CAP-04 | M25: =IF(OR(L25="",K25=""),"",WORKDAY(L25,K25-1)) | N25: Not Started | O25: 0
A26: 3.5 | B26: 3.0 — Nền tảng và năng lực dùng chung | C26: eForm runtime và form catalogue | D26: Form renderer, validation, versioned templates, mapping | E26: P1 | F26: BR-005 | G26: 2.4, 3.4 | H26: Đạt AC-CAP-05 | M26: =IF(OR(L26="",K26=""),"",WORKDAY(L26,K26-1)) | N26: Not Started | O26: 0
A27: 3.6 | B27: 3.0 — Nền tảng và năng lực dùng chung | C27: Quản lý tài liệu và kho lưu trữ | D27: Upload/download, metadata, search, Storage connector mẫu | E27: P1 | F27: BR-006, BR-015 | G27: 2.5, 2.7, 3.4 | H27: Đạt AC-CAP-06, AC-CAP-15 mức Pha 1 | M27: =IF(OR(L27="",K27=""),"",WORKDAY(L27,K27-1)) | N27: Not Started | O27: 0
A28: 3.7 | B28: 3.0 — Nền tảng và năng lực dùng chung | C28: My Tasks và work queue | D28: Danh sách việc, filter, claim/complete, role filtering | E28: P1 | F28: BR-007 | G28: 2.3, 2.6, 3.2 | H28: Đạt AC-CAP-07 | M28: =IF(OR(L28="",K28=""),"",WORKDAY(L28,K28-1)) | N28: Not Started | O28: 0
A29: 3.8 | B29: 3.0 — Nền tảng và năng lực dùng chung | C29: Ký duyệt và phê duyệt nhiều cấp | D29: Approval chain, reject/return, signature evidence | E29: P1 | F29: BR-008 | G29: 1.2, 2.6, 3.2 | H29: Đạt AC-CAP-08; hình thức ký theo A2 | M29: =IF(OR(L29="",K29=""),"",WORKDAY(L29,K29-1)) | N29: Not Started | O29: 0
A30: 3.9 | B30: 3.0 — Nền tảng và năng lực dùng chung | C30: Phiếu nhận xét và đánh giá | D30: Phiếu cấu trúc, lưu hồ sơ, xuất tệp | E30: P1 | F30: BR-009 | G30: 2.4, 3.5 | H30: Đạt AC-CAP-09 | M30: =IF(OR(L30="",K30=""),"",WORKDAY(L30,K30-1)) | N30: Not Started | O30: 0
A31: 3.1 | B31: 3.0 — Nền tảng và năng lực dùng chung | C31: Hội đồng động | D31: Council decision, membership, two-axis composition | E31: P1 | F31: BR-010 | G31: 2.6, 3.4 | H31: Đạt AC-CAP-10 | M31: =IF(OR(L31="",K31=""),"",WORKDAY(L31,K31-1)) | N31: Not Started | O31: 0
A32: 3.11 | B32: 3.0 — Nền tảng và năng lực dùng chung | C32: Phiên họp và biên bản | D32: Session, attendance, minutes, signing | E32: P1 | F32: BR-011 | G32: 3.8, 3.10 | H32: Đạt AC-CAP-11 | M32: =IF(OR(L32="",K32=""),"",WORKDAY(L32,K32-1)) | N32: Not Started | O32: 0
A33: 3.12 | B33: 3.0 — Nền tảng và năng lực dùng chung | C33: Nhập thay cấp Tập đoàn | D33: On-behalf-of action, paper reference, evidence | E33: P1 | F33: BR-012 | G33: 2.6, 3.4, 3.13 | H33: Đạt AC-CAP-12 | M33: =IF(OR(L33="",K33=""),"",WORKDAY(L33,K33-1)) | N33: Not Started | O33: 0
A34: 3.13 | B34: 3.0 — Nền tảng và năng lực dùng chung | C34: Audit trail và provenance | D34: Immutable audit, query/export, actor/proxy/version data | E34: P1 | F34: BR-019 | G34: 2.5, 3.1 | H34: Đạt AC-CAP-19 | M34: =IF(OR(L34="",K34=""),"",WORKDAY(L34,K34-1)) | N34: Not Started | O34: 0
... A51: 5.3 | B51: 5.0 — Giám sát và năng lực mức B tại Pha 1 | C51: Bức tranh thực hiện nhiệm vụ | D51: View sáu chiều; dữ liệu thật cho cột mốc, mô phỏng cho năm chiều còn lại | E51: P1 mức B | F51: BR-016, CAP-16 | G51: 3.4, 5.2 | H51: Đạt AC-CAP-16 | M51: =IF(OR(L51="",K51=""),"",WORKDAY(L51,K51-1)) | N51: Not Started | O51: 0
A52: 5.4 | B52: 5.0 — Giám sát và năng lực mức B tại Pha 1 | C52: Cảnh báo | D52: Cảnh báo workflow thật; tiến độ/dự toán mô phỏng | E52: P1 mức B | F52: BR-017, CAP-17 | G52: 5.3 | H52: Đạt AC-CAP-17 | M52: =IF(OR(L52="",K52=""),"",WORKDAY(L52,K52-1)) | N52: Not Started | O52: 0
A53: 5.5 | B53: 5.0 — Giám sát và năng lực mức B tại Pha 1 | C53: Dashboard tổng hợp | D53: Tầng 1–2 dữ liệu thật; tầng chi tiết theo dữ liệu 5.3 | E53: P1 mức B | F53: BR-018, CAP-18 | G53: 5.3, 5.4 | H53: Đạt AC-CAP-18 | M53: =IF(OR(L53="",K53=""),"",WORKDAY(L53,K53-1)) | N53: Not Started | O53: 0
A54: 6.1 | B54: 6.0 — Kiểm thử và nghiệm thu Pha 1 | C54: Unit/component test | D54: Automated test suite và coverage report | E54: P1 | G54: WBS 3.0–5.0 | H54: Không còn lỗi Sev-1/Sev-2; ngưỡng coverage theo Quality Plan | M54: =IF(OR(L54="",K54=""),"",WORKDAY(L54,K54-1)) | N54: Not Started | O54: 0
A55: 6.2 | B55: 6.0 — Kiểm thử và nghiệm thu Pha 1 | C55: Integration/contract test | D55: Contract test cho IAM, Storage, workflow và service boundary | E55: P1 | G55: 3.6, 3.15, 5.2 | H55: Positive, negative, retry và reconcile đạt | M55: =IF(OR(L55="",K55=""),"",WORKDAY(L55,K55-1)) | N55: Not Started | O55: 0
A56: 6.3 | B56: 6.0 — Kiểm thử và nghiệm thu Pha 1 | C56: System Integration Test | D56: SIT suite cho toàn bộ Pha 1 | E56: P1 | G56: WBS 3.0–5.0 | H56: Exit criteria trong Master Test Plan đạt | M56: =IF(OR(L56="",K56=""),"",WORKDAY(L56,K56-1)) | N56: Not Started | O56: 0
A57: 6.4 | B57: 6.0 — Kiểm thử và nghiệm thu Pha 1 | C57: Security và privacy test | D57: SAST/DAST, authorization, audit, privacy evidence | E57: P1 | G57: 3.13, 3.15, WBS 4.0 | H57: Không còn lỗ hổng critical/high chưa được chấp nhận | M57: =IF(OR(L57="",K57=""),"",WORKDAY(L57,K57-1)) | N57: Not Started | O57: 0
...

Sheet Milestones
A1: MILESTONES & QUALITY GATES
A3: Milestone | B3: Kết quả | C3: Work package bắt buộc | D3: Owner | E3: Planned Date | F3: Status | G3: Actual Date | H3: Evidence
A4: M0 — Scope Ready | B4: Các quyết định chặn đã được xử lý | C4: 1.1–1.5 | F4: Not Started
A5: M1 — Design Baseline | B5: Yêu cầu, thiết kế, test strategy được duyệt | C5: 2.1–2.9 | F5: Not Started
A6: M2 — Platform Ready | B6: Năng lực dùng chung Pha 1 sẵn sàng | C6: 3.1–3.15 | F6: Not Started
A7: M3 — Pha 1 Feature Complete | B7: Tất cả cấu hình và năng lực mức B hoàn thành | C7: 4.1–5.5 | F7: Not Started
A8: M4 — Pha 1 UAT Accepted | B8: UAT và regression đạt | C8: 6.1–6.8 | F8: Not Started
A9: M5 — Pha 1 Go-live | B9: Hệ thống đưa vào vận hành | C9: 7.1–7.5 | F9: Not Started
A10: M6 — Pha 1 Closed | B10: Hypercare và bàn giao hoàn tất | C10: 7.6 | F10: Not Started
A11: M7 — Pha 2 Accepted | B11: Pha 2 nghiệm thu và release | C11: 8.1–8.10 | F11: Not Started
A12: MAI — AI Pilot Decision | B12: Có quyết định Go/Adjust/Stop | C12: 9.1–9.15 | F12: Not Started

Sheet BR Traceability
A1: BRD → WBS TRACEABILITY
A3: BR | B3: CAP | C3: WBS chịu trách nhiệm chính | D3: Ghi chú | E3: Owner | F3: Status | G3: Evidence
A4: BR-001 | B4: CAP-01 | C4: 2.2, 3.2, WBS 4.0 | D4: Baseline P1 | F4: Not Started
A5: BR-002 | B5: CAP-02 | C5: 2.2, 3.2, WBS 4.0 | D5: Baseline P1 | F5: Not Started
A6: BR-003 | B6: CAP-03 | C6: 3.3, 4.11 | D6: Baseline P1 | F6: Not Started
A7: BR-004 | B7: CAP-04 | C7: 3.4, WBS 4.0 | D7: Baseline P1 | F7: Not Started
A8: BR-005 | B8: CAP-05 | C8: 2.4, 3.5, WBS 4.0 | D8: Baseline P1 | F8: Not Started
A9: BR-006 | B9: CAP-06 | C9: 3.6, 4.10, 4.11 | D9: Baseline P1 | F9: Not Started
A10: BR-007 | B10: CAP-07 | C10: 3.7, WBS 4.0 | D10: Baseline P1 | F10: Not Started
A11: BR-008 | B11: CAP-08 | C11: 3.8, WBS 4.0 | D11: Phụ thuộc A2 | F11: Not Started
A12: BR-009 | B12: CAP-09 | C12: 3.9, 4.3, 4.6 | D12: Baseline P1 | F12: Not Started
A13: BR-010 | B13: CAP-10 | C13: 3.10, 4.3, 4.6 | D13: Baseline P1 | F13: Not Started
A14: BR-011 | B14: CAP-11 | C14: 3.11, 4.3, 4.6 | D14: Baseline P1 | F14: Not Started
A15: BR-012 | B15: CAP-12 | C15: 3.12, các luồng .02 | D15: Baseline P1 | F15: Not Started
... A24: BR-021 | B24: CAP-21 | C24: WBS 9.0 | D24: Tùy chọn, ngoài baseline đến khi duyệt A7 | F24: Not Started

Sheet Dependencies
A1: DEPENDENCIES & BLOCKERS
A3: Dependency | B3: Chuỗi ảnh hưởng | C3: Biện pháp quản trị | D3: Owner | E3: Status | F3: Evidence / Decision
A4: Quyết định A1 về mức tự cấu hình | B4: 1.2 → 2.2 → 3.2/3.3 | C4: Chốt trước estimate; nếu chọn T2 phải bổ sung phân hệ Admin và tái baseline WBS | E4: Open
A5: Quyết định A2 về ký số | B5: 1.2 → 2.6 → 3.8 → WBS 4.0 | C5: Xác định nhà cung cấp/chứng thư và môi trường test trước thiết kế chi tiết | E5: Open
A6: Thiếu chi tiết RD08, RD10 | B6: 1.3 → 2.2/2.4 → 4.10/4.11 | C6: Workshop riêng; không cam kết effort trước sign-off | E6: Open
A7: Nguồn dữ liệu RD03.06 | B7: A3 → 4.5 → 5.3–5.5 | C7: Chốt nhập tay, kéo tích hợp lên P1 hoặc giảm tiêu chí P1 | E7: Open
A8: Hệ thống đối tác | B8: 2.7 → 5.2 → 8.1–8.5 | C8: Có owner, contract, sandbox và mock server | E8: Open
A9: NFR chưa có ngưỡng | B9: 1.4 → 2.8 → 6.5 → 7.1 | C9: Chốt trước capacity planning và Production Readiness Review | E9: Open
A10: AI on-premise | B10: 9.1 → 9.4 → 9.5–9.14 | C10: Tách release train và budget; không làm chặn quy trình lõi | E10: Open

Sheet Gates & Decisions
A1: GATES & OPEN DECISIONS
A3: Gate | B3: Nội dung phải chốt | C3: Quyết định nguồn | D3: Tác động nếu chưa chốt | E3: Owner | F3: Status | G3: Due Date | H3: Decision / Evidence
A4: G0-SCOPE | B4: Mức tự cấu hình quy trình, hình thức ký, phạm vi Pha 1, nguyên tắc nghiệm thu hai mức | C4: A1–A6 | D4: Không thể khóa solution scope và effort | F4: Open
A5: G0-AI | B5: Có triển khai AI, luồng pilot, bộ dữ liệu và ngưỡng chất lượng | C5: A7 | D5: Không đưa WBS 9.0 vào baseline | F5: Open
A6: G0-NFR | B6: Hạ tầng, bảo mật, tải, lưu trữ, dữ liệu cá nhân | C6: C1–C5 | D6: Không thể size hạ tầng và test phi chức năng | F6: Open
A7: G0-DATA | B7: Nguồn kế hoạch năm, kho tài liệu, nguồn dữ liệu báo cáo | C7: B5, B9, A3 | D7: Chặn thiết kế dữ liệu và tích hợp | F7: Open
A8: G0-PROCESS | B8: Quy tắc còn mở và lỗi tài liệu nguồn | C8: B1–B8, D1–D6 | D8: Chặn đặc tả luồng và tiêu chí UAT | F8: Open

Sheet Lists
A1: Status | B1: Scope | C1: Gate Status | D1: Roles
A2: Not Started | B2: ALL | C2: Open | D2: Project Manager
A3: In Progress | B3: P1 | C3: In Review | D3: Business Analyst
A4: Blocked | B4: P1 mức B | C4: Approved | D4: Product Owner
A5: Done | B5: P2 | C5: Rejected | D5: Solution Architect
A6: Deferred | B6: OPT-AI | C6: Not Applicable | D6: Tech Lead
D7: QA Lead
D8: Security
D9: DevOps
D10: Data Owner
D11: Integration Owner
