Workbook
Name FSL_Priority: '03_Danh_muc'!$A$2:$A$5
Name FSL_Release: '03_Danh_muc'!$B$2:$B$5
Name FSL_ScopeStatus: '03_Danh_muc'!$C$2:$C$5

Sheet 00_Tong_quan
A1: FUNCTIONAL SCOPE LIST – QTKHCN
A4: Tổng chức năng | D4: Phân hệ | G4: Priority Must | J4: Cần xác nhận
A5: =COUNTA('01_Functional_Scope'!$B$5:$B$362) -> 358 | D5: =COUNTA('02_Phan_he'!$B$4:$B$21) -> 18 | G5: =COUNTIF('01_Functional_Scope'!$K$5:$K$362,"Must") -> 192 | J5: =COUNTIF('01_Functional_Scope'!$M$5:$M$362,"Cần xác nhận") -> 18
A8: Hướng dẫn sử dụng
A9: 1. Sheet 01 là nguồn chính: lọc theo phân hệ, module, priority, release và trạng thái phạm vi.
A10: 2. Priority dùng MoSCoW; Release chỉ là đề xuất sơ bộ, cần chốt sau workshop nghiệp vụ.
A11: 3. Các dòng “Cần xác nhận” là giả định hoặc phạm vi phụ thuộc hệ thống ngoài/chính sách.
A12: 4. Functional Scope List chưa chứa effort, owner và timeline; các trường này thuộc WBS/roadmap tiếp theo.
A13: 5. Sheet 99 giữ danh sách gốc để truy vết các sửa đổi và phần bổ sung.
A15: Phân hệ | B15: Số chức năng
A16: Truy cập, Tổ chức & Phân quyền | B16: =COUNTIF('01_Functional_Scope'!$C$5:$C$362,A16) -> 30
A17: Quản lý Nhiệm vụ KHCN | B17: =COUNTIF('01_Functional_Scope'!$C$5:$C$362,A17) -> 12
A18: Chủ trương & Xét duyệt | B18: =COUNTIF('01_Functional_Scope'!$C$5:$C$362,A18) -> 21
A19: Không gian làm việc & Task | B19: =COUNTIF('01_Functional_Scope'!$C$5:$C$362,A19) -> 22
A20: Hồ sơ, Tài liệu & Biểu mẫu | B20: =COUNTIF('01_Functional_Scope'!$C$5:$C$362,A20) -> 30
A21: Hội đồng & Thẩm định | B21: =COUNTIF('01_Functional_Scope'!$C$5:$C$362,A21) -> 12
A22: Thực hiện Nhiệm vụ | B22: =COUNTIF('01_Functional_Scope'!$C$5:$C$362,A22) -> 17
A23: Điều chỉnh, Tạm dừng & Dừng | B23: =COUNTIF('01_Functional_Scope'!$C$5:$C$362,A23) -> 30
A24: Nghiệm thu | B24: =COUNTIF('01_Functional_Scope'!$C$5:$C$362,A24) -> 11
A25: Quyết toán | B25: =COUNTIF('01_Functional_Scope'!$C$5:$C$362,A25) -> 11
A26: Sản phẩm Nghiên cứu & SHTT | B26: =COUNTIF('01_Functional_Scope'!$C$5:$C$362,A26) -> 23
A27: Báo cáo & Điều hành | B27: =COUNTIF('01_Functional_Scope'!$C$5:$C$362,A27) -> 10
... A33: Trợ giúp & Hỗ trợ Người dùng | B33: =COUNTIF('01_Functional_Scope'!$C$5:$C$362,A33) -> 3

Sheet 01_Functional_Scope
A1: FUNCTIONAL SCOPE LIST – HỆ THỐNG QUẢN LÝ NHIỆM VỤ KHCN
A2: Phiên bản khởi tạo từ VHT_WBS và bổ sung theo tài liệu kiến trúc/nghiệp vụ trong docs/research. Đây là danh mục phạm vi chức năng, chưa phải WBS ước lượng.
A4: STT | B4: Feature ID | C4: Phân hệ | D4: Module | E4: Nhóm chức năng | F4: Chức năng | G4: Mô tả phạm vi | H4: Vai trò chính | I4: Loại | J4: Quy trình/RD | K4: Priority | L4: Release đề xuất | M4: Trạng thái phạm vi | N4: Nguồn/Thay đổi | O4: Định hướng nghiệm thu/Ghi chú
A5: 1 | B5: IAM-SSO-001 | C5: Truy cập, Tổ chức & Phân quyền | D5: Đăng nhập & SSO | E5: Xác thực | F5: Đăng nhập qua SSO/OIDC | G5: Chuyển hướng đến Identity Provider, nhận token và tạo phiên làm việc hợp lệ. | H5: Tất cả người dùng | I5: Nền tảng | K5: Must | L5: Pha 1 | M5: Đề xuất trong phạm vi | N5: Hiệu chỉnh từ VHT_WBS | O5: Đăng nhập thành công bằng tài khoản hợp lệ; lỗi xác thực không làm lộ thông tin nhạy cảm.
A6: 2 | B6: IAM-SSO-002 | C6: Truy cập, Tổ chức & Phân quyền | D6: Đăng nhập & SSO | E6: Xác thực | F6: Đăng xuất tập trung | G6: Kết thúc phiên ứng dụng và phiên SSO theo chính sách tổ chức. | H6: Tất cả người dùng | I6: Nền tảng | K6: Must | L6: Pha 1 | M6: Đề xuất trong phạm vi | N6: Hiệu chỉnh từ VHT_WBS
A7: 3 | B7: IAM-SSO-003 | C7: Truy cập, Tổ chức & Phân quyền | D7: Đăng nhập & SSO | E7: Bảo mật phiên | F7: Gia hạn và hết hạn phiên | G7: Quản lý refresh token, timeout không hoạt động và bắt buộc đăng nhập lại. | H7: Tất cả người dùng | I7: Bảo mật | K7: Must | L7: Pha 1 | M7: Đề xuất trong phạm vi | N7: Bổ sung
A8: 4 | B8: IAM-SSO-004 | C8: Truy cập, Tổ chức & Phân quyền | D8: Đăng nhập & SSO | E8: Hồ sơ người dùng | F8: Xem hồ sơ và ngữ cảnh đăng nhập | G8: Hiển thị người dùng, đơn vị, vai trò, phạm vi dữ liệu và quyền hiệu lực. | H8: Tất cả người dùng | I8: Nền tảng | K8: Must | L8: Pha 1 | M8: Đề xuất trong phạm vi | N8: Bổ sung
A9: 5 | B9: IAM-ORG-001 | C9: Truy cập, Tổ chức & Phân quyền | D9: Cơ cấu tổ chức | E9: Đơn vị tổ chức | F9: Xem danh sách Đơn vị tổ chức | G9: Tra cứu danh sách, phân trang, sắp xếp và lọc Đơn vị tổ chức theo các tiêu chí nghiệp vụ. | H9: Quản trị hệ thống | I9: Nghiệp vụ | K9: Must | L9: Pha 1 | M9: Đề xuất trong phạm vi | N9: Bổ sung theo EPIC01 | O9: Danh sách hiển thị đúng phạm vi dữ liệu và hỗ trợ lọc/xuất theo quyền.
A10: 6 | B10: IAM-ORG-002 | C10: Truy cập, Tổ chức & Phân quyền | D10: Cơ cấu tổ chức | E10: Đơn vị tổ chức | F10: Tạo mới Đơn vị tổ chức | G10: Khởi tạo Đơn vị tổ chức, kiểm tra dữ liệu bắt buộc và lưu nháp trước khi hoàn tất. | H10: Quản trị hệ thống | I10: Nghiệp vụ | K10: Must | L10: Pha 1 | M10: Đề xuất trong phạm vi | N10: Bổ sung theo EPIC01 | O10: Dữ liệu hợp lệ được lưu; lỗi validation hiển thị tại trường tương ứng.
A11: 7 | B11: IAM-ORG-003 | C11: Truy cập, Tổ chức & Phân quyền | D11: Cơ cấu tổ chức | E11: Đơn vị tổ chức | F11: Xem chi tiết Đơn vị tổ chức | G11: Hiển thị thông tin tổng quan, dữ liệu chi tiết, tài liệu liên quan và trạng thái của Đơn vị tổ chức. | H11: Quản trị hệ thống | I11: Nghiệp vụ | K11: Must | L11: Pha 1 | M11: Đề xuất trong phạm vi | N11: Bổ sung theo EPIC01 | O11: Thông tin hiển thị đúng phiên bản và quyền truy cập.
A12: 8 | B12: IAM-ORG-004 | C12: Truy cập, Tổ chức & Phân quyền | D12: Cơ cấu tổ chức | E12: Đơn vị tổ chức | F12: Chỉnh sửa Đơn vị tổ chức | G12: Cập nhật Đơn vị tổ chức khi trạng thái và quyền người dùng cho phép; kiểm soát xung đột cập nhật. | H12: Quản trị hệ thống | I12: Nghiệp vụ | K12: Must | L12: Pha 1 | M12: Đề xuất trong phạm vi | N12: Bổ sung theo EPIC01 | O12: Chỉ trường được phép sửa có hiệu lực và thay đổi được ghi lịch sử.
A13: 9 | B13: IAM-ORG-005 | C13: Truy cập, Tổ chức & Phân quyền | D13: Cơ cấu tổ chức | E13: Đơn vị tổ chức | F13: Xóa/Ngừng sử dụng Đơn vị tổ chức | G13: Xóa logic hoặc ngừng sử dụng Đơn vị tổ chức sau khi kiểm tra ràng buộc tham chiếu. | H13: Quản trị hệ thống | I13: Quản trị/Cán bộ nghiệp vụ | K13: Should | L13: Pha 1 | M13: Đề xuất trong phạm vi | N13: Bổ sung theo EPIC01 | O13: Không xóa vật lý dữ liệu đã phát sinh giao dịch; cảnh báo rõ quan hệ phụ thuộc.
A14: 10 | B14: IAM-ORG-006 | C14: Truy cập, Tổ chức & Phân quyền | D14: Cơ cấu tổ chức | E14: Đơn vị tổ chức | F14: Xem lịch sử Đơn vị tổ chức | G14: Theo dõi phiên bản, thay đổi dữ liệu, người thực hiện và lịch sử xử lý của Đơn vị tổ chức. | H14: Quản trị hệ thống | I14: Cán bộ nghiệp vụ/Quản trị | J14: Audit | L14: Must | M14: Pha 1 | N14: Đề xuất trong phạm vi | O14: Bổ sung theo EPIC01
A15: 11 | B15: IAM-ORG-007 | C15: Truy cập, Tổ chức & Phân quyền | D15: Cơ cấu tổ chức | E15: Cây tổ chức | F15: Quản lý cây tổ chức đa cấp | G15: Thiết lập quan hệ cha-con, cấp đơn vị, hiệu lực và lịch sử thay đổi cơ cấu. | H15: Quản trị hệ thống | I15: Cấu hình | K15: Must | L15: Pha 1 | M15: Đề xuất trong phạm vi | N15: Bổ sung
A16: 12 | B16: IAM-ORG-008 | C16: Truy cập, Tổ chức & Phân quyền | D16: Cơ cấu tổ chức | E16: Chức danh | F16: Quản lý chức danh và vị trí công việc | G16: Khai báo chức danh, vị trí, cấp quản lý và ánh xạ dữ liệu nhân sự. | H16: Quản trị hệ thống | I16: Cấu hình | K16: Should | L16: Pha 1 | M16: Đề xuất trong phạm vi | N16: Bổ sung
A17: 13 | B17: IAM-USR-001 | C17: Truy cập, Tổ chức & Phân quyền | D17: Người dùng & định danh | E17: Người dùng ứng dụng | F17: Xem danh sách Người dùng ứng dụng | G17: Tra cứu danh sách, phân trang, sắp xếp và lọc Người dùng ứng dụng theo các tiêu chí nghiệp vụ. | H17: Quản trị hệ thống | I17: Nghiệp vụ | K17: Must | L17: Pha 1 | M17: Đề xuất trong phạm vi | N17: Bổ sung theo EPIC02 | O17: Danh sách hiển thị đúng phạm vi dữ liệu và hỗ trợ lọc/xuất theo quyền.
A18: 14 | B18: IAM-USR-002 | C18: Truy cập, Tổ chức & Phân quyền | D18: Người dùng & định danh | E18: Người dùng ứng dụng | F18: Tạo mới Người dùng ứng dụng | G18: Khởi tạo Người dùng ứng dụng, kiểm tra dữ liệu bắt buộc và lưu nháp trước khi hoàn tất. | H18: Quản trị hệ thống | I18: Nghiệp vụ | K18: Must | L18: Pha 1 | M18: Đề xuất trong phạm vi | N18: Bổ sung theo EPIC02 | O18: Dữ liệu hợp lệ được lưu; lỗi validation hiển thị tại trường tương ứng.
A19: 15 | B19: IAM-USR-003 | C19: Truy cập, Tổ chức & Phân quyền | D19: Người dùng & định danh | E19: Người dùng ứng dụng | F19: Xem chi tiết Người dùng ứng dụng | G19: Hiển thị thông tin tổng quan, dữ liệu chi tiết, tài liệu liên quan và trạng thái của Người dùng ứng dụng. | H19: Quản trị hệ thống | I19: Nghiệp vụ | K19: Must | L19: Pha 1 | M19: Đề xuất trong phạm vi | N19: Bổ sung theo EPIC02 | O19: Thông tin hiển thị đúng phiên bản và quyền truy cập.
A20: 16 | B20: IAM-USR-004 | C20: Truy cập, Tổ chức & Phân quyền | D20: Người dùng & định danh | E20: Người dùng ứng dụng | F20: Chỉnh sửa Người dùng ứng dụng | G20: Cập nhật Người dùng ứng dụng khi trạng thái và quyền người dùng cho phép; kiểm soát xung đột cập nhật. | H20: Quản trị hệ thống | I20: Nghiệp vụ | K20: Must | L20: Pha 1 | M20: Đề xuất trong phạm vi | N20: Bổ sung theo EPIC02 | O20: Chỉ trường được phép sửa có hiệu lực và thay đổi được ghi lịch sử.
A21: 17 | B21: IAM-USR-005 | C21: Truy cập, Tổ chức & Phân quyền | D21: Người dùng & định danh | E21: Người dùng ứng dụng | F21: Xóa/Ngừng sử dụng Người dùng ứng dụng | G21: Xóa logic hoặc ngừng sử dụng Người dùng ứng dụng sau khi kiểm tra ràng buộc tham chiếu. | H21: Quản trị hệ thống | I21: Quản trị/Cán bộ nghiệp vụ | K21: Should | L21: Pha 1 | M21: Đề xuất trong phạm vi | N21: Bổ sung theo EPIC02 | O21: Không xóa vật lý dữ liệu đã phát sinh giao dịch; cảnh báo rõ quan hệ phụ thuộc.
A22: 18 | B22: IAM-USR-006 | C22: Truy cập, Tổ chức & Phân quyền | D22: Người dùng & định danh | E22: Người dùng ứng dụng | F22: Xem lịch sử Người dùng ứng dụng | G22: Theo dõi phiên bản, thay đổi dữ liệu, người thực hiện và lịch sử xử lý của Người dùng ứng dụng. | H22: Quản trị hệ thống | I22: Cán bộ nghiệp vụ/Quản trị | J22: Audit | L22: Must | M22: Pha 1 | N22: Đề xuất trong phạm vi | O22: Bổ sung theo EPIC02
A23: 19 | B23: IAM-USR-007 | C23: Truy cập, Tổ chức & Phân quyền | D23: Người dùng & định danh | E23: Đồng bộ | F23: Đồng bộ người dùng từ AD/QLNS | G23: Đồng bộ hồ sơ, đơn vị, chức danh và trạng thái người dùng; ghi nhận sai lệch. | H23: Quản trị hệ thống | I23: Tích hợp | K23: Must | L23: Pha 1 | M23: Đề xuất trong phạm vi | N23: Bổ sung
A24: 20 | B24: IAM-USR-008 | C24: Truy cập, Tổ chức & Phân quyền | D24: Người dùng & định danh | E24: Phân công | F24: Gán vai trò và phạm vi dữ liệu cho người dùng | G24: Mỗi assignment gồm user, role, data scope, đơn vị/nhiệm vụ và thời hạn hiệu lực. | H24: Quản trị hệ thống | I24: Phân quyền | K24: Must | L24: Pha 1 | M24: Đề xuất trong phạm vi | N24: Bổ sung theo recfactor-module-user-role
A25: 21 | B25: IAM-USR-009 | C25: Truy cập, Tổ chức & Phân quyền | D25: Người dùng & định danh | E25: Phân công | F25: Ủy quyền và người thay thế | G25: Thiết lập ủy quyền theo thời gian, phạm vi task/quy trình và ngăn xung đột phân quyền. | H25: Người dùng/Quản trị | I25: Phân quyền | K25: Should | L25: Pha 2 | M25: Đề xuất trong phạm vi | N25: Bổ sung
A26: 22 | B26: IAM-RBAC-001 | C26: Truy cập, Tổ chức & Phân quyền | D26: Vai trò & phân quyền | E26: Vai trò nghiệp vụ | F26: Xem danh sách Vai trò nghiệp vụ | G26: Tra cứu danh sách, phân trang, sắp xếp và lọc Vai trò nghiệp vụ theo các tiêu chí nghiệp vụ. | H26: Quản trị hệ thống | I26: Nghiệp vụ | K26: Must | L26: Pha 1 | M26: Đề xuất trong phạm vi | N26: Bổ sung theo EPIC03 | O26: Danh sách hiển thị đúng phạm vi dữ liệu và hỗ trợ lọc/xuất theo quyền.
A27: 23 | B27: IAM-RBAC-002 | C27: Truy cập, Tổ chức & Phân quyền | D27: Vai trò & phân quyền | E27: Vai trò nghiệp vụ | F27: Tạo mới Vai trò nghiệp vụ | G27: Khởi tạo Vai trò nghiệp vụ, kiểm tra dữ liệu bắt buộc và lưu nháp trước khi hoàn tất. | H27: Quản trị hệ thống | I27: Nghiệp vụ | K27: Must | L27: Pha 1 | M27: Đề xuất trong phạm vi | N27: Bổ sung theo EPIC03 | O27: Dữ liệu hợp lệ được lưu; lỗi validation hiển thị tại trường tương ứng.
A28: 24 | B28: IAM-RBAC-003 | C28: Truy cập, Tổ chức & Phân quyền | D28: Vai trò & phân quyền | E28: Vai trò nghiệp vụ | F28: Xem chi tiết Vai trò nghiệp vụ | G28: Hiển thị thông tin tổng quan, dữ liệu chi tiết, tài liệu liên quan và trạng thái của Vai trò nghiệp vụ. | H28: Quản trị hệ thống | I28: Nghiệp vụ | K28: Must | L28: Pha 1 | M28: Đề xuất trong phạm vi | N28: Bổ sung theo EPIC03 | O28: Thông tin hiển thị đúng phiên bản và quyền truy cập.
A29: 25 | B29: IAM-RBAC-004 | C29: Truy cập, Tổ chức & Phân quyền | D29: Vai trò & phân quyền | E29: Vai trò nghiệp vụ | F29: Chỉnh sửa Vai trò nghiệp vụ | G29: Cập nhật Vai trò nghiệp vụ khi trạng thái và quyền người dùng cho phép; kiểm soát xung đột cập nhật. | H29: Quản trị hệ thống | I29: Nghiệp vụ | K29: Must | L29: Pha 1 | M29: Đề xuất trong phạm vi | N29: Bổ sung theo EPIC03 | O29: Chỉ trường được phép sửa có hiệu lực và thay đổi được ghi lịch sử.
A30: 26 | B30: IAM-RBAC-005 | C30: Truy cập, Tổ chức & Phân quyền | D30: Vai trò & phân quyền | E30: Vai trò nghiệp vụ | F30: Xóa/Ngừng sử dụng Vai trò nghiệp vụ | G30: Xóa logic hoặc ngừng sử dụng Vai trò nghiệp vụ sau khi kiểm tra ràng buộc tham chiếu. | H30: Quản trị hệ thống | I30: Quản trị/Cán bộ nghiệp vụ | K30: Should | L30: Pha 1 | M30: Đề xuất trong phạm vi | N30: Bổ sung theo EPIC03 | O30: Không xóa vật lý dữ liệu đã phát sinh giao dịch; cảnh báo rõ quan hệ phụ thuộc.
A31: 27 | B31: IAM-RBAC-006 | C31: Truy cập, Tổ chức & Phân quyền | D31: Vai trò & phân quyền | E31: Vai trò nghiệp vụ | F31: Xem lịch sử Vai trò nghiệp vụ | G31: Theo dõi phiên bản, thay đổi dữ liệu, người thực hiện và lịch sử xử lý của Vai trò nghiệp vụ. | H31: Quản trị hệ thống | I31: Cán bộ nghiệp vụ/Quản trị | J31: Audit | L31: Must | M31: Pha 1 | N31: Đề xuất trong phạm vi | O31: Bổ sung theo EPIC03
A32: 28 | B32: IAM-RBAC-007 | C32: Truy cập, Tổ chức & Phân quyền | D32: Vai trò & phân quyền | E32: Ma trận quyền | F32: Cấu hình ma trận Role × Chức năng × Quyền | G32: Quản lý quyền xem, tạo, sửa, xóa, trình, duyệt, xuất và quản trị theo vai trò. | H32: Quản trị hệ thống | I32: Phân quyền | K32: Must | L32: Pha 1 | M32: Đề xuất trong phạm vi | N32: Bổ sung
A33: 29 | B33: IAM-RBAC-008 | C33: Truy cập, Tổ chức & Phân quyền | D33: Vai trò & phân quyền | E33: Phạm vi dữ liệu | F33: Cấu hình loại phạm vi dữ liệu | G33: Hỗ trợ bản thân, đơn vị, cây đơn vị, nhiệm vụ được giao và toàn hệ thống. | H33: Quản trị hệ thống | I33: Phân quyền | K33: Must | L33: Pha 1 | M33: Đề xuất trong phạm vi | N33: Bổ sung
A34: 30 | B34: IAM-RBAC-009 | C34: Truy cập, Tổ chức & Phân quyền | D34: Vai trò & phân quyền | E34: Mô phỏng | F34: Mô phỏng quyền hiệu lực | G34: Giải thích quyền thao tác từ role policy và phạm vi dữ liệu từ user assignment. | H34: Quản trị hệ thống/Audit | I34: Phân quyền | K34: Should | L34: Pha 2 | M34: Đề xuất trong phạm vi | N34: Bổ sung
A35: 31 | B35: MIS-MISSION-001 | C35: Quản lý Nhiệm vụ KHCN | D35: Hồ sơ nhiệm vụ | E35: Nhiệm vụ KHCN | F35: Xem danh sách Nhiệm vụ KHCN | G35: Tra cứu danh sách, phân trang, sắp xếp và lọc Nhiệm vụ KHCN theo các tiêu chí nghiệp vụ. | H35: Cán bộ KHCN/Chủ nhiệm | I35: Nghiệp vụ | K35: Must | L35: Pha 1 | M35: Đề xuất trong phạm vi | N35: Hiệu chỉnh từ VHT_WBS | O35: Danh sách hiển thị đúng phạm vi dữ liệu và hỗ trợ lọc/xuất theo quyền.
A36: 32 | B36: MIS-MISSION-002 | C36: Quản lý Nhiệm vụ KHCN | D36: Hồ sơ nhiệm vụ | E36: Nhiệm vụ KHCN | F36: Tạo mới Nhiệm vụ KHCN | G36: Khởi tạo Nhiệm vụ KHCN, kiểm tra dữ liệu bắt buộc và lưu nháp trước khi hoàn tất. | H36: Cán bộ KHCN/Chủ nhiệm | I36: Nghiệp vụ | K36: Must | L36: Pha 1 | M36: Đề xuất trong phạm vi | N36: Hiệu chỉnh từ VHT_WBS | O36: Dữ liệu hợp lệ được lưu; lỗi validation hiển thị tại trường tương ứng.
A37: 33 | B37: MIS-MISSION-003 | C37: Quản lý Nhiệm vụ KHCN | D37: Hồ sơ nhiệm vụ | E37: Nhiệm vụ KHCN | F37: Xem chi tiết Nhiệm vụ KHCN | G37: Hiển thị thông tin tổng quan, dữ liệu chi tiết, tài liệu liên quan và trạng thái của Nhiệm vụ KHCN. | H37: Cán bộ KHCN/Chủ nhiệm | I37: Nghiệp vụ | K37: Must | L37: Pha 1 | M37: Đề xuất trong phạm vi | N37: Hiệu chỉnh từ VHT_WBS | O37: Thông tin hiển thị đúng phiên bản và quyền truy cập.
A38: 34 | B38: MIS-MISSION-004 | C38: Quản lý Nhiệm vụ KHCN | D38: Hồ sơ nhiệm vụ | E38: Nhiệm vụ KHCN | F38: Chỉnh sửa Nhiệm vụ KHCN | G38: Cập nhật Nhiệm vụ KHCN khi trạng thái và quyền người dùng cho phép; kiểm soát xung đột cập nhật. | H38: Cán bộ KHCN/Chủ nhiệm | I38: Nghiệp vụ | K38: Must | L38: Pha 1 | M38: Đề xuất trong phạm vi | N38: Hiệu chỉnh từ VHT_WBS | O38: Chỉ trường được phép sửa có hiệu lực và thay đổi được ghi lịch sử.
A39: 35 | B39: MIS-MISSION-005 | C39: Quản lý Nhiệm vụ KHCN | D39: Hồ sơ nhiệm vụ | E39: Nhiệm vụ KHCN | F39: Xóa/Ngừng sử dụng Nhiệm vụ KHCN | G39: Xóa logic hoặc ngừng sử dụng Nhiệm vụ KHCN sau khi kiểm tra ràng buộc tham chiếu. | H39: Cán bộ KHCN/Chủ nhiệm | I39: Quản trị/Cán bộ nghiệp vụ | K39: Should | L39: Pha 1 | M39: Đề xuất trong phạm vi | N39: Hiệu chỉnh từ VHT_WBS | O39: Không xóa vật lý dữ liệu đã phát sinh giao dịch; cảnh báo rõ quan hệ phụ thuộc.
A40: 36 | B40: MIS-MISSION-006 | C40: Quản lý Nhiệm vụ KHCN | D40: Hồ sơ nhiệm vụ | E40: Nhiệm vụ KHCN | F40: Xem lịch sử Nhiệm vụ KHCN | G40: Theo dõi phiên bản, thay đổi dữ liệu, người thực hiện và lịch sử xử lý của Nhiệm vụ KHCN. | H40: Cán bộ KHCN/Chủ nhiệm | I40: Cán bộ nghiệp vụ/Quản trị | J40: Audit | L40: Must | M40: Pha 1 | N40: Đề xuất trong phạm vi | O40: Hiệu chỉnh từ VHT_WBS
A41: 37 | B41: MIS-MISSION-007 | C41: Quản lý Nhiệm vụ KHCN | D41: Hồ sơ nhiệm vụ | E41: Vòng đời | F41: Quản lý trạng thái vòng đời nhiệm vụ | G41: Quản lý chuyển trạng thái từ đề xuất, phê duyệt, thực hiện, điều chỉnh, nghiệm thu, quyết toán đến đóng nhiệm vụ. | H41: Cán bộ KHCN | I41: Nghiệp vụ | J41: RD01-RD10 | K41: Must | L41: Pha 1 | M41: Đề xuất trong phạm vi | N41: Bổ sung
...

Sheet 02_Phan_he
A1: MA TRẬN PHÂN HỆ VÀ MỨC BAO PHỦ
A3: STT | B3: Phân hệ | C3: Mô tả phạm vi | D3: Tổng chức năng | E3: Must | F3: Should | G3: Could | H3: Cần xác nhận
A4: 1 | B4: Truy cập, Tổ chức & Phân quyền | C4: SSO, tổ chức, người dùng, vai trò, quyền và phạm vi dữ liệu. | D4: =COUNTIF('01_Functional_Scope'!$C$5:$C$362,B4) -> 30 | E4: =COUNTIFS('01_Functional_Scope'!$C$5:$C$362,B4,'01_Functional_Scope'!$K$5:$K$362,E$3) -> 21 | F4: =COUNTIFS('01_Functional_Scope'!$C$5:$C$362,B4,'01_Functional_Scope'!$K$5:$K$362,F$3) -> 6 | G4: =COUNTIFS('01_Functional_Scope'!$C$5:$C$362,B4,'01_Functional_Scope'!$K$5:$K$362,G$3) -> 0 | H4: =COUNTIFS('01_Functional_Scope'!$C$5:$C$362,B4,'01_Functional_Scope'!$M$5:$M$362,H$3) -> 0
A5: 2 | B5: Quản lý Nhiệm vụ KHCN | C5: Hồ sơ nhiệm vụ trung tâm và vòng đời RD01–RD10. | D5: =COUNTIF('01_Functional_Scope'!$C$5:$C$362,B5) -> 12 | E5: =COUNTIFS('01_Functional_Scope'!$C$5:$C$362,B5,'01_Functional_Scope'!$K$5:$K$362,E$3) -> 8 | F5: =COUNTIFS('01_Functional_Scope'!$C$5:$C$362,B5,'01_Functional_Scope'!$K$5:$K$362,F$3) -> 3 | G5: =COUNTIFS('01_Functional_Scope'!$C$5:$C$362,B5,'01_Functional_Scope'!$K$5:$K$362,G$3) -> 0 | H5: =COUNTIFS('01_Functional_Scope'!$C$5:$C$362,B5,'01_Functional_Scope'!$M$5:$M$362,H$3) -> 0
A6: 3 | B6: Chủ trương & Xét duyệt | C6: RD01 chủ trương và RD02 xét duyệt/giao nhiệm vụ. | D6: =COUNTIF('01_Functional_Scope'!$C$5:$C$362,B6) -> 21 | E6: =COUNTIFS('01_Functional_Scope'!$C$5:$C$362,B6,'01_Functional_Scope'!$K$5:$K$362,E$3) -> 15 | F6: =COUNTIFS('01_Functional_Scope'!$C$5:$C$362,B6,'01_Functional_Scope'!$K$5:$K$362,F$3) -> 2 | G6: =COUNTIFS('01_Functional_Scope'!$C$5:$C$362,B6,'01_Functional_Scope'!$K$5:$K$362,G$3) -> 0 | H6: =COUNTIFS('01_Functional_Scope'!$C$5:$C$362,B6,'01_Functional_Scope'!$M$5:$M$362,H$3) -> 0
A7: 4 | B7: Không gian làm việc & Task | C7: Worklist, task UI, action chuẩn và ngoại lệ có kiểm soát. | D7: =COUNTIF('01_Functional_Scope'!$C$5:$C$362,B7) -> 22 | E7: =COUNTIFS('01_Functional_Scope'!$C$5:$C$362,B7,'01_Functional_Scope'!$K$5:$K$362,E$3) -> 14 | F7: =COUNTIFS('01_Functional_Scope'!$C$5:$C$362,B7,'01_Functional_Scope'!$K$5:$K$362,F$3) -> 0 | G7: =COUNTIFS('01_Functional_Scope'!$C$5:$C$362,B7,'01_Functional_Scope'!$K$5:$K$362,G$3) -> 8 | H7: =COUNTIFS('01_Functional_Scope'!$C$5:$C$362,B7,'01_Functional_Scope'!$M$5:$M$362,H$3) -> 8
A8: 5 | B8: Hồ sơ, Tài liệu & Biểu mẫu | C8: Dossier, eForm, mẫu văn bản, file và ký số. | D8: =COUNTIF('01_Functional_Scope'!$C$5:$C$362,B8) -> 30 | E8: =COUNTIFS('01_Functional_Scope'!$C$5:$C$362,B8,'01_Functional_Scope'!$K$5:$K$362,E$3) -> 16 | F8: =COUNTIFS('01_Functional_Scope'!$C$5:$C$362,B8,'01_Functional_Scope'!$K$5:$K$362,F$3) -> 12 | G8: =COUNTIFS('01_Functional_Scope'!$C$5:$C$362,B8,'01_Functional_Scope'!$K$5:$K$362,G$3) -> 0 | H8: =COUNTIFS('01_Functional_Scope'!$C$5:$C$362,B8,'01_Functional_Scope'!$M$5:$M$362,H$3) -> 1
A9: 6 | B9: Hội đồng & Thẩm định | C9: Hội đồng, chuyên gia, lịch họp, phiếu và biên bản. | D9: =COUNTIF('01_Functional_Scope'!$C$5:$C$362,B9) -> 12 | E9: =COUNTIFS('01_Functional_Scope'!$C$5:$C$362,B9,'01_Functional_Scope'!$K$5:$K$362,E$3) -> 9 | F9: =COUNTIFS('01_Functional_Scope'!$C$5:$C$362,B9,'01_Functional_Scope'!$K$5:$K$362,F$3) -> 2 | G9: =COUNTIFS('01_Functional_Scope'!$C$5:$C$362,B9,'01_Functional_Scope'!$K$5:$K$362,G$3) -> 0 | H9: =COUNTIFS('01_Functional_Scope'!$C$5:$C$362,B9,'01_Functional_Scope'!$M$5:$M$362,H$3) -> 0
A10: 7 | B10: Thực hiện Nhiệm vụ | C10: Kế hoạch, nhân sự, kinh phí, mua sắm, tài sản và báo cáo. | D10: =COUNTIF('01_Functional_Scope'!$C$5:$C$362,B10) -> 17 | E10: =COUNTIFS('01_Functional_Scope'!$C$5:$C$362,B10,'01_Functional_Scope'!$K$5:$K$362,E$3) -> 10 | F10: =COUNTIFS('01_Functional_Scope'!$C$5:$C$362,B10,'01_Functional_Scope'!$K$5:$K$362,F$3) -> 4 | G10: =COUNTIFS('01_Functional_Scope'!$C$5:$C$362,B10,'01_Functional_Scope'!$K$5:$K$362,G$3) -> 1 | H10: =COUNTIFS('01_Functional_Scope'!$C$5:$C$362,B10,'01_Functional_Scope'!$M$5:$M$362,H$3) -> 1
A11: 8 | B11: Điều chỉnh, Tạm dừng & Dừng | C11: Các loại điều chỉnh nhiệm vụ thuộc RD04. | D11: =COUNTIF('01_Functional_Scope'!$C$5:$C$362,B11) -> 30 | E11: =COUNTIFS('01_Functional_Scope'!$C$5:$C$362,B11,'01_Functional_Scope'!$K$5:$K$362,E$3) -> 18 | F11: =COUNTIFS('01_Functional_Scope'!$C$5:$C$362,B11,'01_Functional_Scope'!$K$5:$K$362,F$3) -> 4 | G11: =COUNTIFS('01_Functional_Scope'!$C$5:$C$362,B11,'01_Functional_Scope'!$K$5:$K$362,G$3) -> 0 | H11: =COUNTIFS('01_Functional_Scope'!$C$5:$C$362,B11,'01_Functional_Scope'!$M$5:$M$362,H$3) -> 0
A12: 9 | B12: Nghiệm thu | C12: Hồ sơ, điều kiện, hội đồng và kết quả RD05. | D12: =COUNTIF('01_Functional_Scope'!$C$5:$C$362,B12) -> 11 | E12: =COUNTIFS('01_Functional_Scope'!$C$5:$C$362,B12,'01_Functional_Scope'!$K$5:$K$362,E$3) -> 7 | F12: =COUNTIFS('01_Functional_Scope'!$C$5:$C$362,B12,'01_Functional_Scope'!$K$5:$K$362,F$3) -> 2 | G12: =COUNTIFS('01_Functional_Scope'!$C$5:$C$362,B12,'01_Functional_Scope'!$K$5:$K$362,G$3) -> 0 | H12: =COUNTIFS('01_Functional_Scope'!$C$5:$C$362,B12,'01_Functional_Scope'!$M$5:$M$362,H$3) -> 0
A13: 10 | B13: Quyết toán | C13: Hồ sơ, chứng từ, đối soát và kết quả RD06. | D13: =COUNTIF('01_Functional_Scope'!$C$5:$C$362,B13) -> 11 | E13: =COUNTIFS('01_Functional_Scope'!$C$5:$C$362,B13,'01_Functional_Scope'!$K$5:$K$362,E$3) -> 8 | F13: =COUNTIFS('01_Functional_Scope'!$C$5:$C$362,B13,'01_Functional_Scope'!$K$5:$K$362,F$3) -> 1 | G13: =COUNTIFS('01_Functional_Scope'!$C$5:$C$362,B13,'01_Functional_Scope'!$K$5:$K$362,G$3) -> 0 | H13: =COUNTIFS('01_Functional_Scope'!$C$5:$C$362,B13,'01_Functional_Scope'!$M$5:$M$362,H$3) -> 0
A14: 11 | B14: Sản phẩm Nghiên cứu & SHTT | C14: Sản phẩm, công bố, công nghệ và SHTT RD07–RD08. | D14: =COUNTIF('01_Functional_Scope'!$C$5:$C$362,B14) -> 23 | E14: =COUNTIFS('01_Functional_Scope'!$C$5:$C$362,B14,'01_Functional_Scope'!$K$5:$K$362,E$3) -> 5 | F14: =COUNTIFS('01_Functional_Scope'!$C$5:$C$362,B14,'01_Functional_Scope'!$K$5:$K$362,F$3) -> 13 | G14: =COUNTIFS('01_Functional_Scope'!$C$5:$C$362,B14,'01_Functional_Scope'!$K$5:$K$362,G$3) -> 1 | H14: =COUNTIFS('01_Functional_Scope'!$C$5:$C$362,B14,'01_Functional_Scope'!$M$5:$M$362,H$3) -> 0
A15: 12 | B15: Báo cáo & Điều hành | C15: Dashboard, KPI, cảnh báo và báo cáo RD09. | D15: =COUNTIF('01_Functional_Scope'!$C$5:$C$362,B15) -> 10 | E15: =COUNTIFS('01_Functional_Scope'!$C$5:$C$362,B15,'01_Functional_Scope'!$K$5:$K$362,E$3) -> 3 | F15: =COUNTIFS('01_Functional_Scope'!$C$5:$C$362,B15,'01_Functional_Scope'!$K$5:$K$362,F$3) -> 7 | G15: =COUNTIFS('01_Functional_Scope'!$C$5:$C$362,B15,'01_Functional_Scope'!$K$5:$K$362,G$3) -> 0 | H15: =COUNTIFS('01_Functional_Scope'!$C$5:$C$362,B15,'01_Functional_Scope'!$M$5:$M$362,H$3) -> 0
... A21: 18 | B21: Trợ giúp & Hỗ trợ Người dùng | C21: Hướng dẫn, onboarding và yêu cầu hỗ trợ. | D21: =COUNTIF('01_Functional_Scope'!$C$5:$C$362,B21) -> 3 | E21: =COUNTIFS('01_Functional_Scope'!$C$5:$C$362,B21,'01_Functional_Scope'!$K$5:$K$362,E$3) -> 0 | F21: =COUNTIFS('01_Functional_Scope'!$C$5:$C$362,B21,'01_Functional_Scope'!$K$5:$K$362,F$3) -> 1 | G21: =COUNTIFS('01_Functional_Scope'!$C$5:$C$362,B21,'01_Functional_Scope'!$K$5:$K$362,G$3) -> 2 | H21: =COUNTIFS('01_Functional_Scope'!$C$5:$C$362,B21,'01_Functional_Scope'!$M$5:$M$362,H$3) -> 0

Sheet 03_Danh_muc
A1: Priority | B1: Release | C1: Trạng thái phạm vi | D1: Loại | E1: Nguồn
A2: Must | B2: Pha 1 | C2: Đề xuất trong phạm vi | D2: Nghiệp vụ | E2: Giữ từ VHT_WBS
A3: Should | B3: Pha 2 | C3: Cần xác nhận | D3: Workflow | E3: Hiệu chỉnh từ VHT_WBS
A4: Could | B4: Pha 3 | C4: Ngoài phạm vi | D4: Nền tảng | E4: Bổ sung
A5: Won't/Để sau | B5: Chưa xếp pha | C5: Hoãn | D5: Cấu hình | E5: Bổ sung theo tài liệu kiến trúc
D6: Tích hợp | E6: Cần xác nhận
D7: Báo cáo
D8: Phân quyền
D9: Bảo mật
D10: Audit
D11: Vận hành
D12: Hỗ trợ

Sheet 04_Thay_doi
A1: NHẬT KÝ HIỆU CHỈNH VÀ BỔ SUNG PHẠM VI
A3: STT | B3: Loại thay đổi | C3: Tham chiếu gốc | D3: Nội dung | E3: Xử lý trong FSL | F3: Ghi chú
A4: 1 | B4: Sửa cấu trúc | C4: Cột D | D4: Cột không có tiêu đề | E4: Đặt tên thành Nhóm chức năng/Sub-module và chuẩn hóa thành trường Nhóm chức năng.
A5: 2 | B5: Bổ sung mã | C5: Cột TT | D5: Cột trống toàn bộ | E5: Sinh STT và Feature ID duy nhất theo phân hệ/module.
A6: 3 | B6: Bổ sung ưu tiên | C6: Cột Priority | D6: Cột trống toàn bộ | E6: Gán MoSCoW sơ bộ và thêm dropdown để hiệu chỉnh. | F6: Cần workshop chốt.
A7: 4 | B7: Sửa lỗi | C7: Dòng 22 | D7: ma trạn quyết định | E7: Chuẩn hóa thành ma trận quyết định/DMN.
A8: 5 | B8: Sửa lỗi | C8: Dòng 27 | D8: Copy ma trận quyết định trong module phê duyệt | E8: Chuẩn hóa thành sao chép ma trận phê duyệt.
A9: 6 | B9: Sửa lỗi | C9: Dòng 34–36 | D9: Trùng tạo Loại phê duyệt, thiếu CRUD | E9: Thay bằng chức năng quản lý danh mục loại phê duyệt đầy đủ.
A10: 7 | B10: Sửa lỗi | C10: Dòng 113 | D10: Lịch sử Hồ sơ quyết toán trong eForm | E10: Thay bằng quản lý lịch sử eForm.
A11: 8 | B11: Phân rã | C11: Dòng 55 | D11: Tích hợp | E11: Tách Integration Hub, 8 connector, monitoring, retry và đối soát. | F11: Phạm vi từng connector cần xác nhận.
A12: 9 | B12: Phân rã | C12: Dòng 107 | D12: Dashboard đa cấp | E12: Tách KPI nhiệm vụ, SLA, kinh phí, nhân sự, sản phẩm và cảnh báo.
A13: 10 | B13: Bổ sung phân hệ | C13: Không có | D13: Hội đồng & Thẩm định | E13: Bổ sung hội đồng, chuyên gia, lịch, phiếu, tổng hợp và biên bản.
A14: 11 | B14: Bổ sung phân hệ | C14: Không có | D14: Thực hiện nhiệm vụ | E14: Bổ sung tiến độ, nhân sự, kinh phí, mua sắm, tài sản và báo cáo.
A15: 12 | B15: Bổ sung phân hệ | C15: Không có | D15: Sản phẩm nghiên cứu & SHTT | E15: Bổ sung RD07, RD08, công bố và công nghệ lõi.
A16: 13 | B16: Bổ sung phân hệ | C16: Không có | D16: Runtime Administration | E16: Bổ sung instance, incident, retry, reassign, cancel, restart và batch.
A17: 14 | B17: Bổ sung nền tảng | C17: Không có | D17: SSO/RBAC/Audit/SLA/Notification/Search | E17: Bổ sung các capability xuyên suốt theo kiến trúc mục tiêu.

Sheet 99_Danh_sach_goc
A1: DANH SÁCH GỐC – VHT_WBS.xlsx (THAM CHIẾU, KHÔNG CHỈNH SỬA)
A2: Column1 | B2: Column2 | C2: Column3 | D2: Column4 | E2: Column5 | F2: Column6 | G2: Column7
A3: TT | B3: Phân hệ | C3: Module | D3: Nhóm chức năng (tiêu đề suy luận) | E3: FS / Chức năng | F3: Ghi chú | G3: Priority
B4: Đăng nhập SSO | C4: Đăng nhập SSO | E4: Đăng nhập/ Đăng xuất trên cổng SSO
B5: Quản trị Quy trình | C5: Quản lý quy trình | E5: Xem Danh sách quy trình
B6: Quản trị Quy trình | C6: Quản lý quy trình | E6: Tìm kiếm/ Lọc quy trình theo nhiều tiêu chí
B7: Quản trị Quy trình | C7: BPMN Core | D7: Kết nối Camunda 8 | E7: Kết nối Camunda 8
B8: Quản trị Quy trình | C8: BPMN Core | D8: Canvas BPMN | E8: Vẽ BPMN và các tiện ích trên Canvas BPMN
B9: Quản trị Quy trình | C9: BPMN Core | D9: Canvas BPMN | E9: Khởi tạo các Element BPMN mẫu
B10: Quản trị Quy trình | C10: Quản lý quy trình | E10: Tạo mới quy trình thông qua vẽ BPMN trực tiếp | F10: Thông tin chung + BPMN
B11: Quản trị Quy trình | C11: Quản lý quy trình | E11: Tạo mới quy trình thông qua import file .bpmn | F11: Thông tin chung + BPMN
B12: Quản trị Quy trình | C12: Quản lý quy trình | E12: Xem chi tiết quy trình | F12: Thông tin chung + BPMN
B13: Quản trị Quy trình | C13: Quản lý quy trình | E13: Chỉnh sửa quy trình | F13: Thông tin chung + BPMN
B14: Quản trị Quy trình | C14: Quản lý quy trình | E14: Xóa quy trình
B15: Quản trị Quy trình | C15: Quản lý quy trình | E15: Test quy trình | F15: Test trước Deploy
B16: Quản trị Quy trình | C16: Quản lý quy trình | E16: Ban hành quy trình | F16: Deploy lên Camunda 8
B17: Quản trị Quy trình | C17: Quản lý quy trình | E17: Tạm ngừng quy trình
B18: Quản trị Quy trình | C18: Quản lý quy trình | E18: Quản lý lịch sử quy trình
B19: Quản trị Quy trình | C19: Quản lý quy trình | E19: Xem tổng quan sơ đồ quy trình bao gồm BPMN + Luồng chi tiết
B20: Quản trị Quy trình | C20: Ma trận quyết định (DMN) | E20: Xem danh sách Ma trận quyết định
B21: Quản trị Quy trình | C21: Ma trận quyết định (DMN) | E21: Tạo mới ma trận quyết định thủ công từ giao diện
B22: Quản trị Quy trình | C22: Ma trận quyết định (DMN) | E22: Tạo mới ma trận quyết định thông qua copy một ma trận quyết định hiện hữu trên hệ thống
B23: Quản trị Quy trình | C23: Ma trận quyết định (DMN) | E23: Xem chi tiết ma trận quyết định
B24: Quản trị Quy trình | C24: Ma trận quyết định (DMN) | E24: Chỉnh sửa ma trạn quyết định
B25: Quản trị Quy trình | C25: Ma trận quyết định (DMN) | E25: Xóa ma trận quyết định
B26: Quản trị Quy trình | C26: Ma trận quyết định (DMN) | E26: Quản lý lịch sử ma trận quyết định
B27: Quản trị Quy trình | C27: Ma trận phê duyệt | E27: Xem danh sách Ma trận phê duyệt
B28: Quản trị Quy trình | C28: Ma trận phê duyệt | E28: Tạo mới ma trận phê duyệt thủ công từ giao diện
... B33: Quản trị Quy trình | C33: Ma trận phê duyệt | E33: Quản lý lịch sử ma trận phê duyệt
B34: Quản trị Quy trình | C34: Ma trận phê duyệt | D34: Ma trận phê duyệt | E34: Test mô phỏng ma trận phê duyệt
B35: Quản trị Quy trình | C35: Ma trận phê duyệt | D35: Loại phê duyệt | E35: Xem danh sách Loại phê duyệt
B36: Quản trị Quy trình | C36: Ma trận phê duyệt | D36: Loại phê duyệt | E36: Tạo Loại phê duyệt
B37: Quản trị Quy trình | C37: Ma trận phê duyệt | D37: Loại phê duyệt | E37: Chỉnh sửa Loại phê duyệt
B38: Quản trị Quy trình | C38: Ma trận phê duyệt | D38: Loại phê duyệt | E38: Tạo mới Loại phê duyệt
B39: Quản trị Quy trình | C39: Ma trận hành động | D39: Luật hiển thị nút | E39: Xem danh sách Luật hiển thị nút
B40: Quản trị Quy trình | C40: Ma trận hành động | D40: Luật hiển thị nút | E40: Tạo mới Luật hiển thị nút
B41: Quản trị Quy trình | C41: Ma trận hành động | D41: Luật hiển thị nút | E41: Xem chi tiết Luật hiển thị nút
B42: Quản trị Quy trình | C42: Ma trận hành động | D42: Luật hiển thị nút | E42: Chỉnh sửa Luật hiển thị nút
B43: Quản trị Quy trình | C43: Ma trận hành động | D43: Luật hiển thị nút | E43: Xóa Luật hiển thị nút
B44: Quản trị Quy trình | C44: Ma trận hành động | D44: Luật hiển thị nút | E44: Test mô phỏng luật hiển thị nút
...
