Workbook
Name a: #REF!
Name a: #REF!
Name a: #REF!
Name a: #REF!
Name a: #REF!
Name a: #REF!
Name a: #REF!
Name a: #REF!
Name DPCD: '[1]BCT-NV (CK)'!$BB$14:$BB$713
Name DT: #REF!
Name DT: #REF!
Name DT: #REF!
Name DT: #REF!
Name DT: #REF!
Name DT: #REF!
Name DT: #REF!
Name DT: #REF!
Name HTTT: #REF!
Name HTTT: #REF!
Name HTTT: #REF!
Name HTTT: #REF!
Name HTTT: #REF!
Name HTTT: #REF!
Name HTTT: #REF!
Name HTTT: #REF!
Name MANV1: '[1]BCT-NV (CK)'!$D$14:$D$713
Name Slicer_TÌNH_TRẠNG_PHÂN_BỔ: #N/A
Name T7.2020: #REF!
Name T7.2020: #REF!
Name T7.2020: #REF!
Name T7.2020: #REF!
Name T7.2020: #REF!
Name T7.2020: #REF!
Name T7.2020: #REF!
Name T7.2020: #REF!

Sheet Estimate HR KH
A1: STT | B1: Module | C1: Chức năng | D1: Mô tả
A2: I | B2: Quản lý đề tài dự án
A3: 1 | C3: Quản lý đề tài đã được phê duyệt | D3: Cho phép import hoặc tạo mới đề tài đã được trình ký
A4: 2 | C4: Quản lý nhân sự thuộc đề tài | D4: Cho phép thêm, sửa update nhân sự thuộc đề tài Cho phép view báo cáo dư kiến chi phí của đề tài theo như nhân sự được load vào đề tài
A5: 3 | C5: Giao nhiệm vụ cho nhân viên thuộc đề tài | D5: Cho phép giao nhiệm vụ của đề tài cho nhân viên
A6: 4 | C6: Báo cáo chi phí đề tài theo tháng và theo lũy kế | D6: Tính chi phí của từng đề tài theo lương thực tế, theo lũy kế đến thời điểm hiện tại
A7: II | B7: Module quản lý lương
A8: 1 | C8: Quản lý lương mục tiêu
A9: 2 | C9: Quản lý lịch sử lương mục tiêu
A10: 3 | C10: Quản lý bảng lương tháng
A11: III | B11: Module chấm công
A12: 1 | C12: Quản lý chấm công : HR Upload bảng chấm công tháng (n-1)
A13: 2 | C13: Chấm công tháng | D13: 1. PA thực hiện chấm công, và view chi phí đã sử dụng, chưa sử dụng 2. HR duyệt công 3. Kế toán xác nhận 4. Xuất báo cáo 5. Trình ký Voffice
A15: IV | B15: Chi phí nhân công
A16: 1 | C16: Tổng hợp chi phí nhân công | D16: Trình ký Voffice các Biểu mẫu tại Sheet 7.BM3.2 BTH CÔNG, Sheet 9.BM 4.1 HR_PBNC Tháng,Sheet 10.BM 4.2 HR_BTH PBNC
A17: 2 | C17: Lập bảng tông hợp chi phí nhân công theo biểu mẫu | D17: Trình ký Voffice sheet 12.BM05_BTH CPNC theo nội dung CV
A18: V | B18: Quản lý nhân viên, phòng ban, đơn vi (Tái sử dụng 1 phần HR)
A19: 1 | C19: Quản lý nhân viên
A20: 2 | C20: Quản lý chức danh, vài trò
A21: 3 | C21: Quản lý cây đơn vị
A22: VI | B22: Xác thực, phân quyền
A23: 1 | C23: Tích hợp xác thực với SSO
A24: 2 | C24: Tích hợp phân quyền với hệ thống phan quền | D24: Tích hợp với hệ thống phân quyền hiện có của khách hàng. (Không phải phân quyền của VTIT)
A25: VII | B25: Tích hợp Voffice để trình ký
A26: 1 | C26: Module chung trình ký chung. Tích hợp Voffice
A27: 2 | C27: Tạo văn bản danh sách nhân sự trình ký
A28: 3 | C28: Trình ký chấm công
A29: 4 | C29: Trình ký CPNC tổng hợp biểu mẫu 7
A30: 5 | C30: Trình ký tổng hợp CPNC biểu mẫu 12

Sheet Sheet1
A1: Module | B1: Tính năng | C1: Ghi chú
A2: Danh mục | B2: Đơn vị | C2: Thông tin đơn vị và mối quan hệ giữa các đơn vị trong mô hình tổ chức
A3: Danh mục | B3: Xử lý màn hình
A4: Danh mục | B4: Xử lý nghiệp vụ CRUD
A5: Danh mục | B5: Xử lý nghiệp vụ export
A6: Danh mục | B6: Xử lý nghiệp vụ import
A7: Danh mục | B7: Chức danh | C7: Thông tin chức danh giống hệ thống nhân sự
A8: Danh mục | B8: Xử lý màn hình
A9: Danh mục | B9: Xử lý nghiệp vụ CRUD
A10: Danh mục | B10: Xử lý nghiệp vụ export
A11: Danh mục | B11: Xử lý nghiệp vụ import
A12: Danh mục | B12: Nhân viên | C12: Thông tin cơ bản và trạng thái nhân viên
A13: Danh mục | B13: Xử lý màn hình
A14: Danh mục | B14: Xử lý nghiệp vụ CRUD
A15: Danh mục | B15: Xử lý nghiệp vụ export
A16: Danh mục | B16: Xử lý nghiệp vụ import
A17: Danh mục | B17: Nguồn kinh phí
A18: Danh mục | B18: Xử lý màn hình
A19: Danh mục | B19: Xử lý nghiệp vụ CRUD
A20: Danh mục | B20: Quản lý thư viện nhiệm vụ
A21: Danh mục | B21: Xử lý màn hình
A22: Danh mục | B22: Xử lý nghiệp vụ CRUD
A23: Danh mục | B23: Xử lý nghiệp vụ export
A24: Danh mục | B24: Xử lý nghiệp vụ import
... A34: Nhiệm vụ | B34: Xử lý nghiệp vụ import
A35: Nhiệm vụ | B35: Danh sách công việc | C35: Danh sách các công việc của đề tài
A36: Nhiệm vụ | B36: Xử lý màn hình
A37: Nhiệm vụ | B37: Xử lý nghiệp vụ CRUD
A38: Nhiệm vụ | B38: Xử lý nghiệp vụ export
A39: Nhiệm vụ | B39: Xử lý nghiệp vụ import
A40: Nhiệm vụ | B40: Danh sách vai trò | C40: Các vai trò PA, PM dự án theo thời gian? Có dùng chung với danh sách nhân sự được không?
A41: Nhiệm vụ | B41: Xử lý màn hình
A42: Nhiệm vụ | B42: Xử lý nghiệp vụ CRUD
A43: Nhiệm vụ | B43: Xử lý nghiệp vụ export
A44: Nhiệm vụ | B44: Xử lý nghiệp vụ import
A45: Nhiệm vụ | B45: Danh sách nhân sự | C45: Lập/ Điều chỉnh danh sách nhân sự và giao việc, vai trò
A46: Nhiệm vụ | B46: Lập danh sách nhân sự tham gia đề tài
A47: Nhiệm vụ | B47: Xử lý màn hình
A48: Nhiệm vụ | B48: Xử lý nghiệp vụ CRUD
A49: Nhiệm vụ | B49: Xử lý nghiệp vụ export
...

Sheet 0.QuyTrinh
A1: QUY TRÌNH THỰC HIỆN
A11: CÁC TABS Ở CỘT TRÁI | B11: NỘI DUNG MÀN HÌNH HIỂN THỊ
A12: 1. Danh sách nhân sự | B12: Nội dung 4 TABS như mô tả ở các sheet 1-4
A13: 2. Chấm công
A14: 3. Báo cáo
A15: 4. Trình ký
F19: Xác nhận | G19: Xác nhận thông tin công PA đã chấm
G20: TH1: PA đơn vị chấm công không phải đơn vị chủ trì => PA/PM của đơn vị chủ trì xác nhận
G21: TH2: PA đơn vị chấm công = ĐƠn vị chủ trì => Vừa submit vừa xác nhận
F22: Thẩm định | G22: HR nhận thông tin => Thẩm định qua trao đổi tương tác ngoài.

Sheet 1.DS Nhân sự
A1: NỘI DUNG FIX TRÊN MÀN HÌNH: ĐƠN VỊ…
A4: TAB 1: DANH SÁCH NHÂN SỰ (Màn hình acc PA/PM)
A5: Hiện toàn bộ DS nhân sự của Đơn vị phân bổ (Đơn vị cấp 5) | J5: Chọn Thời gian: | K5: Tháng/Năm | L5: Mặc định để tháng hiện tại cần phân bổ, các tháng trước hiện thông tin đã duyệt
J6: Tỷ lệ Chi phí nhân công đã phân bổ của Đơn vị cấp 5 theo tháng đã chọn | K6: …% | L6: bằng CPNC phân bổ/quỹ lương tháng đó
B8: TT | C8: MÃ NV | D8: Họ và tên | E8: Chức danh | F8: THÔNG TIN CÔNG THÁNG…
F9: 1 | G9: 2 | H9: 3 | I9: … | J9: … | K9: 30 | L9: 31
F10: T2 | G10: T3 | H10: T4 | I10: … | J10: … | K10: T7 | L10: CN | O10: Chú thích màu theo các nhiệm vụ:
B11: 1 | C11: 123204 | D11: Nguyễn Văn X1 | E11: Phó giám đốc | P11: Dự án A
B12: 2 | C12: 130448 | D12: Nguyễn Văn X2 | E12: Trưởng phòng | P12: Dự án B
B13: 3 | C13: 131748 | D13: Nguyễn Văn X3 | E13: Kỹ sư phát triển phần mềm | P13: Đề tài C
B14: 4 | C14: 135755 | D14: Nguyễn Văn X4 | E14: Kỹ sư chính | P14: Đề tài B
B15: 5 | C15: 135756 | D15: Nguyễn Văn X5 | E15: Kỹ sư chính | P15: T7/CN/Nghỉ phép
B16: 6 | C16: 135757 | D16: Nguyễn Văn X6 | E16: Kỹ sư Kiểm thử | P16: Chưa chấm công
A19: TAB 1: DANH SÁCH NHÂN SỰ (Màn hình acc HR)
J20: Chọn Thời gian: | K20: Tháng/Năm | L20: Mặc định để tháng hiện tại cần phân bổ, các tháng trước hiện thông tin đã duyệt
B22: Đơn vị cấp 4 | C22: Đơn vị cấp 5 | D22: Trạng thái | E22: Tỷ lệ Chi phí nhân công đã phân bổ của Đơn vị cấp 5 theo tháng đã chọn
B23: Khối 1 | C23: Trung tâm… | D23: Chưa chấm công | E23: …% | F23: + Xem bảng chấm công
D24: PA đã submit chấm công
D25: PA/PM chủ trì đã xác nhận
D26: HR Hoàn thành trình ký
B27: Hiển thị theo thứ tự | C27: Hiển thị theo thứ tự cùng ĐV cấp 4 | D27: Tự động cập nhật 1 trong 4 trạng thái trên | F27: Click vào đây để xem tab chấm công của đơn vị đó
B28: Khối 1
B29: Khối 2
B30: Khối 3
B31: Trung tâm Kinh doanh
B32: Trung tâm QLCL
A35: Note: | B35: Khi PA/PM vào chọn tháng => Nhìn luôn toàn bộ nhân sự của ông ấy tham gia vào những nhiệm vụ nào
B36: PM/PA quản lý nhân sự thông qua đơn vị
B37: Đơn vị | C37: Giống mô hình của tập đoàn
B39: PA ở phòng tổng hợp => Chấm công cho đơn vị khác.
B40: => Đổi thành cho chọn chủ động, không mặc định hiển thị theo đơn vị trực thuộc cấp 5 nữa, mỗi lần chọn 1 đơn vị
B41: 1 nhiệm vụ có 1 PM và 1 PA đơn vị chủ trì
B42: Mỗi đơn vị phân bổ có 1 PA
B43: => Quản lý danh sách vai trò PA, PM của nhiệm vụ (Khác với chức danh/ vị trí của HRM)

Sheet 2.Chấm công
A1: NỘI DUNG FIX TRÊN MÀN HÌNH: ĐƠN VỊ…
A3: TAB 2: CHẤM CÔNG
C5: TÊN NHIỆM VỤ | D5: Gõ tên nhiệm vụ/Mã nhiệm vụ để ra nhiệm vụ đã có thông tin, nếu chưa có thông tin thì ấn nút tạo mới/import | K5: + SỬA | L5: + TẠO MỚI | M5: + IMPORT
M6: BM5 DS Nhiệm vụ
B8: 1 | C8: Mã nhiệm vụ:
B9: 2 | C9: Đơn vị chủ trì: | D9: Đơn vị cấp 5 | E9: Đơn vị cấp 4 | F9: Xem sheet LIST
B10: 3 | C10: Chủ nhiệm đề tài/dự án: | E10: Trợ lý đề tài/Dự án:
B11: 4 | C11: Thời gian bắt đầu: | D11: mm/yyyy | E11: Thời gian kết thúc: | F11: mm/yyyy
B12: 5 | C12: Phân loại: | D12: Đề tài KHCN/Phương án kinh doanh/Dự án ĐTPT/Nhiệm vụ QPAN
B13: 6 | C13: Tổng dự toán được phê duyệt: | D13: VNĐ
B14: 7 | C14: Chi phí nhân công được phê duyệt: | D14: VNĐ
C17: >> NẾU MỤC 5 CHỌN ĐỀ TÀI KHCN, GIAO DIỆN HIỂN THỊ NHƯ SAU:
D19: Chi phí nhân công được phê duyệt | E19: Chi phí nhân công đã phân bổ đến tháng N-1 | F19: Dự phòng | G19: Chi phí nhân công còn lại | H19: Tạm tính lương 6 tháng | I19: Tạm tính lương năm
C20: Nội dung CV 1 | D20: VNĐ | E20: VNĐ | F20: VNĐ | G20: VNĐ
C21: Nội dung CV 2 | D21: VNĐ | E21: VNĐ | F21: VNĐ | G21: VNĐ
C22: Nội dung CV 3 | D22: VNĐ | E22: VNĐ | F22: VNĐ | G22: VNĐ
C23: Nội dung CV 4 | D23: VNĐ | E23: VNĐ | F23: VNĐ | G23: VNĐ
C24: Nội dung CV 5 | D24: VNĐ | E24: VNĐ | F24: VNĐ | G24: VNĐ
B26: BẢNG CHẤM CÔNG (KHCN) | K26: Thời gian: | M26: chọn theo Tháng/Năm
K27: CPNC tạm tính: | M27: VNĐ
M28: phần mềm tính theo Bảng lương import
K29: Xuất DS Nhân sự excel | L29: XUẤT BẢNG CÔNG excel | M29: XUẤT BẢNG LƯƠNG excel
K30: BM 1 | L30: BM 2.1 | M30: BM 3.1
A32: TT | B32: MÃ NV | C32: Họ và tên | D32: Chức danh | E32: Nội dung công việc tham gia nhiệm vụ | F32: CHẤM CÔNG | M32: Ghi chú
F33: 1 | G33: 2 | H33: 3 | I33: … | J33: … | K33: 30 | L33: 31
F34: T2 | G34: T3 | H34: T4 | I34: … | J34: … | K34: T7 | L34: CN
A35: 1 | B35: 123204 | C35: Nguyễn Văn X1 | D35: Phó giám đốc | E35: Chọn theo DS nhiệm vụ đc phê duyệt | N35: + SỬA | O35: + XOÁ
A36: 2 | B36: 130448 | C36: Nguyễn Văn X2 | D36: Trưởng phòng | N36: + SỬA | O36: + XOÁ
A37: 3 | B37: 131748 | C37: Nguyễn Văn X3 | D37: Kỹ sư phát triển phần mềm | N37: + SỬA | O37: + XOÁ
A38: 4 | B38: 135755 | C38: Nguyễn Văn X4 | D38: Kỹ sư chính | N38: + SỬA | O38: + XOÁ
A39: 5 | B39: 135756 | C39: Nguyễn Văn X5 | D39: Kỹ sư chính | N39: + SỬA | O39: + XOÁ
A40: 6 | B40: 135757 | C40: Nguyễn Văn X6 | D40: Kỹ sư Kiểm thử | N40: + SỬA | O40: + XOÁ
B41: + THÊM MỚI
L44: SUBMIT | M44: PA/PM chủ trì xác nhận
C52: >> NẾU MỤC 5 CHỌN "PAKD", GIAO DIỆN HIỂN THỊ NHƯ SAU:
C54: Phân nguồn | D54: Sản phẩm | E54: Thời gian bắt đầu | F54: Thời gian kết thúc: | G54: Chi phí nhân công được phê duyệt | H54: Chi phí nhân công đã phân bổ đến tháng N-1 | I54: Dự phòng | J54: Chi phí nhân công còn lại | K54: Tạm tính lương 6 tháng | L54: Tạm tính lương năm
C55: SXKD | D55: A | G55: VNĐ | H55: VNĐ | I55: VNĐ | J55: VNĐ
D56: B | G56: VNĐ | H56: VNĐ | I56: VNĐ | J56: VNĐ
C57: Bán hàng | D57: A | G57: VNĐ | H57: VNĐ | I57: VNĐ | J57: VNĐ
D58: B | G58: VNĐ | H58: VNĐ | I58: VNĐ | J58: VNĐ
...

Sheet 3.Báo cáo
C1: NỘI DUNG FIX TRÊN MÀN HÌNH: ĐƠN VỊ - KHỐI
A3: TAB 3: BÁO CÁO (ACCOUNT PA/PM ĐƠN VỊ CHỦ TRÌ)
B6: Theo dõi nguồn CPNC của các nhiệm vụ
E7: ĐVT: | F7: Triệu đồng | G7: Xuất Báo cáo excel
G8: BM5 Danh sách nhiệm vụ (Xuất riêng nhiệm vụ của đơn vị chủ trì)
B9: Nhiệm vụ của ĐV Chủ trì | C9: Phân nguồn | D9: Nguồn đã được lập dự toán (Bằng nguồn CPNC đc phê duyệt + Dự phòng nếu có) | E9: Nguồn đã phân bổ | F9: Nguồn cần để phân bổ 6 tháng/Năm | G9: Nguồn còn lại
B10: Nhiệm vụ 1 (KHCN) | C10: KHCN | D10: 10000 | E10: 11000 | F10: 1000 | G10: =D10-E10-F10 -> -2000
B11: Nhiệm vụ 2 (SXKD) | C11: SXKD | D11: 20000 | E11: 8000 | F11: 1500 | G11: =D11-E11-F11 -> 10500
B12: Nhiệm vụ 2 (Bán hàng) | C12: Bán hàng | D12: 3000 | E12: 1000 | F12: 200 | G12: =D12-E12-F12 -> 1800
B13: Nhiệm vụ 3 (ĐTPT) | C13: ĐTPT | D13: 30000 | E13: 22000 | F13: 3000 | G13: =D13-E13-F13 -> 5000
B14: Tổng | D14: =SUM(D10:D13) -> 63000 | E14: =SUM(E10:E13) -> 42000 | F14: =SUM(F10:F13) -> 5700 | G14: =SUM(G10:G13) -> 15300
B18: Tỷ lệ PBNC của đơn vị trong năm | C18: Tính bằng tổng CPNC đc phân bổ mỗi tháng/Quỹ lương tháng của đơn vị cấp 5
C20: 45658 | D20: 45689 | E20: 45717 | F20: 45748 | G20: 45778 | H20: 45809 | I20: 45839 | J20: 45870 | K20: 45901 | L20: 45931 | M20: 45962 | N20: 45992
C21: 0.58012517 | D21: 0.6395034 | E21: 0.66823368 | F21: 0.70030638 | G21: 0.75341836
B36: Nội dung gửi mail cảnh báo | C36: PA/PM | D36: GĐTT | E36: BGĐ Khối | F36: HR | G36: Ghi chú
A37: 1 | B37: Nhiệm vụ sắp hết nguồn | C37: Cảnh báo nếu tháng N+1 và N+2 CPNC phân bổ = tháng N thì cảnh báo ko đủ nguồn | D37: Cảnh báo nếu tháng N+1 CPNC phân bổ = tháng N thì ko đủ nguồn | F37: Cảnh báo nếu tháng N+1 và N+2 CPNC phân bổ = tháng N thì cảnh báo ko đủ nguồn
A38: 2 | B38: Tỷ lệ PBNC của đơn vị hàng tháng | D38: Hàng tháng | F38: Hàng tháng | G38: Nếu <70% có nội dung cảnh báo trong mail
A39: 3 | B39: Tỷ lệ PBNC của Khối hàng quý | E39: Hàng quý | F39: Hàng quý | G39: Nếu <70% có nội dung cảnh báo trong mail
A41: TAB 3: BÁO CÁO (ACCOUNT HR)
B43: TỔNG HỢP
C45: 45658 | D45: 45689 | E45: 45717 | F45: 45748 | G45: 45778 | H45: 45809 | I45: 45839 | J45: 45870 | K45: 45901 | L45: 45931 | M45: 45962 | N45: 45992
B46: Tỷ lệ PBNC của 3 KHỐI | C46: 0.58012517 | D46: 0.6395034 | E46: 0.66823368 | F46: 0.70030638 | G46: 0.75341836
B47: Tính bằng tổng CPNC đc phân bổ mỗi tháng/Quỹ lương tháng của tổng 3 Khối
B49: Tỷ lệ PBNC của VHT | C49: =C46-10% -> 0.48012517 | D49: =D46-10% -> 0.5395034 | E49: =E46-10% -> 0.56823368 | F49: =F46-10% -> 0.60030638 | G49: =G46-10% -> 0.65341836
B50: Tính bằng tổng CPNC đc phân bổ mỗi tháng/Quỹ lương tháng của cả VHT
C51: => Quỹ lương tháng của VHT: Tính theo tổng của bảng lương tháng đã import
B67: Danh sách nhiệm vụ sắp hết nguồn
K68: Xuất Báo cáo excel
B69: Nhiệm vụ sắp hết nguồn (Nguồn còn lại dự kiến ko đủ phân bổ cho 2 tháng tiếp theo) | C69: ĐV Chủ trì | D69: Phân nguồn | E69: Nguồn đã được lập dự toán | F69: Dự phòng | G69: Nguồn đã phân bổ | H69: Nguồn cần để phân bổ 6 tháng/Năm | I69: Nguồn còn lại | K69: BM5 DS Nhiệm vụ (Xuất tất cả nhiệm vụ của VHT)
A70: 1 | B70: Nhiệm vụ 1 (KHCN)
A71: 2 | B71: Nhiệm vụ 2 (SXKD)
A72: 3 | B72: Nhiệm vụ 2 (Bán hàng)
B73: Nhiệm vụ 3 (ĐTPT)

Sheet 4. Trình ký
C1: NỘI DUNG FIX TRÊN MÀN HÌNH: ĐƠN VỊ - KHỐI
A3: TAB 4: TRÌNH KÝ | C3: Chỉ hiện với acc HR
B5: Thời gian: | C5: chọn theo Tháng/Năm | G5: IMPORT | I5: XUẤT EXCEL | J5: TRÌNH KÝ VO THEO NHIỆM VỤ | K5: TRÌNH KÝ VO BẢNG TỔNG HỢP
G6: Bao gồm: | I6: Bao gồm: | J6: Bao gồm: | K6: Bao gồm
G7: 0. BẢNG LƯƠNG THÁNG | H7: Nhập hàng tháng | I7: 3. BẢNG TH PHÂN BỔ | J7: 1. DANH SÁCH NHÂN SỰ | K7: 4. BẢNG TH PHÂN BỔ CPNC
G8: 0. BẢNG CÔNG THÁNG | H8: Nhập hàng tháng | I8: 4. BẢNG TH PHÂN BỔ CPNC | J8: 2.1 & 2.2. BẢNG CÔNG
G9: 5. DANH SÁCH NHIỆM VỤ | H9: Nhập khi có nhiệm vụ mới | J9: 3.1 & 3.2. BẢNG LƯƠNG

Sheet List
A1: Chọn tên Khối (Đơn vị cấp 4) | B1: Chọn tên Đơn vị cấp 5
A2: Khối 1 - TCT CNC | B2: Khối 1
A3: Khối 2 - TCT CNC | B3: Ban Giám đốc Khối
A4: Khối 3 - TCT CNC | B4: Phòng Kinh doanh
A5: Trung tâm Kinh doanh - TCT CNC | B5: Phòng Kiểu dáng và đồ họa
A6: Trung tâm QLCL - TCT CNC | B6: Phòng Tổng hợp
B7: Trung tâm Chỉ huy điều khiển
B8: Trung tâm Công nghệ Cơ khí - Tự động hóa
B9: Trung tâm Đảm bảo chất lượng
B10: Trung tâm dịch vụ sau bán hàng
B11: Trung tâm Khí cụ bay
B12: Trung tâm Mô hình mô phỏng
B13: Trung tâm Nghiên cứu giải pháp tích hợp công nghệ cao
B14: Trung tâm Quang điện tử
B15: Trung tâm Rada
B16: Trung tâm sản xuất
B17: Trung tâm Tác chiến điện tử
B18: Trung tâm Thông tin Quân sự
... B42: Trung tâm QLCL

Sheet BM0.Bang luong thang import
B1: TẬP ĐOÀN CÔNG NGHIỆP - VIỄN THÔNG QUÂN ĐỘI | P1: CỘNG HOÀ XÃ HỘI CHỦ NGHĨA VIỆT NAM
B2: TỔNG CÔNG TY CÔNG NGHIỆP CÔNG NGHỆ CAO VIETTEL | P2: Độc lập - Tự do - Hạnh phúc
A4: BẢNG LƯƠNG THÁNG
M8: AG | N8: AK | O8: AL | P8: AM | Q8: AN | R8: AO | S8: AQ | U8: =SUM(H14:T14) -> 47093365550
A9: Stt | B9: Mã nhân viên | C9: Họ và tên | D9: Đối tượng | E9: Thông tin công | G9: Lương tháng (trừ làm thêm, lương phép) | H9: Lương tháng (trừ BH cá nhân) | I9: Truy thu/truy lĩnh (lương tháng lần 2) | J9: Lương SXKD (nếu có) | K9: Lương thử việc, tập nghề | L9: Lương kinh doanh thử việc, tập nghề | M9: Bảo hiểm, KPCĐ | T9: Các khoản ăn ca, điện thoại, chi phí, phụ cấp | V9: Đơn vị | W9: Đơn vị cấp 5 | X9: Đơn vị cấp 4 | Y9: GT/TT
M10: BHXH | O10: BHYT | Q10: BHTN | S10: KPCĐ
E11: Công tiêu chuẩn | F11: Công tính lương | M11: Cá nhân | N11: Đơn vị | O11: Cá nhân | P11: Đơn vị | Q11: Cá nhân | R11: Đơn vị
A13: STT | B13: MNV | C13: HỌ VÀ TÊN | D13: Đối tượng | E13: Công tiêu chuẩn | F13: Công tính lương | G13: Lương tháng (trừ làm thêm, lương phép) | H13: Lương tháng (trừ BH cá nhân) | I13: Truy thu/truy lĩnh (lương tháng lần 2) | J13: Lương SXKD (nếu có) | K13: Lương thử việc, tập nghề | L13: Lương kinh doanh thử việc, tập nghề | M13: Cá nhân | N13: Đơn vị | O13: Cá nhân | P13: Đơn vị | Q13: Cá nhân | R13: Đơn vị | S13: KPCĐ | T13: Các khoản ăn ca, điện thoại, chi phí, phụ cấp | U13: CỘNG | V13: Đơn vị | W13: Đơn vị | X13: Khối/Phòng ban
C14: Tổng | G14: =SUM(G15:G1048576) -> 41712607632 | H14: =SUM(H15:H1048576) -> 40342565043 | I14: =SUM(I15:I1048576) -> 0 | J14: =SUM(J15:J1048576) -> 0 | K14: =SUM(K15:K1048576) -> 759073941 | L14: =SUM(L15:L1048576) -> 0 | M14: =SUM(M15:M1048576) -> 1095926072 | N14: =SUM(N15:N1048576) -> 2388761735 | ... U14: =SUM(U15:U1048576) -> 47093365550 | V14: =SUBTOTAL(9,V15:V1059) -> 0
A15: =SUBTOTAL(3,$B$15:B15) -> 0 | B15: 000375 | C15: Nguyễn Ngọc Hà | D15: QNCN | E15: 21 | F15: 21 | G15: 20790517 | H15: =+G15-SUM(M15,O15,Q15) -> 19410666 | M15: 1379851 | N15: 3018425 | O15: 0 | P15: 0 | Q15: 0 | R15: 0 | S15: 344963 | T15: 1047000 | U15: =+SUM(H15:T15) -> 25200905 | W15: =+VLOOKUP($B15,[2]Time_S4!$B:$G,6,0) -> Phòng Nhân sự | X15: =IF(W15="Phòng Kinh doanh","Trung tâm Kinh doanh - TCT CNC",+VLOOKUP($B15,[2]Time_S4!$B:$G,5,0)) -> Khối cơ quan - TCT CNC
A16: =SUBTOTAL(3,$B$15:B16) -> 0 | B16: 001615 | C16: Đỗ Đức Ánh | D16: VCQP | E16: 21 | F16: 21 | G16: 25852064 | H16: =+G16-SUM(M16,O16,Q16) -> 24849780 | M16: 844029 | N16: 1846313 | O16: 158255 | P16: 316511 | Q16: 0 | R16: 0 | S16: 211007 | T16: 930000 | U16: =+SUM(H16:T16) -> 29155895 | W16: =+VLOOKUP($B16,[2]Time_S4!$B:$G,6,0) -> Phòng Kinh doanh | X16: =IF(W16="Phòng Kinh doanh","Trung tâm Kinh doanh - TCT CNC",+VLOOKUP($B16,[2]Time_S4!$B:$G,5,0)) -> Trung tâm Kinh doanh - TCT CNC
A17: =SUBTOTAL(3,$B$15:B17) -> 0 | B17: 001618 | C17: Nguyễn Thị Hiên | D17: QNCN | E17: 21 | F17: 21 | G17: 68679032 | H17: =+G17-SUM(M17,O17,Q17) -> 67077536 | M17: 1601496 | N17: 3503273 | O17: 0 | P17: 0 | Q17: 0 | R17: 0 | S17: 400374 | T17: 1847000 | U17: =+SUM(H17:T17) -> 74429679 | W17: =+VLOOKUP($B17,[2]Time_S4!$B:$G,6,0) -> Phòng Hành chính | X17: =IF(W17="Phòng Kinh doanh","Trung tâm Kinh doanh - TCT CNC",+VLOOKUP($B17,[2]Time_S4!$B:$G,5,0)) -> Khối cơ quan - TCT CNC
A18: =SUBTOTAL(3,$B$15:B18) -> 0 | B18: 002127 | C18: Đỗ Thu Hằng | D18: VCQP | E18: 21 | F18: 21 | G18: 20131774 | H18: =+G18-SUM(M18,O18,Q18) -> 19254934 | M18: 738392 | N18: 1615232 | O18: 138448 | P18: 276897 | Q18: 0 | R18: 0 | S18: 184598 | T18: 1047000 | U18: =+SUM(H18:T18) -> 23255501 | W18: =+VLOOKUP($B18,[2]Time_S4!$B:$G,6,0) -> Hệ thống Lab dùng chung | X18: =IF(W18="Phòng Kinh doanh","Trung tâm Kinh doanh - TCT CNC",+VLOOKUP($B18,[2]Time_S4!$B:$G,5,0)) -> Trung tâm Quản lý chất lượng - TCT CNC
A19: =SUBTOTAL(3,$B$15:B19) -> 0 | B19: 003738 | C19: Nguyễn Thế Anh | D19: HDDH | E19: 21 | F19: 21 | G19: 21013687 | H19: =+G19-SUM(M19,O19,Q19) -> 20097079 | M19: 698368 | N19: 1527680 | O19: 130944 | P19: 261888 | Q19: 87296 | R19: 87296 | S19: 174592 | T19: 1866000 | U19: =+SUM(H19:T19) -> 24931143 | W19: =+VLOOKUP($B19,[2]Time_S4!$B:$G,6,0) -> Trung tâm dịch vụ sau bán hàng | X19: =IF(W19="Phòng Kinh doanh","Trung tâm Kinh doanh - TCT CNC",+VLOOKUP($B19,[2]Time_S4!$B:$G,5,0)) -> Khối 1 - TCT CNC
A20: =SUBTOTAL(3,$B$15:B20) -> 0 | B20: 003965 | C20: Trần Trung Trực | D20: SQ | E20: 21 | F20: 21 | G20: 90999558 | H20: =+G20-SUM(M20,O20,Q20) -> 89307270 | M20: 1692288 | N20: 3701880 | O20: 0 | P20: 0 | Q20: 0 | R20: 0 | S20: 423072 | T20: 1730000 | U20: =+SUM(H20:T20) -> 96854510 | W20: =+VLOOKUP($B20,[2]Time_S4!$B:$G,6,0) -> Trung tâm Nghiên cứu giải pháp tích hợp công nghệ cao | X20: =IF(W20="Phòng Kinh doanh","Trung tâm Kinh doanh - TCT CNC",+VLOOKUP($B20,[2]Time_S4!$B:$G,5,0)) -> Khối 1 - TCT CNC
A21: =SUBTOTAL(3,$B$15:B21) -> 0 | B21: 003966 | C21: Nguyễn Gia Vinh | D21: SQ | E21: 21 | F21: 21 | G21: 90999558 | H21: =+G21-SUM(M21,O21,Q21) -> 89482676 | M21: 1516882 | N21: 3318179 | O21: 0 | P21: 0 | Q21: 0 | R21: 0 | S21: 379220 | T21: 1730000 | U21: =+SUM(H21:T21) -> 96426957 | W21: =+VLOOKUP($B21,[2]Time_S4!$B:$G,6,0) -> Phòng Chiến lược - KHCN | X21: =IF(W21="Phòng Kinh doanh","Trung tâm Kinh doanh - TCT CNC",+VLOOKUP($B21,[2]Time_S4!$B:$G,5,0)) -> Khối cơ quan - TCT CNC
A22: =SUBTOTAL(3,$B$15:B22) -> 1 | B22: 003990 | C22: Vũ Ngọc Vinh | D22: SQ | E22: 21 | F22: 21 | G22: 97935011 | H22: =+G22-SUM(M22,O22,Q22) -> 96438909 | M22: 1496102 | N22: 3272724 | O22: 0 | P22: 0 | Q22: 0 | R22: 0 | S22: 374026 | T22: 1230000 | U22: =+SUM(H22:T22) -> 102811761 | W22: =+VLOOKUP($B22,[2]Time_S4!$B:$G,6,0) -> Trung tâm Chỉ huy điều khiển | X22: =IF(W22="Phòng Kinh doanh","Trung tâm Kinh doanh - TCT CNC",+VLOOKUP($B22,[2]Time_S4!$B:$G,5,0)) -> Khối 1 - TCT CNC
A23: =SUBTOTAL(3,$B$15:B23) -> 1 | B23: 003994 | C23: Đinh Ngọc Kỳ Sơn | D23: VCQP | E23: 21 | F23: 21 | G23: 26960570 | H23: =+G23-SUM(M23,O23,Q23) -> 25846580 | M23: 938097 | N23: 2052086 | O23: 175893 | P23: 351786 | Q23: 0 | R23: 0 | S23: 234524 | T23: 930000 | U23: =+SUM(H23:T23) -> 30528966 | W23: =+VLOOKUP($B23,[2]Time_S4!$B:$G,6,0) -> Phòng Công nghệ thông tin | X23: =IF(W23="Phòng Kinh doanh","Trung tâm Kinh doanh - TCT CNC",+VLOOKUP($B23,[2]Time_S4!$B:$G,5,0)) -> Khối cơ quan - TCT CNC
A24: =SUBTOTAL(3,$B$15:B24) -> 1 | B24: 004011 | C24: Phan Thanh Trung | D24: SQ | E24: 21 | F24: 21 | G24: 170228538 | H24: =+G24-SUM(M24,O24,Q24) -> 168536250 | M24: 1692288 | N24: 3701880 | O24: 0 | P24: 0 | Q24: 0 | R24: 0 | S24: 423072 | T24: 3432000 | U24: =+SUM(H24:T24) -> 177785490 | W24: =+VLOOKUP($B24,[2]Time_S4!$B:$G,6,0) -> Ban Giám đốc Khối | X24: =IF(W24="Phòng Kinh doanh","Trung tâm Kinh doanh - TCT CNC",+VLOOKUP($B24,[2]Time_S4!$B:$G,5,0)) -> Khối 2 - TCT CNC
A25: =SUBTOTAL(3,$B$15:B25) -> 1 | B25: 004012 | C25: Tống Thanh Sơn | D25: SQ | E25: 21 | F25: 21 | G25: 152160840 | H25: =+G25-SUM(M25,O25,Q25) -> 150643958 | M25: 1516882 | N25: 3318179 | O25: 0 | P25: 0 | Q25: 0 | R25: 0 | S25: 379220 | T25: 2730000 | U25: =+SUM(H25:T25) -> 158588239 | W25: =+VLOOKUP($B25,[2]Time_S4!$B:$G,6,0) -> Ban Giám đốc | X25: =IF(W25="Phòng Kinh doanh","Trung tâm Kinh doanh - TCT CNC",+VLOOKUP($B25,[2]Time_S4!$B:$G,5,0)) -> Trung tâm Kinh doanh - TCT CNC
A26: =SUBTOTAL(3,$B$15:B26) -> 1 | B26: 004032 | C26: Nguyễn Đức Nam | D26: HDDH | E26: 21 | F26: 21 | G26: 78568069 | H26: =+G26-SUM(M26,O26,Q26) -> 77120245 | M26: 1103104 | N26: 2413040 | O26: 206832 | P26: 413664 | Q26: 137888 | R26: 137888 | S26: 275776 | T26: 1230000 | U26: =+SUM(H26:T26) -> 83038437 | W26: =+VLOOKUP($B26,[2]Time_S4!$B:$G,6,0) -> Trung tâm Rada | X26: =IF(W26="Phòng Kinh doanh","Trung tâm Kinh doanh - TCT CNC",+VLOOKUP($B26,[2]Time_S4!$B:$G,5,0)) -> Khối 1 - TCT CNC
... A51: =SUBTOTAL(3,$B$15:B51) -> 1 | B51: 011220 | C51: Phan Viết Thời | D51: VCQP | E51: 21 | F51: 21 | G51: 33829476 | H51: =+G51-SUM(M51,O51,Q51) -> 32753900 | M51: 905748 | N51: 1981325 | O51: 169828 | P51: 339656 | Q51: 0 | R51: 0 | S51: 226437 | T51: 1030000 | U51: =+SUM(H51:T51) -> 37406894 | W51: =+VLOOKUP($B51,[2]Time_S4!$B:$G,6,0) -> Trung tâm dịch vụ sau bán hàng | X51: =IF(W51="Phòng Kinh doanh","Trung tâm Kinh doanh - TCT CNC",+VLOOKUP($B51,[2]Time_S4!$B:$G,5,0)) -> Khối 2 - TCT CNC
A52: =SUBTOTAL(3,$B$15:B52) -> 1 | B52: 011238 | C52: Lê Thúy Mai | D52: QNCN | E52: 21 | F52: 21 | G52: 42467798 | H52: =+G52-SUM(M52,O52,Q52) -> 40955316 | J52: 0 | L52: 0 | M52: 1512482 | N52: 3308555 | O52: 0 | P52: 0 | Q52: 0 | R52: 0 | S52: 378121 | T52: 1347000 | U52: =+SUM(H52:T52) -> 47501474 | W52: =+VLOOKUP($B52,[2]Time_S4!$B:$G,6,0) -> Phòng Thương hiệu và truyền thông | X52: =IF(W52="Phòng Kinh doanh","Trung tâm Kinh doanh - TCT CNC",+VLOOKUP($B52,[2]Time_S4!$B:$G,5,0)) -> Trung tâm Kinh doanh - TCT CNC
A53: =SUBTOTAL(3,$B$15:B53) -> 1 | B53: 011350 | C53: Nguyễn Hoàng Long | D53: SQ | E53: 21 | F53: 21 | G53: 100964258 | H53: =+G53-SUM(M53,O53,Q53) -> 99365383 | J53: 0 | L53: 0 | M53: 1598875 | N53: 3497540 | O53: 0 | P53: 0 | Q53: 0 | R53: 0 | S53: 399719 | T53: 2730000 | U53: =+SUM(H53:T53) -> 107591517 | W53: =+VLOOKUP($B53,[2]Time_S4!$B:$G,6,0) -> Ban Giám đốc | X53: =IF(W53="Phòng Kinh doanh","Trung tâm Kinh doanh - TCT CNC",+VLOOKUP($B53,[2]Time_S4!$B:$G,5,0)) -> Khối 3 - TCT CNC
A54: =SUBTOTAL(3,$B$15:B54) -> 1 | B54: 012486 | C54: Đoàn Hữu Đồng | D54: QNCN | E54: 21 | F54: 21 | G54: 31091030 | H54: =+G54-SUM(M54,O54,Q54) -> 29696764 | J54: 0 | L54: 0 | M54: 1394266 | N54: 3049956 | O54: 0 | P54: 0 | Q54: 0 | R54: 0 | S54: 348566 | T54: 1381000 | U54: =+SUM(H54:T54) -> 35870552 | W54: =+VLOOKUP($B54,[2]Time_S4!$B:$G,6,0) -> Văn phòng | X54: =IF(W54="Phòng Kinh doanh","Trung tâm Kinh doanh - TCT CNC",+VLOOKUP($B54,[2]Time_S4!$B:$G,5,0)) -> Khối cơ quan - TCT CNC
A55: =SUBTOTAL(3,$B$15:B55) -> 1 | B55: 012721 | C55: Hồ Trọng Hiếu | D55: SQ | E55: 21 | F55: 21 | G55: 72242477 | H55: =+G55-SUM(M55,O55,Q55) -> 70385453 | M55: 1857024 | N55: 4062240 | O55: 0 | P55: 0 | Q55: 0 | R55: 0 | S55: 464256 | T55: 2432000 | U55: =+SUM(H55:T55) -> 79200973 | W55: =+VLOOKUP($B55,[2]Time_S4!$B:$G,6,0) -> Văn phòng | X55: =IF(W55="Phòng Kinh doanh","Trung tâm Kinh doanh - TCT CNC",+VLOOKUP($B55,[2]Time_S4!$B:$G,5,0)) -> Khối cơ quan - TCT CNC
A56: =SUBTOTAL(3,$B$15:B56) -> 1 | B56: 013943 | C56: Phạm Thế Anh | D56: QNCN | E56: 21 | F56: 21 | G56: 16076467 | H56: =+G56-SUM(M56,O56,Q56) -> 14859667 | M56: 1216800 | N56: 2661750 | O56: 0 | P56: 0 | Q56: 0 | R56: 0 | S56: 304200 | T56: 930000 | U56: =+SUM(H56:T56) -> 19972417 | W56: =+VLOOKUP($B56,[2]Time_S4!$B:$G,6,0) -> Phòng Hành chính | X56: =IF(W56="Phòng Kinh doanh","Trung tâm Kinh doanh - TCT CNC",+VLOOKUP($B56,[2]Time_S4!$B:$G,5,0)) -> Khối cơ quan - TCT CNC
A57: =SUBTOTAL(3,$B$15:B57) -> 1 | B57: 014553 | C57: Hà Minh Đức | D57: QNCN | E57: 21 | F57: 0 | G57: 19322071 | H57: =+G57-SUM(M57,O57,Q57) -> 18054321 | M57: 1267750 | N57: 2773204 | O57: 0 | P57: 0 | Q57: 0 | R57: 0 | S57: 316938 | T57: 0 | U57: =+SUM(H57:T57) -> 22412213 | W57: =+VLOOKUP($B57,[2]Time_S4!$B:$G,6,0) -> Phòng Hành chính | X57: =IF(W57="Phòng Kinh doanh","Trung tâm Kinh doanh - TCT CNC",+VLOOKUP($B57,[2]Time_S4!$B:$G,5,0)) -> Khối cơ quan - TCT CNC
A58: =SUBTOTAL(3,$B$15:B58) -> 1 | B58: 014913 | C58: Trần Thị Hồng Nhung | D58: QNCN | E58: 21 | F58: 21 | G58: 27552070 | H58: =+G58-SUM(M58,O58,Q58) -> 26145356 | M58: 1406714 | N58: 3077188 | O58: 0 | P58: 0 | Q58: 0 | R58: 0 | S58: 351679 | T58: 1398000 | U58: =+SUM(H58:T58) -> 32378937 | W58: =+VLOOKUP($B58,[2]Time_S4!$B:$G,6,0) -> Phòng Hợp đồng | X58: =IF(W58="Phòng Kinh doanh","Trung tâm Kinh doanh - TCT CNC",+VLOOKUP($B58,[2]Time_S4!$B:$G,5,0)) -> Trung tâm Mua sắm - TCT CNC
A59: =SUBTOTAL(3,$B$15:B59) -> 1 | B59: 015237 | C59: Nguyễn Trần Huy Toàn | D59: QNCN | E59: 21 | F59: 21 | G59: 17142387 | H59: =+G59-SUM(M59,O59,Q59) -> 15867181 | M59: 1275206 | N59: 2789514 | O59: 0 | P59: 0 | Q59: 0 | R59: 0 | S59: 318802 | T59: 1530000 | U59: =+SUM(H59:T59) -> 21780703 | W59: =+VLOOKUP($B59,[2]Time_S4!$B:$G,6,0) -> Phòng Hành chính | X59: =IF(W59="Phòng Kinh doanh","Trung tâm Kinh doanh - TCT CNC",+VLOOKUP($B59,[2]Time_S4!$B:$G,5,0)) -> Khối cơ quan - TCT CNC
A60: =SUBTOTAL(3,$B$15:B60) -> 1 | B60: 015413 | C60: Tạ Diệu Thúy | D60: HDDH | E60: 21 | F60: 21 | G60: 27552070 | H60: =+G60-SUM(M60,O60,Q60) -> 26536510 | M60: 773760 | N60: 1692600 | O60: 145080 | P60: 290160 | Q60: 96720 | R60: 96720 | S60: 193440 | T60: 1047000 | U60: =+SUM(H60:T60) -> 30871990 | W60: =+VLOOKUP($B60,[2]Time_S4!$B:$G,6,0) -> Phòng Đảm bảo chất lượng | X60: =IF(W60="Phòng Kinh doanh","Trung tâm Kinh doanh - TCT CNC",+VLOOKUP($B60,[2]Time_S4!$B:$G,5,0)) -> Trung tâm Quản lý chất lượng - TCT CNC
A61: =SUBTOTAL(3,$B$15:B61) -> 1 | B61: 016049 | C61: Lê Thị Út Lan | D61: HDDH | E61: 21 | F61: 21 | G61: 20344177 | H61: =+G61-SUM(M61,O61,Q61) -> 19427569 | M61: 698368 | N61: 1527680 | O61: 130944 | P61: 261888 | Q61: 87296 | R61: 87296 | S61: 174592 | T61: 1047000 | U61: =+SUM(H61:T61) -> 23442633 | W61: =+VLOOKUP($B61,[2]Time_S4!$B:$G,6,0) -> Phòng Tổng hợp | X61: =IF(W61="Phòng Kinh doanh","Trung tâm Kinh doanh - TCT CNC",+VLOOKUP($B61,[2]Time_S4!$B:$G,5,0)) -> Khối 1 - TCT CNC
A62: =SUBTOTAL(3,$B$15:B62) -> 1 | B62: 016474 | C62: Mai Gia Hà | D62: QNCN | E62: 21 | F62: 21 | G62: 69403754 | H62: =+G62-SUM(M62,O62,Q62) -> 67923002 | M62: 1480752 | N62: 3239145 | O62: 0 | P62: 0 | Q62: 0 | R62: 0 | S62: 370188 | T62: 1730000 | U62: =+SUM(H62:T62) -> 74743087 | W62: =+VLOOKUP($B62,[2]Time_S4!$B:$G,6,0) -> Phòng Công nghệ thông tin | X62: =IF(W62="Phòng Kinh doanh","Trung tâm Kinh doanh - TCT CNC",+VLOOKUP($B62,[2]Time_S4!$B:$G,5,0)) -> Khối cơ quan - TCT CNC
A63: =SUBTOTAL(3,$B$15:B63) -> 1 | B63: 017247 | C63: Cao Thị Lệ Thúy | D63: HDDH | E63: 21 | F63: 21 | G63: 21857433 | H63: =+G63-SUM(M63,O63,Q63) -> 20940825 | M63: 698368 | N63: 1527680 | O63: 130944 | P63: 261888 | Q63: 87296 | R63: 87296 | S63: 174592 | T63: 1515000 | U63: =+SUM(H63:T63) -> 25423889 | W63: =+VLOOKUP($B63,[2]Time_S4!$B:$G,6,0) -> Bộ phận Hỗ trợ nghiệp vụ | X63: =IF(W63="Phòng Kinh doanh","Trung tâm Kinh doanh - TCT CNC",+VLOOKUP($B63,[2]Time_S4!$B:$G,5,0)) -> Trung tâm Kinh doanh - TCT CNC
A64: =SUBTOTAL(3,$B$15:B64) -> 1 | B64: 018257 | C64: Nguyễn Thị Thu Hiền | D64: VCQP | E64: 21 | F64: 21 | G64: 20790517 | H64: =+G64-SUM(M64,O64,Q64) -> 19797103 | M64: 836559 | N64: 1829974 | O64: 156855 | P64: 313710 | Q64: 0 | R64: 0 | S64: 209140 | T64: 1047000 | U64: =+SUM(H64:T64) -> 24190341 | W64: =+VLOOKUP($B64,[2]Time_S4!$B:$G,6,0) -> Phòng Đảm bảo hàng hóa | X64: =IF(W64="Phòng Kinh doanh","Trung tâm Kinh doanh - TCT CNC",+VLOOKUP($B64,[2]Time_S4!$B:$G,5,0)) -> Trung tâm Mua sắm - TCT CNC
A65: =SUBTOTAL(3,$B$15:B65) -> 1 | B65: 019658 | C65: Lê Trường Giang | D65: SQ | E65: 21 | F65: 21 | G65: 132630507 | H65: =+G65-SUM(M65,O65,Q65) -> 131301013 | M65: 1329494 | N65: 2908269 | O65: 0 | P65: 0 | Q65: 0 | R65: 0 | S65: 332374 | T65: 3432000 | U65: =+SUM(H65:T65) -> 139303150 | W65: =+VLOOKUP($B65,[2]Time_S4!$B:$G,6,0) -> Ban Giám đốc Khối | X65: =IF(W65="Phòng Kinh doanh","Trung tâm Kinh doanh - TCT CNC",+VLOOKUP($B65,[2]Time_S4!$B:$G,5,0)) -> Khối 2 - TCT CNC
A66: =SUBTOTAL(3,$B$15:B66) -> 1 | B66: 019662 | C66: Nguyễn Đức Tuyền | D66: HDDH | E66: 21 | F66: 21 | G66: 48861507 | H66: =+G66-SUM(M66,O66,Q66) -> 47616795 | M66: 948352 | N66: 2074520 | O66: 177816 | P66: 355632 | Q66: 118544 | R66: 118544 | S66: 237088 | T66: 1030000 | U66: =+SUM(H66:T66) -> 52677291 | W66: =+VLOOKUP($B66,[2]Time_S4!$B:$G,6,0) -> Trung tâm Nghiên cứu thiết bị vô tuyến băng rộng | X66: =IF(W66="Phòng Kinh doanh","Trung tâm Kinh doanh - TCT CNC",+VLOOKUP($B66,[2]Time_S4!$B:$G,5,0)) -> Khối 2 - TCT CNC
... A385: =SUBTOTAL(3,$B$15:B385) -> 2 | B385: 177559 | C385: Nguyễn Thị Hồng | D385: HDDH | E385: 21 | F385: 21 | G385: 40650853 | H385: =+G385-SUM(M385,O385,Q385) -> 39525925 | M385: 857088 | N385: 1874880 | O385: 160704 | P385: 321408 | Q385: 107136 | R385: 107136 | S385: 214272 | T385: 1147000 | U385: =+SUM(H385:T385) -> 44315549 | W385: =+VLOOKUP($B385,[2]Time_S4!$B:$G,6,0) -> Trung tâm Phát triển nền tảng thanh toán | X385: =IF(W385="Phòng Kinh doanh","Trung tâm Kinh doanh - TCT CNC",+VLOOKUP($B385,[2]Time_S4!$B:$G,5,0)) -> Khối 2 - TCT CNC
A386: =SUBTOTAL(3,$B$15:B386) -> 2 | B386: 177560 | C386: Trần Văn Hùng | D386: HDDH | E386: 21 | F386: 21 | G386: 29826640 | H386: =+G386-SUM(M386,O386,Q386) -> 28759000 | J386: 0 | M386: 813440 | N386: 1779400 | O386: 152520 | P386: 305040 | Q386: 101680 | R386: 101680 | S386: 203360 | T386: 1630000 | U386: =+SUM(H386:T386) -> 33846120 | W386: =+VLOOKUP($B386,[2]Time_S4!$B:$G,6,0) -> Trung tâm dịch vụ sau bán hàng | X386: =IF(W386="Phòng Kinh doanh","Trung tâm Kinh doanh - TCT CNC",+VLOOKUP($B386,[2]Time_S4!$B:$G,5,0)) -> Khối 2 - TCT CNC
A387: =SUBTOTAL(3,$B$15:B387) -> 2 | B387: 177564 | C387: Trần Đức Bình | D387: HDDH | E387: 21 | F387: 21 | G387: 49418622 | H387: =+G387-SUM(M387,O387,Q387) -> 48173910 | J387: 0 | M387: 948352 | N387: 2074520 | O387: 177816 | P387: 355632 | Q387: 118544 | R387: 118544 | S387: 237088 | T387: 1030000 | U387: =+SUM(H387:T387) -> 53234406 | W387: =+VLOOKUP($B387,[2]Time_S4!$B:$G,6,0) -> Trung tâm Nghiên cứu Công nghệ chuyển mạch | X387: =IF(W387="Phòng Kinh doanh","Trung tâm Kinh doanh - TCT CNC",+VLOOKUP($B387,[2]Time_S4!$B:$G,5,0)) -> Khối 2 - TCT CNC
...

Sheet BM0.Bang cong thang import
D1: => Chuyển thành số để import
A3: 04. Đơn vị cấp 4 | B3: 05. Đơn vị cấp 5 (F) | C3: ID cá nhân | D3: Tên đầy đủ | E3: 01 | F3: 02 | G3: 03 | H3: 04 | I3: 05 | J3: 06 | K3: 07 | L3: 08 | M3: 09 | N3: 10 | O3: 11 | P3: 12 | Q3: 13 | R3: 14 | S3: 15 | T3: 16 | U3: 17 | V3: 18 | W3: 19 | X3: 20 | Y3: 21 | Z3: 22 | AA3: 23 | AB3: 24 | AC3: 25 | AD3: 26 | AE3: 27 | AF3: 28 | AG3: 29 | AH3: 30 | AI3: 31 | AJ3: Ngày công chế độ | AK3: Ngày công thực tế | AL3: Công nghỉ phép | AM3: Công nghỉ việc riêng có hưởng lương | AN3: Công tính lương
A4: Khối 1 - TCT CNC - 9013948 | B4: Ban Giám đốc Khối - 9014043 | C4: 087233 | D4: Dương Anh Trà | F4: X:8 | G4: X:8 | H4: X:8 | I4: X:8 | J4: X:8 | M4: X:8 | N4: X:8 | O4: X:8 | P4: X:8 | Q4: X:8 | T4: X:8 | U4: X:8 | V4: X:8 | W4: X:8 | X4: X:8 | AA4: X:8 | AB4: X:8 | AC4: X:8 | AD4: X:8 | AE4: X:8 | AH4: X:8 | AJ4: 21 | AK4: 21 | AL4: 0 | AM4: 0 | AN4: 21
A5: Khối 1 - TCT CNC - 9013948 | B5: Ban Giám đốc Khối - 9014043 | C5: 059526 | D5: Trần Vũ Hợp | F5: X:8 | G5: X:8 | H5: X:8 | I5: X:8 | J5: X:8 | M5: X:8 | N5: X:8 | O5: X:8 | P5: X:8 | Q5: X:8 | T5: X:8 | U5: X:8 | V5: X:8 | W5: X:8 | X5: X:8 | AA5: X:8 | AB5: X:8 | AC5: X:8 | AD5: X:8 | AE5: X:8 | AH5: X:8 | AJ5: 21 | AK5: 21 | AL5: 0 | AM5: 0 | AN5: 21
A6: Khối 1 - TCT CNC - 9013948 | B6: Phòng Kinh doanh - 9033765 | C6: 206277 | D6: Nguyễn Hoàng Việt | F6: X:8 | G6: X:8 | H6: X:8 | I6: X:8 | J6: X:8 | M6: X:8 | N6: X:8 | O6: X:8 | P6: X:8 | Q6: X:8 | T6: X:8 | U6: X:8 | V6: X:8 | W6: X:8 | X6: X:8 | AA6: X:8 | AB6: X:8 | AC6: X:8 | AD6: X:8 | AE6: X:8 | AH6: X:8 | AJ6: 21 | AK6: 21 | AL6: 0 | AM6: 0 | AN6: 21
A7: Khối 1 - TCT CNC - 9013948 | B7: Phòng Kinh doanh - 9033765 | C7: 074176 | D7: Nguyễn Đình Thắng | F7: X:8 | G7: X:8 | H7: X:8 | I7: X:8 | J7: X:8 | M7: X:8 | N7: X:8 | O7: X:8 | P7: X:8 | Q7: X:8 | T7: X:8 | U7: X:8 | V7: X:8 | W7: X:8 | X7: X:8 | AA7: X:8 | AB7: X:8 | AC7: X:8 | AD7: X:8 | AE7: X:8 | AH7: X:8 | AJ7: 21 | AK7: 21 | AL7: 0 | AM7: 0 | AN7: 21
A8: Khối 1 - TCT CNC - 9013948 | B8: Phòng Kinh doanh - 9033765 | C8: 001615 | D8: Đỗ Đức Ánh | F8: X:8 | G8: X:8 | H8: X:8 | I8: X:8 | J8: X:8 | M8: X:8 | N8: X:8 | O8: X:8 | P8: X:8 | Q8: X:8 | T8: X:8 | U8: X:8 | V8: X:8 | W8: X:8 | X8: X:8 | AA8: X:8 | AB8: X:8 | AC8: X:8 | AD8: X:8 | AE8: X:8 | AH8: X:8 | AJ8: 21 | AK8: 21 | AL8: 0 | AM8: 0 | AN8: 21
A9: Khối 1 - TCT CNC - 9013948 | B9: Phòng Kiểu dáng và đồ họa - 9033773 | C9: 269742 | D9: Chu Trọng Kiên | F9: X:8 | G9: P:8 | H9: X:8 | I9: X:8 | J9: X:8 | M9: X:8 | N9: X:8 | O9: X:8 | P9: X:8 | Q9: X:8 | T9: X:8 | U9: X:8 | V9: X:8 | W9: X:8 | X9: X:8 | AA9: X:8 | AB9: X:8 | AC9: X:8 | AD9: X:8 | AE9: X:8 | AH9: X:8 | AJ9: 21 | AK9: 20 | AL9: 1 | AM9: 0 | AN9: 21
A10: Khối 1 - TCT CNC - 9013948 | B10: Phòng Kiểu dáng và đồ họa - 9033773 | C10: 210043 | D10: Hoàng Thu Trang | F10: X:8 | G10: X:8 | H10: X:8 | I10: X:8 | J10: X:8 | M10: X:8 | N10: X:8 | O10: DL:8 | P10: DL:8 | Q10: DL:8 | T10: X:8 | U10: X:8 | V10: X:8 | W10: X:8 | X10: X:8 | AA10: X:8 | AB10: X:8 | AC10: X:8 | AD10: X:8 | AE10: X:8 | AH10: X:8 | AJ10: 21 | AK10: 21 | AL10: 0 | AM10: 0 | AN10: 21
A11: Khối 1 - TCT CNC - 9013948 | B11: Phòng Kiểu dáng và đồ họa - 9033773 | C11: 176234 | D11: Lê Minh Quang | F11: X:8 | G11: X:8 | H11: X:8 | I11: X:8 | J11: X:8 | M11: X:8 | N11: X:8 | O11: X:8 | P11: X:8 | Q11: X:8 | T11: X:8 | U11: X:8 | V11: X:8 | W11: X:8 | X11: X:8 | AA11: X:8 | AB11: X:8 | AC11: X:8 | AD11: X:8 | AE11: X:8 | AH11: X:8 | AJ11: 21 | AK11: 21 | AL11: 0 | AM11: 0 | AN11: 21
A12: Khối 1 - TCT CNC - 9013948 | B12: Phòng Kiểu dáng và đồ họa - 9033773 | C12: 293213 | D12: Lê Ngọc Anh | F12: X:8 | G12: X:8 | H12: X:8 | I12: X:8 | J12: X:8 | M12: X:8 | N12: X:8 | O12: X:8 | P12: X:8 | Q12: X:8 | T12: X:8 | U12: X:8 | V12: X:8 | W12: X:8 | X12: X:8 | AA12: X:8 | AB12: X:8 | AC12: X:8 | AD12: X:8 | AE12: X:8 | AH12: X:8 | AJ12: 21 | AK12: 21 | AL12: 0 | AM12: 0 | AN12: 21
A13: Khối 1 - TCT CNC - 9013948 | B13: Phòng Kiểu dáng và đồ họa - 9033773 | C13: 204896 | D13: Nguyễn Ngọc Hiệp | F13: X:8 | G13: X:8 | H13: X:8 | I13: X:8 | J13: X:8 | M13: X:8 | N13: X:8 | O13: X:8 | P13: X:8 | Q13: X:8 | T13: X:8 | U13: X:8 | V13: X:8 | W13: X:8 | X13: X:8 | AA13: X:8 | AB13: X:8 | AC13: X:8 | AD13: X:8 | AE13: X:8 | AH13: P:8 | AJ13: 21 | AK13: 20 | AL13: 1 | AM13: 0 | AN13: 21
A14: Khối 1 - TCT CNC - 9013948 | B14: Phòng Kiểu dáng và đồ họa - 9033773 | C14: 243250 | D14: Nguyễn Thùy Tiên | F14: X:8 | G14: X:8 | H14: X:8 | I14: X:8 | J14: X:8 | M14: X:8 | N14: X:8 | O14: DL:8 | P14: DL:8 | Q14: DL:8 | T14: X:8 | U14: X:8 | V14: X:8 | W14: X:8 | X14: X:8 | AA14: X:8 | AB14: X:8 | AC14: X:8 | AD14: X:8 | AE14: X:8 | AH14: X:8 | AJ14: 21 | AK14: 21 | AL14: 0 | AM14: 0 | AN14: 21
A15: Khối 1 - TCT CNC - 9013948 | B15: Phòng Kiểu dáng và đồ họa - 9033773 | C15: 251479 | D15: Nguyễn Việt Hà | F15: X:8 | G15: X:8 | H15: X:8 | I15: X:8 | J15: X:8 | M15: X:8 | N15: X:8 | O15: X:8 | P15: X:8 | Q15: X:8 | T15: X:8 | U15: X:8 | V15: X:8 | W15: X:8 | X15: X:8 | AA15: X:8 | AB15: X:8 | AC15: X:8 | AD15: X:8 | AE15: X:8 | AH15: X:8 | AJ15: 21 | AK15: 21 | AL15: 0 | AM15: 0 | AN15: 21
... A25: Khối 1 - TCT CNC - 9013948 | B25: Phòng Kiểu dáng và đồ họa - 9033773 | C25: 095099 | D25: Đặng Lưu Hạnh | F25: X:8 | G25: X:8 | H25: X:8 | I25: X:8 | J25: X:8 | M25: X:8 | N25: X:8 | O25: X:8 | P25: X:8 | Q25: P:8 | T25: X:8 | U25: X:8 | V25: X:8 | W25: X:8 | X25: X:8 | AA25: X:8 | AB25: X:8 | AC25: X:8 | AD25: X:8 | AE25: X:8 | AH25: X:8 | AJ25: 21 | AK25: 20 | AL25: 1 | AM25: 0 | AN25: 21
A26: Khối 1 - TCT CNC - 9013948 | B26: Phòng Kiểu dáng và đồ họa - 9033773 | C26: 441035 | D26: Đỗ Ngọc Phi Long | F26: X:8 | G26: X:8 | H26: X:8 | I26: X:8 | J26: X:8 | M26: X:8 | N26: X:8 | O26: X:8 | P26: X:8 | Q26: X:8 | AJ26: 21 | AK26: 10 | AL26: 0 | AM26: 0 | AN26: 10
A27: Khối 1 - TCT CNC - 9013948 | B27: Phòng Kiểu dáng và đồ họa - 9033773 | C27: 290432 | D27: Đỗ Việt Trung | F27: X:8 | G27: X:8 | H27: X:8 | I27: X:8 | J27: X:8 | M27: X:8 | N27: X:8 | O27: X:8 | P27: X:8 | Q27: X:8 | T27: X:8 | U27: X:8 | V27: X:8 | W27: X:8 | X27: X:8 | AA27: X:8 | AB27: X:8 | AC27: X:8 | AD27: X:8 | AE27: X:4; P:4 | AH27: X:8 | AJ27: 21 | AK27: 20.5 | AL27: 0.5 | AM27: 0 | AN27: 21
A28: Khối 1 - TCT CNC - 9013948 | B28: Phòng Tổng hợp - 9014098 | C28: 056957 | D28: Hoàng Thị Kim Thoa | F28: X:8 | G28: X:8 | H28: X:8 | I28: X:8 | J28: X:8 | M28: X:8 | N28: X:8 | O28: X:8 | P28: X:8 | Q28: X:8 | T28: P:8 | U28: P:8 | V28: X:8 | W28: X:8 | X28: X:8 | AA28: X:8 | AB28: X:8 | AC28: X:8 | AD28: X:8 | AE28: X:8 | AH28: X:8 | AJ28: 21 | AK28: 19 | AL28: 2 | AM28: 0 | AN28: 21
A29: Khối 1 - TCT CNC - 9013948 | B29: Phòng Tổng hợp - 9014098 | C29: 045097 | D29: Hoàng Thị Nga | F29: P:8 | G29: P:8 | H29: P:8 | I29: X:8 | J29: X:8 | M29: X:8 | N29: X:8 | O29: X:8 | P29: X:8 | Q29: X:8 | T29: X:8 | U29: X:8 | V29: X:8 | W29: X:8 | X29: X:8 | AA29: X:8 | AB29: X:8 | AC29: X:8 | AD29: X:8 | AE29: X:8 | AH29: X:8 | AJ29: 21 | AK29: 18 | AL29: 3 | AM29: 0 | AN29: 21
A30: Khối 1 - TCT CNC - 9013948 | B30: Phòng Tổng hợp - 9014098 | C30: 016049 | D30: Lê Thị Út Lan | F30: P:8 | G30: X:8 | H30: X:8 | I30: X:8 | J30: X:8 | M30: X:8 | N30: X:8 | O30: X:8 | P30: X:8 | Q30: X:8 | T30: X:8 | U30: X:8 | V30: X:8 | W30: X:8 | X30: X:8 | AA30: X:8 | AB30: X:8 | AC30: X:8 | AD30: X:8 | AE30: X:8 | AH30: X:8 | AJ30: 21 | AK30: 20 | AL30: 1 | AM30: 0 | AN30: 21
A31: Khối 1 - TCT CNC - 9013948 | B31: Phòng Tổng hợp - 9014098 | C31: 204945 | D31: Lương Mỹ Linh | F31: DS:8 | G31: DS:8 | H31: DS:8 | I31: DS:8 | J31: DS:8 | M31: X:8 | N31: X:8 | O31: X:8 | P31: X:8 | Q31: X:8 | T31: X:8 | U31: X:8 | V31: X:8 | W31: P:8 | X31: X:8 | AA31: X:8 | AB31: X:8 | AC31: X:8 | AD31: X:8 | AE31: X:8 | AH31: X:8 | AJ31: 21 | AK31: 15 | AL31: 1 | AM31: 0 | AN31: 16
A32: Khối 1 - TCT CNC - 9013948 | B32: Phòng Tổng hợp - 9014098 | C32: 284785 | D32: Mai Thu Hà | F32: DS:8 | G32: DS:8 | H32: DS:8 | I32: DS:8 | J32: DS:8 | M32: X:8 | N32: X:8 | O32: X:8 | P32: X:8 | Q32: P:8 | T32: X:8 | U32: X:8 | V32: X:8 | W32: X:8 | X32: X:8 | AA32: X:8 | AB32: X:8 | AC32: X:8 | AD32: X:8 | AE32: X:8 | AH32: X:8 | AJ32: 21 | AK32: 15 | AL32: 1 | AM32: 0 | AN32: 16
A33: Khối 1 - TCT CNC - 9013948 | B33: Phòng Tổng hợp - 9014098 | C33: 137168 | D33: Nguyễn Hương Giang | F33: X:8 | G33: X:8 | H33: X:8 | I33: X:8 | J33: X:8 | M33: X:8 | N33: X:8 | O33: X:8 | P33: X:8 | Q33: X:8 | T33: X:8 | U33: X:8 | V33: X:8 | W33: X:8 | X33: X:8 | AA33: X:8 | AB33: X:8 | AC33: X:8 | AD33: X:8 | AE33: X:8 | AH33: X:8 | AJ33: 21 | AK33: 21 | AL33: 0 | AM33: 0 | AN33: 21
A34: Khối 1 - TCT CNC - 9013948 | B34: Phòng Tổng hợp - 9014098 | C34: 118760 | D34: Nguyễn Thị Linh | F34: X:8 | G34: X:8 | H34: X:8 | I34: X:8 | J34: X:8 | M34: X:8 | N34: DL:8 | O34: DL:8 | P34: DL:8 | Q34: P:8 | T34: X:8 | U34: X:8 | V34: X:8 | W34: X:8 | X34: X:8 | AA34: X:8 | AB34: X:8 | AC34: X:8 | AD34: X:8 | AE34: X:8 | AH34: X:8 | AJ34: 21 | AK34: 20 | AL34: 1 | AM34: 0 | AN34: 21
A35: Khối 1 - TCT CNC - 9013948 | B35: Phòng Tổng hợp - 9014098 | C35: 185613 | D35: Nguyễn Thị Phương Anh | F35: X:8 | G35: X:8 | H35: X:8 | I35: X:8 | J35: X:8 | M35: X:8 | N35: X:8 | O35: P:8 | P35: P:8 | Q35: P:8 | T35: X:8 | U35: X:8 | V35: X:8 | W35: X:8 | X35: X:8 | AA35: X:8 | AB35: X:8 | AC35: X:8 | AD35: X:8 | AE35: X:8 | AH35: X:8 | AJ35: 21 | AK35: 18 | AL35: 3 | AM35: 0 | AN35: 21
A36: Khối 1 - TCT CNC - 9013948 | B36: Phòng Tổng hợp - 9014098 | C36: 063770 | D36: Trương Thị Thùy Dung | F36: TS:8 | G36: TS:8 | H36: TS:8 | I36: TS:8 | J36: TS:8 | M36: TS:8 | N36: TS:8 | O36: TS:8 | P36: TS:8 | Q36: TS:8 | T36: TS:8 | U36: TS:8 | V36: TS:8 | W36: TS:8 | X36: TS:8 | AA36: TS:8 | AB36: TS:8 | AC36: TS:8 | AD36: DS:8 | AE36: DS:8 | AH36: DS:8 | AJ36: 21 | AK36: 0 | AL36: 0 | AM36: 0 | AN36: 0
A37: Khối 1 - TCT CNC - 9013948 | B37: Phòng Tổng hợp - 9014098 | C37: 108598 | D37: Tống Thị Thùy Linh | F37: X:8 | G37: X:8 | H37: X:8 | I37: X:8 | J37: X:8 | M37: X:8 | N37: X:8 | O37: X:8 | P37: X:8 | Q37: X:8 | T37: X:8 | U37: X:8 | V37: X:8 | W37: X:8 | X37: X:8 | AA37: X:8 | AB37: X:8 | AC37: X:8 | AD37: X:8 | AE37: X:8 | AH37: X:8 | AJ37: 21 | AK37: 21 | AL37: 0 | AM37: 0 | AN37: 21
A38: Khối 1 - TCT CNC - 9013948 | B38: Phòng Tổng hợp - 9014098 | C38: 004040 | D38: Vũ Thị Dương Hùng Hoàn | F38: X:8 | G38: X:8 | H38: X:8 | I38: X:8 | J38: X:8 | M38: X:8 | N38: X:8 | O38: X:8 | P38: X:8 | Q38: X:8 | T38: X:8 | U38: X:8 | V38: X:8 | W38: X:8 | X38: X:8 | AA38: X:8 | AB38: X:8 | AC38: X:8 | AD38: X:8 | AE38: X:8 | AH38: X:8 | AJ38: 21 | AK38: 21 | AL38: 0 | AM38: 0 | AN38: 21
... A62: Khối 1 - TCT CNC - 9013948 | B62: Trung tâm Chỉ huy điều khiển - 9014071 | C62: 467403 | D62: Nguyễn Quang Huy | F62: X:8 | G62: X:8 | H62: X:8 | I62: X:8 | J62: X:8 | M62: X:8 | N62: X:8 | O62: X:8 | P62: X:8 | Q62: X:8 | T62: X:8 | U62: X:8 | V62: X:8 | W62: X:8 | X62: X:8 | AA62: X:8 | AB62: X:8 | AC62: X:8 | AD62: X:8 | AE62: X:8 | AH62: X:8 | AJ62: 21 | AK62: 21 | AL62: 0 | AM62: 0 | AN62: 21
A63: Khối 1 - TCT CNC - 9013948 | B63: Trung tâm Chỉ huy điều khiển - 9014071 | C63: 447101 | D63: Nguyễn Thanh Sang | AJ63: 21 | AK63: 2 | AL63: 0 | AM63: 0 | AN63: 2
A64: Khối 1 - TCT CNC - 9013948 | B64: Trung tâm Chỉ huy điều khiển - 9014071 | C64: 247601 | D64: Nguyễn Thị Mai | F64: X:8 | G64: X:8 | H64: DL:8 | I64: DL:8 | J64: DL:8 | M64: X:8 | N64: X:8 | O64: X:8 | P64: X:8 | Q64: X:8 | T64: X:8 | U64: X:8 | V64: X:8 | W64: X:8 | X64: X:8 | AA64: X:8 | AB64: X:8 | AC64: X:8 | AD64: X:8 | AE64: X:8 | AH64: X:8 | AJ64: 21 | AK64: 21 | AL64: 0 | AM64: 0 | AN64: 21
A65: Khối 1 - TCT CNC - 9013948 | B65: Trung tâm Chỉ huy điều khiển - 9014071 | C65: 087316 | D65: Nguyễn Thị Thùy Linh | F65: X:8 | G65: X:8 | H65: DL:8 | I65: DL:8 | J65: DL:8 | M65: X:8 | N65: X:8 | O65: X:8 | P65: X:8 | Q65: X:8 | T65: X:8 | U65: X:8 | V65: X:8 | W65: X:8 | X65: X:8 | AA65: X:8 | AB65: X:8 | AC65: X:8 | AD65: X:8 | AE65: X:8 | AH65: X:8 | AJ65: 21 | AK65: 21 | AL65: 0 | AM65: 0 | AN65: 21
A66: Khối 1 - TCT CNC - 9013948 | B66: Trung tâm Chỉ huy điều khiển - 9014071 | C66: 458501 | D66: Nguyễn Việt Hoàng | F66: X:8 | G66: X:8 | H66: DL:8 | I66: DL:8 | J66: DL:8 | M66: X:8 | N66: X:8 | O66: X:8 | P66: X:8 | Q66: X:8 | T66: X:8 | U66: X:8 | V66: X:8 | W66: X:8 | X66: X:8 | AA66: X:8 | AB66: X:8 | AC66: X:8 | AD66: X:8 | AE66: X:8 | AH66: X:8 | AJ66: 21 | AK66: 21 | AL66: 0 | AM66: 0 | AN66: 21
A67: Khối 1 - TCT CNC - 9013948 | B67: Trung tâm Chỉ huy điều khiển - 9014071 | C67: 194533 | D67: Nguyễn Văn Cương | F67: X:8 | G67: X:8 | H67: DL:8 | I67: DL:8 | J67: DL:8 | M67: X:8 | N67: X:8 | O67: X:8 | P67: X:8 | Q67: X:8 | T67: X:8 | U67: X:8 | V67: X:8 | W67: X:8 | X67: X:8 | AA67: X:8 | AB67: X:8 | AC67: X:8 | AD67: X:8 | AE67: X:8 | AH67: X:8 | AJ67: 21 | AK67: 21 | AL67: 0 | AM67: 0 | AN67: 21
A68: Khối 1 - TCT CNC - 9013948 | B68: Trung tâm Chỉ huy điều khiển - 9014071 | C68: 225347 | D68: Nguyễn Văn Hoàng | F68: P:8 | G68: X:8 | H68: DL:8 | I68: DL:8 | J68: DL:8 | M68: X:8 | N68: X:8 | O68: X:8 | P68: X:8 | Q68: X:8 | T68: X:8 | U68: P:8 | V68: X:8 | W68: X:8 | X68: X:8 | AA68: X:8 | AB68: X:8 | AC68: X:8 | AD68: X:8 | AE68: X:8 | AH68: X:8 | AJ68: 21 | AK68: 19 | AL68: 2 | AM68: 0 | AN68: 21
A69: Khối 1 - TCT CNC - 9013948 | B69: Trung tâm Chỉ huy điều khiển - 9014071 | C69: 207638 | D69: Nguyễn Văn Tuấn | F69: X:8 | G69: X:8 | H69: DL:8 | I69: DL:8 | J69: DL:8 | M69: X:8 | N69: X:8 | O69: X:8 | P69: X:8 | Q69: X:8 | T69: X:8 | U69: X:8 | V69: X:8 | W69: X:8 | X69: X:8 | AA69: X:8 | AB69: X:8 | AC69: X:8 | AD69: X:8 | AE69: X:8 | AH69: X:8 | AJ69: 21 | AK69: 21 | AL69: 0 | AM69: 0 | AN69: 21
A70: Khối 1 - TCT CNC - 9013948 | B70: Trung tâm Chỉ huy điều khiển - 9014071 | C70: 121263 | D70: Nguyễn Đình Việt | F70: X:8 | G70: X:8 | H70: DL:8 | I70: DL:8 | J70: DL:8 | M70: X:8 | N70: X:8 | O70: X:8 | P70: X:8 | Q70: X:8 | T70: X:8 | U70: X:8 | V70: X:8 | W70: X:8 | X70: X:8 | AA70: X:8 | AB70: X:8 | AC70: X:8 | AD70: X:8 | AE70: X:8 | AH70: X:8 | AJ70: 21 | AK70: 21 | AL70: 0 | AM70: 0 | AN70: 21
A71: Khối 1 - TCT CNC - 9013948 | B71: Trung tâm Chỉ huy điều khiển - 9014071 | C71: 450245 | D71: Nguyễn Đắc Tú | F71: X:8 | G71: X:8 | H71: DL:8 | I71: DL:8 | J71: DL:8 | M71: X:8 | N71: X:8 | O71: X:8 | P71: X:8 | Q71: X:8 | T71: X:8 | U71: X:8 | V71: X:8 | W71: X:8 | X71: X:8 | AA71: X:8 | AB71: X:8 | AC71: X:8 | AD71: X:8 | AE71: X:8 | AH71: X:8 | AJ71: 21 | AK71: 21 | AL71: 0 | AM71: 0 | AN71: 21
A72: Khối 1 - TCT CNC - 9013948 | B72: Trung tâm Chỉ huy điều khiển - 9014071 | C72: 463853 | D72: Nguyễn Đức Toàn | F72: X:8 | G72: X:8 | H72: DL:8 | I72: DL:8 | J72: DL:8 | M72: X:8 | N72: X:8 | O72: X:8 | P72: X:8 | Q72: X:8 | T72: X:8 | U72: X:8 | V72: P:8 | W72: X:8 | X72: X:8 | AA72: X:8 | AB72: X:8 | AC72: X:8 | AD72: X:8 | AE72: X:8 | AH72: X:8 | AJ72: 21 | AK72: 20 | AL72: 1 | AM72: 0 | AN72: 21
A73: Khối 1 - TCT CNC - 9013948 | B73: Trung tâm Chỉ huy điều khiển - 9014071 | C73: 427395 | D73: Ngô Thiên Phú | F73: X:8 | G73: X:8 | H73: DL:8 | I73: DL:8 | J73: DL:8 | M73: X:8 | N73: X:8 | O73: X:8 | P73: X:8 | Q73: X:8 | T73: X:8 | U73: X:8 | V73: X:8 | W73: X:8 | X73: X:8 | AA73: X:8 | AB73: X:8 | AC73: X:8 | AD73: X:8 | AE73: X:8 | AH73: X:8 | AJ73: 21 | AK73: 21 | AL73: 0 | AM73: 0 | AN73: 21
...

Sheet BM1.DSNhanSu
G1: BM.06
A2: TẬP ĐOÀN CÔNG NGHIỆP - VIỄN THÔNG QUÂN ĐỘI | F2: CỘNG HÒA XÃ HỘI CHỦ NGHĨA VIỆT NAM
B3: ĐƠN VỊ TRỰC THUỘC TẬP ĐOÀN | F3: Độc lập - Tự do - Hạnh phúc
E5: Hà Nội, ngày tháng năm 20..
A7: DANH SÁCH NHÂN SỰ THAM GIA NHIỆM VỤ KHCN
B8: Tên nhiệm vụ KHCN: ………
B9: Mã số: …………
A11: TT | B11: MÃ NV | C11: Họ và tên | D11: Chức danh | E11: Nội dung công việc tham gia nhiệm vụ KHCN | F11: Thời gian tham gia | G11: Ghi chú
A12: 1 | B12: 123204 | C12: Nguyễn Văn X1 | D12: Phó giám đốc | E12: Thiết kế phần cứng | F12: từ ngày … đến khi kết thúc đề tài
A13: 2 | B13: 130448 | C13: Nguyễn Văn X2 | D13: =+VLOOKUP(B13,[3]Sheet1!C$18:J$782,8,0) -> Phó Trưởng phòng | E13: Phát triển phần mềm | F13: từ ngày … đến ngày …
A14: 3 | B14: 131748 | C14: Nguyễn Văn X3 | D14: Trưởng phòng | E14: Phát triển phần mềm
A15: 4 | B15: 135755 | C15: Nguyễn Văn X4 | D15: Kỹ sư | E15: Thiết kế cơ khí | G15: Thay thế cho đồng chí A đã nghỉ việc
A16: 5 | B16: 135756 | C16: Nguyễn Văn X5 | D16: Kỹ sư chính | E16: Thiết kế cơ khí | G16: Nhân sự tuyển mới theo thuyết minh đề tài
A17: 6 | B17: 135757 | C17: Nguyễn Văn X6 | D17: Kỹ sư chính | E17: Thiết kế cơ khí
B19: CHỦ NHIỆM NHIỆM VỤ | E19: PHÒNG NHÂN SỰ | G19: THỦ TRƯỞNG ĐƠN VỊ

Sheet BM2.1.Bang cham cong_KHCN
AL1: BM.03.01
A2: TỔNG CÔNG TY CÔNG NGHIỆP CÔNG NGHỆ CAO VIETTEL | J2: Note: | K2: Không chia mục I, II nữa | AC2: CỘNG HÒA XÃ HỘI CHỦ NGHĨA VIỆT NAM
A3: TRUNG TÂM | K3: Các nội dung mà có nhiều nhân sự bị tách thành nhiều dòng thì thêm dòng group (như mẫu BM3.1) | AC3: Độc lập - Tự do - Hạnh phúc
A5: BẢNG CHẤM CÔNG THEO NỘI DUNG CÔNG VIỆC THÁNG | V5: 5 | W5: / | X5: 2025
B6: Tên nhiệm vụ KHCN:
B7: Mã số:
A8: STT | B8: Nội dung | C8: Nhân sự tham gia | N8: Tháng | Q8: =V5 -> 5 | R8: =W5 -> / | S8: =X5 -> 2025 | AL8: Ghi chú
C9: Mã nhân viên | D9: Họ và tên | E9: =DATE($X$5,$V$5,1) -> 45778 | F9: =E9+1 -> 45779 | G9: =F9+1 -> 45780 | H9: =G9+1 -> 45781 | I9: =H9+1 -> 45782 | J9: =I9+1 -> 45783 | K9: =J9+1 -> 45784 | L9: =K9+1 -> 45785 | M9: =L9+1 -> 45786 | ... AF9: =AE9+1 -> 45805 | AG9: =IF(EOMONTH(E9,0)>AF9,AF9+1,"") -> 45806 | AH9: =IF(EOMONTH(F9,0)>AG9,AG9+1,"") -> 45807 | AI9: =IF(EOMONTH(G9,0)>AH9,AH9+1,"") -> 45808 | AJ9: Tổng thời gian thực hiện trong tháng
E10: =TEXT(E9,"[$-42A]ddd") -> T5 | F10: =TEXT(F9,"[$-42A]ddd") -> T6 | G10: =TEXT(G9,"[$-42A]ddd") -> T7 | H10: =TEXT(H9,"[$-42A]ddd") -> CN | I10: =TEXT(I9,"[$-42A]ddd") -> T2 | J10: =TEXT(J9,"[$-42A]ddd") -> T3 | K10: =TEXT(K9,"[$-42A]ddd") -> T4 | L10: =TEXT(L9,"[$-42A]ddd") -> T5 | ... AI10: =TEXT(AI9,"[$-42A]ddd") -> T7 | AJ10: Số ngày | AK10: Số man-month
A11: I - Nhân sự quản lý đề tài
A12: 1 | B12: Chủ nhiệm đề tài | C12: 123456 | D12: Nguyễn Văn A | AJ12: =SUM(E12:AI12) -> 0
A13: 2 | B13: Thư ký đề tài | C13: 241253 | D13: Nguyễn Văn B | AJ13: =SUM(E13:AI13) -> 0
A14: II - Nhân sự nghiên cứu trực tiếp
A15: 1 | B15: ='[4]2.BTH cham cong'!C39 -> Kiểm thử
A16: 2 | B16: ='[4]2.BTH cham cong'!C40 -> Nghiên cứu giải pháp | C16: 123333 | D16: Nguyễn Minh Hùng | AJ16: =SUM(E16:AI16) -> 0
A17: 3 | B17: ='[4]2.BTH cham cong'!C41 -> Thiết kế cơ khí
A18: 4 | B18: ='[4]2.BTH cham cong'!D62 -> 0 | C18: 234522 | D18: Hà Thị Hải | AJ18: =SUM(E18:AI18) -> 0 | AL18: VD: nhân sự bổ sung
A19: 5 | B19: =AN20 -> 0
A20: 6 | B20: =AN21 -> 0 | C20: 123333 | D20: Nguyễn Minh Hùng | AJ20: =SUM(E20:AI20) -> 0
A21: 7 | B21: =AN32 -> 0
A22: 8 | B22: =AN23 -> 0 | AJ22: =SUM(E22:AI22) -> 0 | AL22: VD: nhân sự bổ sung
A23: 9 | B23: =AN24 -> 0
A24: 10 | B24: =AN25 -> 0 | AJ24: =SUM(E24:AI24) -> 0
A25: 11 | B25: =AN26 -> 0
A26: 12 | B26: =AN32 -> 0 | AJ26: =SUM(E26:AI26) -> 0 | AL26: VD: nhân sự bổ sung
A27: 13 | B27: =AN28 -> 0 | AJ27: =SUM(E27:AI27) -> 0 | AL27: VD: nhân sự bổ sung
A28: 14 | B28: =AN29 -> 0
A29: 15 | B29: =AN30 -> 0 | AJ29: =SUM(E29:AI29) -> 0
A30: 16 | B30: =AN31 -> 0
A31: 17 | B31: =AN32 -> 0 | AJ31: =SUM(E31:AI31) -> 0 | AL31: VD: nhân sự bổ sung
A32: 18 | B32: =AN33 -> 0 | AJ32: =SUM(E32:AI32) -> 0 | AL32: VD: nhân sự bổ sung
A33: 19 | B33: =AN34 -> 0
A34: 20 | B34: =AN35 -> 0 | AJ34: =SUM(E34:AI34) -> 0
A35: TỔNG CỘNG | AJ35: =SUM(AJ12:AJ34) -> 0
C37: NGƯỜI LẬP BIỂU | M37: CHỦ NHIỆM NHIỆM VỤ | AB37: TRUNG TÂM

Sheet BM2.2.Bang cham cong_SXKD
AL2: BM.03.01 | AM2: =AN23 -> 0
A3: ĐƠN VỊ TRỰC THUỘC TẬP ĐOÀN | AC3: CỘNG HÒA XÃ HỘI CHỦ NGHĨA VIỆT NAM
A4: TRUNG TÂM | AC4: Độc lập - Tự do - Hạnh phúc
A6: BẢNG CHẤM CÔNG THEO NỘI DUNG CÔNG VIỆC THÁNG | V6: 5 | W6: / | X6: 2025
B7: Tên nhiệm vụ SXKD: | C7: Sản xuất 03 đài Ra đa 3D cảnh giới tầm trung băng S VRS-MRS, gói vật tư dự phòng và gói triển khai hạ tầng
B8: Nguồn: | C8: CHỌN NGUỒN (SXKD/Bán hàng/Bảo hành/Đầu tư phát triển)
A10: STT | B10: Nội dung | C10: Nhân sự tham gia | N10: Tháng | Q10: =V6 -> 5 | R10: =W6 -> / | S10: =X6 -> 2025 | AL10: Ghi chú
C11: Mã nhân viên | D11: Họ và tên | E11: =DATE($X$6,$V$6,1) -> 45778 | F11: =E11+1 -> 45779 | G11: =F11+1 -> 45780 | H11: =G11+1 -> 45781 | I11: =H11+1 -> 45782 | J11: =I11+1 -> 45783 | K11: =J11+1 -> 45784 | L11: =K11+1 -> 45785 | M11: =L11+1 -> 45786 | ... AF11: =AE11+1 -> 45805 | AG11: =IF(EOMONTH(E11,0)>AF11,AF11+1,"") -> 45806 | AH11: =IF(EOMONTH(F11,0)>AG11,AG11+1,"") -> 45807 | AI11: =IF(EOMONTH(G11,0)>AH11,AH11+1,"") -> 45808 | AJ11: Tổng thời gian thực hiện trong tháng
E12: =TEXT(E11,"[$-42A]ddd") -> T5 | F12: =TEXT(F11,"[$-42A]ddd") -> T6 | G12: =TEXT(G11,"[$-42A]ddd") -> T7 | H12: =TEXT(H11,"[$-42A]ddd") -> CN | I12: =TEXT(I11,"[$-42A]ddd") -> T2 | J12: =TEXT(J11,"[$-42A]ddd") -> T3 | K12: =TEXT(K11,"[$-42A]ddd") -> T4 | L12: =TEXT(L11,"[$-42A]ddd") -> T5 | ... AI12: =TEXT(AI11,"[$-42A]ddd") -> T7 | AJ12: Số ngày | AK12: Số man-month
A13: I - Nhân sự quản lý dự án
A14: 1 | B14: Chủ nhiệm dự án | C14: 123456 | D14: Nguyễn Văn A | AJ14: =SUM(E14:AI14) -> 0
A15: 2 | B15: Thư ký dự án | C15: 241253 | D15: Nguyễn Văn B | AJ15: =SUM(E15:AI15) -> 0
A16: II - Nhân sự nghiên cứu trực tiếp
A17: A | B17: Đài Ra đa VRS-MRS
A18: 1 | B18: Thiết kế phần cứng | C18: 123333 | D18: Nguyễn Minh Hùng
A19: 2 | B19: Phát triển phần mềm | AJ19: =SUM(E19:AI19) -> 0
A20: B | B20: Bộ ZIP cho đài Ra đa VRS-MRS
A21: 3 | B21: Thiết kế cơ khí | C21: 234522 | D21: Hà Thị Hải
A22: 4 | AJ22: =SUM(E22:AI22) -> 0
A23: 5 | B23: …
A24: 6 | AJ24: =SUM(E24:AI24) -> 0
A25: 7
A26: 8 | AJ26: =SUM(E26:AI26) -> 0 | AL26: VD: nhân sự bổ sung
A27: 9
A28: 10 | AJ28: =SUM(E28:AI28) -> 0
A29: 11 | AJ29: =SUM(E29:AI29) -> 0
A30: 12
A31: 13 | AJ31: =SUM(E31:AI31) -> 0
A32: 14 | AJ32: =SUM(E32:AI32) -> 0
A33: 15
A34: 16 | AJ34: =SUM(E34:AI34) -> 0 | AL34: VD: nhân sự bổ sung
A35: 17 | AJ35: =SUM(E35:AI35) -> 0 | AL35: VD: nhân sự bổ sung
A36: 18
A37: 19 | AJ37: =SUM(E37:AI37) -> 0
A38: 20 | AJ38: =SUM(E38:AI38) -> 0
A39: TỔNG CỘNG | AJ39: =SUM(AJ14:AJ38) -> 0
C41: NGƯỜI LẬP BIỂU | M41: CHỦ NHIỆM NHIỆM VỤ | AB41: TRUNG TÂM

Sheet BM3.Bang TH phan bo
A1: STT | B1: MNV | C1: Họ và tên | D1: Tên đề tài | E1: Mã đề tài, dự án | F1: Nội dung công việc | G1: Phân nguồn (KHCN, QL, Bán hàng, Bảo hành, SXKD) | H1: Đơn vị trong DS | I1: Đơn vị phân bổ | J1: Khối | L1: Công tính lương | M1: Công phân bổ | N1: Mã (ghép MNV và ngày công) | O1: Số lần xuấn hiện mã | P1: Số lần xuất hiện mã đến dòng hiện tại | Q1: CHI PHÍ NHÂN CÔNG THÁNG (làm căn cứ phân bổ) | AF1: CHI PHÍ NHÂN CÔNG PHÂN BỔ
Q2: Lương tháng | R2: Lương tháng (trừ BH cá nhân) | S2: Truy thu/truy lĩnh (lương tháng lần 2) | T2: Lương SXKD (nếu có) | U2: Lương thử việc, tập nghề | V2: Lương kinh doanh thử việc, tập nghề | W2: BHXH | Y2: BHYT | AA2: BHTN | AC2: KPCĐ | AD2: Các khoản ăn ca, điện thoại, chi phí phụ cấp | AE2: CỘNG | AF2: Lương tháng | AG2: Lương tháng (trừ BH cá nhân) | AH2: Truy thu/truy lĩnh (lương tháng lần 2) | AI2: Lương SXKD (nếu có) | AJ2: Lương thử việc, tập nghề | AK2: Lương kinh doanh thử việc, tập nghề | AL2: BHXH | AN2: BHYT | AP2: BHTN | AR2: KPCĐ | AS2: Các khoản ăn ca, điện thoại, chi phí phụ cấp | AT2: CỘNG
W3: Cá nhân | X3: Đơn vị | Y3: Cá nhân | Z3: Đơn vị | AA3: Cá nhân | AB3: Đơn vị | AL3: Cá nhân | AM3: Đơn vị | AN3: Cá nhân | AO3: Đơn vị | AP3: Cá nhân | AQ3: Đơn vị
A4: STT | B4: MNV | C4: Họ và tên | D4: Tên đề tài | E4: Mã đề tài, dự án | F4: Nội dung công việc | G4: Phân nguồn (KHCN, QL, Bán hàng, Bảo hành, SXKD) | H4: Đơn vị trong DS | I4: Đơn vị phân bổ | J4: Khối | K4: Công chế độ | L4: Công tính lương | M4: Công phân bổ | N4: Mã (ghép MNV và ngày công) | O4: Số lần xuấn hiện mã | P4: Số lần xuất hiện mã đến dòng hiện tại | Q4: Lương tháng | R4: Lương tháng (trừ BH cá nhân) | S4: Truy thu/truy lĩnh (lương tháng lần 2) | T4: Lương SXKD (nếu có) | U4: Lương thử việc, tập nghề | V4: Lương kinh doanh thử việc, tập nghề | W4: Cá nhân | X4: Đơn vị | Y4: Cá nhân | Z4: Đơn vị | AA4: Cá nhân | AB4: Đơn vị | AC4: KPCĐ | AD4: Các khoản ăn ca, điện thoại, chi phí phụ cấp | AE4: CỘNG | AF4: Lương tháng | AG4: Lương tháng (trừ BH cá nhân) | AH4: Truy thu/truy lĩnh (lương tháng lần 2) | AI4: Lương SXKD (nếu có) | AJ4: Lương thử việc, tập nghề | AK4: Lương kinh doanh thử việc, tập nghề | AL4: Cá nhân | AM4: Đơn vị | AN4: Cá nhân | AO4: Đơn vị | AP4: Cá nhân | AQ4: Đơn vị | AR4: KPCĐ | AS4: Các khoản ăn ca, điện thoại, chi phí phụ cấp | AT4: CỘNG | AW4: Check tên
