Workbook
Name FSL_Priority: Lists!$B$2:$B$4
Name FSL_Release: Lists!$C$2:$C$4
Name FSL_ScopeStatus: Lists!$D$2:$D$3

Sheet Dashboard
A1: WBS DASHBOARD — FUNCTIONAL SCOPE LIST V4
A3: Nguồn: VHT_Functional_Scope_List_v4.xlsx | 453 Feature ID | 19 phân hệ | Work item leaf truy vết 1:1.
A5: Tổng work item | C5: Priority Must | E5: Release Pha 1 | G5: Cần xác nhận | I5: Hoàn thành | K5: Tiến độ trung bình
A6: =COUNTA(WBS!$C$5:$C$457) -> 453 | C6: =COUNTIF(WBS!$M$5:$M$457,"Must") -> 304 | E6: =COUNTIF(WBS!$N$5:$N$457,"Pha 1") -> 242 | G6: =COUNTIF(WBS!$O$5:$O$457,"Cần xác nhận") -> 61 | I6: =COUNTIF(WBS!$Y$5:$Y$457,"Done") -> 0 | K6: =IFERROR(AVERAGE(WBS!$Z$5:$Z$457),0) -> 0
A10: Phân hệ | B10: Số work item | D10: Release | E10: Số work item
A11: Truy cập, Tổ chức & Phân quyền | B11: =COUNTIF(WBS!$D$5:$D$457,A11) -> 30 | D11: Pha 1 | E11: =COUNTIF(WBS!$N$5:$N$457,D11) -> 242
A12: Quản lý Nhiệm vụ KHCN | B12: =COUNTIF(WBS!$D$5:$D$457,A12) -> 15 | D12: Pha 2 | E12: =COUNTIF(WBS!$N$5:$N$457,D12) -> 158
A13: Chủ trương & Xét duyệt | B13: =COUNTIF(WBS!$D$5:$D$457,A13) -> 21 | D13: Pha 3 | E13: =COUNTIF(WBS!$N$5:$N$457,D13) -> 53
A14: Không gian làm việc & Task | B14: =COUNTIF(WBS!$D$5:$D$457,A14) -> 28
A15: Hồ sơ, Tài liệu & Biểu mẫu | B15: =COUNTIF(WBS!$D$5:$D$457,A15) -> 30 | D15: Priority | E15: Số work item
A16: Hội đồng & Thẩm định | B16: =COUNTIF(WBS!$D$5:$D$457,A16) -> 21 | D16: Must | E16: =COUNTIF(WBS!$M$5:$M$457,D16) -> 304
A17: Thực hiện Nhiệm vụ | B17: =COUNTIF(WBS!$D$5:$D$457,A17) -> 17 | D17: Should | E17: =COUNTIF(WBS!$M$5:$M$457,D17) -> 102
A18: Điều chỉnh, Tạm dừng & Dừng | B18: =COUNTIF(WBS!$D$5:$D$457,A18) -> 72 | D18: Could | E18: =COUNTIF(WBS!$M$5:$M$457,D18) -> 47
A19: Nghiệm thu | B19: =COUNTIF(WBS!$D$5:$D$457,A19) -> 11
A20: Quyết toán | B20: =COUNTIF(WBS!$D$5:$D$457,A20) -> 11
A21: Sản phẩm Nghiên cứu & SHTT | B21: =COUNTIF(WBS!$D$5:$D$457,A21) -> 23
A22: Báo cáo & Điều hành | B22: =COUNTIF(WBS!$D$5:$D$457,A22) -> 10
A23: Lưu trữ, Pháp lý & Tra cứu | B23: =COUNTIF(WBS!$D$5:$D$457,A23) -> 12
A24: Quy trình & Cấu hình Nghiệp vụ | B24: =COUNTIF(WBS!$D$5:$D$457,A24) -> 77
A25: Tích hợp Hệ thống | B25: =COUNTIF(WBS!$D$5:$D$457,A25) -> 18
A26: Vận hành Workflow & Hệ thống | B26: =COUNTIF(WBS!$D$5:$D$457,A26) -> 12
A27: Audit, An toàn & Cấu hình Hệ thống | B27: =COUNTIF(WBS!$D$5:$D$457,A27) -> 11
A28: Trợ giúp & Hỗ trợ Người dùng | B28: =COUNTIF(WBS!$D$5:$D$457,A28) -> 3
A29: Trợ lý AI hỗ trợ nghiệp vụ | B29: =COUNTIF(WBS!$D$5:$D$457,A29) -> 31

Sheet WBS
A1: WORK BREAKDOWN STRUCTURE — FUNCTIONAL SCOPE LIST V4
A2: 453 leaf work item ánh xạ 1:1 với Feature ID; các cột S–AA là vùng lập kế hoạch có thể cập nhật.
A4: WBS ID | B4: Parent WBS | C4: Feature ID | D4: Phân hệ | E4: Module | F4: Nhóm chức năng | G4: Work Item | H4: Mô tả / Đầu ra | I4: Vai trò chính | J4: Loại | K4: Quy trình/RD | L4: Capability ID | M4: Priority | N4: Release | O4: Trạng thái phạm vi | P4: Nguồn/Thay đổi | Q4: Acceptance / Ghi chú FSL | R4: Requirement/NFR ID | S4: Dependencies | T4: Owner | U4: Effort (person-day) | V4: Duration (workday) | W4: Planned Start | X4: Planned Finish | Y4: Status | Z4: % Complete | AA4: Notes / Evidence
A5: =B5&"."&TEXT(COUNTIF($B$5:B5,B5),"000") -> 1.01.01.001 | B5: =IFERROR(INDEX('Work Packages'!$A$5:$A$200,MATCH(D5&"|"&E5,'Work Packages'!$P$5:$P$200,0)),"") -> 1.01.01 | C5: ='FSL Source'!B5 -> IAM-SSO-001 | D5: ='FSL Source'!C5 -> Truy cập, Tổ chức & Phân quyền | E5: ='FSL Source'!D5 -> Đăng nhập & SSO | F5: ='FSL Source'!E5 -> Xác thực | G5: ='FSL Source'!F5 -> Đăng nhập qua SSO/OIDC | H5: ='FSL Source'!G5 -> Chuyển hướng đến Identity Provider, nhận token và tạo phiên làm việc hợp lệ. | I5: ='FSL Source'!H5 -> Tất cả người dùng | J5: ='FSL Source'!I5 -> Nền tảng | ... R5: ='FSL Source'!Q5 -> 0 | X5: =IF(OR(W5="",V5=""),"",WORKDAY(W5,V5-1)) | Y5: Not Started | Z5: 0
A6: =B6&"."&TEXT(COUNTIF($B$5:B6,B6),"000") -> 1.01.01.002 | B6: =IFERROR(INDEX('Work Packages'!$A$5:$A$200,MATCH(D6&"|"&E6,'Work Packages'!$P$5:$P$200,0)),"") -> 1.01.01 | C6: ='FSL Source'!B6 -> IAM-SSO-002 | D6: ='FSL Source'!C6 -> Truy cập, Tổ chức & Phân quyền | E6: ='FSL Source'!D6 -> Đăng nhập & SSO | F6: ='FSL Source'!E6 -> Xác thực | G6: ='FSL Source'!F6 -> Đăng xuất tập trung | H6: ='FSL Source'!G6 -> Kết thúc phiên ứng dụng và phiên SSO theo chính sách tổ chức. | I6: ='FSL Source'!H6 -> Tất cả người dùng | J6: ='FSL Source'!I6 -> Nền tảng | ... R6: ='FSL Source'!Q6 -> 0 | X6: =IF(OR(W6="",V6=""),"",WORKDAY(W6,V6-1)) | Y6: Not Started | Z6: 0
A7: =B7&"."&TEXT(COUNTIF($B$5:B7,B7),"000") -> 1.01.01.003 | B7: =IFERROR(INDEX('Work Packages'!$A$5:$A$200,MATCH(D7&"|"&E7,'Work Packages'!$P$5:$P$200,0)),"") -> 1.01.01 | C7: ='FSL Source'!B7 -> IAM-SSO-003 | D7: ='FSL Source'!C7 -> Truy cập, Tổ chức & Phân quyền | E7: ='FSL Source'!D7 -> Đăng nhập & SSO | F7: ='FSL Source'!E7 -> Bảo mật phiên | G7: ='FSL Source'!F7 -> Gia hạn và hết hạn phiên | H7: ='FSL Source'!G7 -> Quản lý refresh token, timeout không hoạt động và bắt buộc đăng nhập lại. | I7: ='FSL Source'!H7 -> Tất cả người dùng | J7: ='FSL Source'!I7 -> Bảo mật | ... R7: ='FSL Source'!Q7 -> 0 | X7: =IF(OR(W7="",V7=""),"",WORKDAY(W7,V7-1)) | Y7: Not Started | Z7: 0
A8: =B8&"."&TEXT(COUNTIF($B$5:B8,B8),"000") -> 1.01.01.004 | B8: =IFERROR(INDEX('Work Packages'!$A$5:$A$200,MATCH(D8&"|"&E8,'Work Packages'!$P$5:$P$200,0)),"") -> 1.01.01 | C8: ='FSL Source'!B8 -> IAM-SSO-004 | D8: ='FSL Source'!C8 -> Truy cập, Tổ chức & Phân quyền | E8: ='FSL Source'!D8 -> Đăng nhập & SSO | F8: ='FSL Source'!E8 -> Hồ sơ người dùng | G8: ='FSL Source'!F8 -> Xem hồ sơ và ngữ cảnh đăng nhập | H8: ='FSL Source'!G8 -> Hiển thị người dùng, đơn vị, vai trò, phạm vi dữ liệu và quyền hiệu lực. | I8: ='FSL Source'!H8 -> Tất cả người dùng | J8: ='FSL Source'!I8 -> Nền tảng | ... R8: ='FSL Source'!Q8 -> 0 | X8: =IF(OR(W8="",V8=""),"",WORKDAY(W8,V8-1)) | Y8: Not Started | Z8: 0
A9: =B9&"."&TEXT(COUNTIF($B$5:B9,B9),"000") -> 1.01.02.001 | B9: =IFERROR(INDEX('Work Packages'!$A$5:$A$200,MATCH(D9&"|"&E9,'Work Packages'!$P$5:$P$200,0)),"") -> 1.01.02 | C9: ='FSL Source'!B9 -> IAM-ORG-001 | D9: ='FSL Source'!C9 -> Truy cập, Tổ chức & Phân quyền | E9: ='FSL Source'!D9 -> Cơ cấu tổ chức | F9: ='FSL Source'!E9 -> Đơn vị tổ chức | G9: ='FSL Source'!F9 -> Xem danh sách Đơn vị tổ chức | H9: ='FSL Source'!G9 -> Tra cứu danh sách, phân trang, sắp xếp và lọc Đơn vị tổ chức theo các tiêu chí nghiệp vụ. | I9: ='FSL Source'!H9 -> Quản trị hệ thống | J9: ='FSL Source'!I9 -> Nghiệp vụ | ... R9: ='FSL Source'!Q9 -> 0 | X9: =IF(OR(W9="",V9=""),"",WORKDAY(W9,V9-1)) | Y9: Not Started | Z9: 0
A10: =B10&"."&TEXT(COUNTIF($B$5:B10,B10),"000") -> 1.01.02.002 | B10: =IFERROR(INDEX('Work Packages'!$A$5:$A$200,MATCH(D10&"|"&E10,'Work Packages'!$P$5:$P$200,0)),"") -> 1.01.02 | C10: ='FSL Source'!B10 -> IAM-ORG-002 | D10: ='FSL Source'!C10 -> Truy cập, Tổ chức & Phân quyền | E10: ='FSL Source'!D10 -> Cơ cấu tổ chức | F10: ='FSL Source'!E10 -> Đơn vị tổ chức | G10: ='FSL Source'!F10 -> Tạo mới Đơn vị tổ chức | H10: ='FSL Source'!G10 -> Khởi tạo Đơn vị tổ chức, kiểm tra dữ liệu bắt buộc và lưu nháp trước khi hoàn tất. | I10: ='FSL Source'!H10 -> Quản trị hệ thống | J10: ='FSL Source'!I10 -> Nghiệp vụ | ... R10: ='FSL Source'!Q10 -> 0 | X10: =IF(OR(W10="",V10=""),"",WORKDAY(W10,V10-1)) | Y10: Not Started | Z10: 0
A11: =B11&"."&TEXT(COUNTIF($B$5:B11,B11),"000") -> 1.01.02.003 | B11: =IFERROR(INDEX('Work Packages'!$A$5:$A$200,MATCH(D11&"|"&E11,'Work Packages'!$P$5:$P$200,0)),"") -> 1.01.02 | C11: ='FSL Source'!B11 -> IAM-ORG-003 | D11: ='FSL Source'!C11 -> Truy cập, Tổ chức & Phân quyền | E11: ='FSL Source'!D11 -> Cơ cấu tổ chức | F11: ='FSL Source'!E11 -> Đơn vị tổ chức | G11: ='FSL Source'!F11 -> Xem chi tiết Đơn vị tổ chức | H11: ='FSL Source'!G11 -> Hiển thị thông tin tổng quan, dữ liệu chi tiết, tài liệu liên quan và trạng thái của Đơn vị tổ chức. | I11: ='FSL Source'!H11 -> Quản trị hệ thống | J11: ='FSL Source'!I11 -> Nghiệp vụ | ... R11: ='FSL Source'!Q11 -> 0 | X11: =IF(OR(W11="",V11=""),"",WORKDAY(W11,V11-1)) | Y11: Not Started | Z11: 0
A12: =B12&"."&TEXT(COUNTIF($B$5:B12,B12),"000") -> 1.01.02.004 | B12: =IFERROR(INDEX('Work Packages'!$A$5:$A$200,MATCH(D12&"|"&E12,'Work Packages'!$P$5:$P$200,0)),"") -> 1.01.02 | C12: ='FSL Source'!B12 -> IAM-ORG-004 | D12: ='FSL Source'!C12 -> Truy cập, Tổ chức & Phân quyền | E12: ='FSL Source'!D12 -> Cơ cấu tổ chức | F12: ='FSL Source'!E12 -> Đơn vị tổ chức | G12: ='FSL Source'!F12 -> Chỉnh sửa Đơn vị tổ chức | H12: ='FSL Source'!G12 -> Cập nhật Đơn vị tổ chức khi trạng thái và quyền người dùng cho phép; kiểm soát xung đột cập nhật. | I12: ='FSL Source'!H12 -> Quản trị hệ thống | J12: ='FSL Source'!I12 -> Nghiệp vụ | ... R12: ='FSL Source'!Q12 -> 0 | X12: =IF(OR(W12="",V12=""),"",WORKDAY(W12,V12-1)) | Y12: Not Started | Z12: 0
A13: =B13&"."&TEXT(COUNTIF($B$5:B13,B13),"000") -> 1.01.02.005 | B13: =IFERROR(INDEX('Work Packages'!$A$5:$A$200,MATCH(D13&"|"&E13,'Work Packages'!$P$5:$P$200,0)),"") -> 1.01.02 | C13: ='FSL Source'!B13 -> IAM-ORG-005 | D13: ='FSL Source'!C13 -> Truy cập, Tổ chức & Phân quyền | E13: ='FSL Source'!D13 -> Cơ cấu tổ chức | F13: ='FSL Source'!E13 -> Đơn vị tổ chức | G13: ='FSL Source'!F13 -> Xóa/Ngừng sử dụng Đơn vị tổ chức | H13: ='FSL Source'!G13 -> Xóa logic hoặc ngừng sử dụng Đơn vị tổ chức sau khi kiểm tra ràng buộc tham chiếu. | I13: ='FSL Source'!H13 -> Quản trị/Cán bộ nghiệp vụ | J13: ='FSL Source'!I13 -> Nghiệp vụ | ... R13: ='FSL Source'!Q13 -> 0 | X13: =IF(OR(W13="",V13=""),"",WORKDAY(W13,V13-1)) | Y13: Not Started | Z13: 0
A14: =B14&"."&TEXT(COUNTIF($B$5:B14,B14),"000") -> 1.01.02.006 | B14: =IFERROR(INDEX('Work Packages'!$A$5:$A$200,MATCH(D14&"|"&E14,'Work Packages'!$P$5:$P$200,0)),"") -> 1.01.02 | C14: ='FSL Source'!B14 -> IAM-ORG-006 | D14: ='FSL Source'!C14 -> Truy cập, Tổ chức & Phân quyền | E14: ='FSL Source'!D14 -> Cơ cấu tổ chức | F14: ='FSL Source'!E14 -> Đơn vị tổ chức | G14: ='FSL Source'!F14 -> Xem lịch sử Đơn vị tổ chức | H14: ='FSL Source'!G14 -> Theo dõi phiên bản, thay đổi dữ liệu, người thực hiện và lịch sử xử lý của Đơn vị tổ chức. | I14: ='FSL Source'!H14 -> Cán bộ nghiệp vụ/Quản trị | J14: ='FSL Source'!I14 -> Audit | ... R14: ='FSL Source'!Q14 -> 0 | X14: =IF(OR(W14="",V14=""),"",WORKDAY(W14,V14-1)) | Y14: Not Started | Z14: 0
A15: =B15&"."&TEXT(COUNTIF($B$5:B15,B15),"000") -> 1.01.02.007 | B15: =IFERROR(INDEX('Work Packages'!$A$5:$A$200,MATCH(D15&"|"&E15,'Work Packages'!$P$5:$P$200,0)),"") -> 1.01.02 | C15: ='FSL Source'!B15 -> IAM-ORG-007 | D15: ='FSL Source'!C15 -> Truy cập, Tổ chức & Phân quyền | E15: ='FSL Source'!D15 -> Cơ cấu tổ chức | F15: ='FSL Source'!E15 -> Cây tổ chức | G15: ='FSL Source'!F15 -> Quản lý cây tổ chức đa cấp | H15: ='FSL Source'!G15 -> Thiết lập quan hệ cha-con, cấp đơn vị, hiệu lực và lịch sử thay đổi cơ cấu. | I15: ='FSL Source'!H15 -> Quản trị hệ thống | J15: ='FSL Source'!I15 -> Cấu hình | ... R15: ='FSL Source'!Q15 -> 0 | X15: =IF(OR(W15="",V15=""),"",WORKDAY(W15,V15-1)) | Y15: Not Started | Z15: 0
A16: =B16&"."&TEXT(COUNTIF($B$5:B16,B16),"000") -> 1.01.02.008 | B16: =IFERROR(INDEX('Work Packages'!$A$5:$A$200,MATCH(D16&"|"&E16,'Work Packages'!$P$5:$P$200,0)),"") -> 1.01.02 | C16: ='FSL Source'!B16 -> IAM-ORG-008 | D16: ='FSL Source'!C16 -> Truy cập, Tổ chức & Phân quyền | E16: ='FSL Source'!D16 -> Cơ cấu tổ chức | F16: ='FSL Source'!E16 -> Chức danh | G16: ='FSL Source'!F16 -> Quản lý chức danh và vị trí công việc | H16: ='FSL Source'!G16 -> Khai báo chức danh, vị trí, cấp quản lý và ánh xạ dữ liệu nhân sự. | I16: ='FSL Source'!H16 -> Quản trị hệ thống | J16: ='FSL Source'!I16 -> Cấu hình | ... R16: ='FSL Source'!Q16 -> 0 | X16: =IF(OR(W16="",V16=""),"",WORKDAY(W16,V16-1)) | Y16: Not Started | Z16: 0
... A457: =B457&"."&TEXT(COUNTIF($B$5:B457,B457),"000") -> 1.19.08.004 | B457: =IFERROR(INDEX('Work Packages'!$A$5:$A$200,MATCH(D457&"|"&E457,'Work Packages'!$P$5:$P$200,0)),"") -> 1.19.08 | C457: ='FSL Source'!B457 -> AIA-APP-004 | D457: ='FSL Source'!C457 -> Trợ lý AI hỗ trợ nghiệp vụ | E457: ='FSL Source'!D457 -> AI hỗ trợ thẩm định | F457: ='FSL Source'!E457 -> Human-in-the-loop | G457: ='FSL Source'!F457 -> Xác nhận/chỉnh sửa kết quả AI thẩm định | H457: ='FSL Source'!G457 -> Người thẩm định xác nhận, chỉnh sửa hoặc bác bỏ gợi ý AI; lưu feedback để cải thiện checklist/skill. | I457: ='FSL Source'!H457 -> Người thẩm định | J457: ='FSL Source'!I457 -> AI hỗ trợ | ... R457: ='FSL Source'!Q457 -> REQ-068 | X457: =IF(OR(W457="",V457=""),"",WORKDAY(W457,V457-1)) | Y457: Not Started | Z457: 0

Sheet Work Packages
A1: WORK PACKAGES — TỔNG HỢP THEO PHÂN HỆ VÀ MODULE
A2: Các số lượng, effort, trạng thái và tiến độ được tính trực tiếp từ sheet WBS.
A4: Parent WBS | B4: Phân hệ | C4: Module | D4: Tổng work item | E4: Must | F4: Should | G4: Could | H4: Pha 1 | I4: Pha 2 | J4: Pha 3 | K4: Cần xác nhận | L4: Owner | M4: Effort (PD) | N4: Status | O4: % Complete | P4: Lookup Key
A5: 1.01.01 | B5: Truy cập, Tổ chức & Phân quyền | C5: Đăng nhập & SSO | D5: =COUNTIFS(WBS!$D$5:$D$457,B5,WBS!$E$5:$E$457,C5) -> 4 | E5: =COUNTIFS(WBS!$D$5:$D$457,B5,WBS!$E$5:$E$457,C5,WBS!$M$5:$M$457,"Must") -> 4 | F5: =COUNTIFS(WBS!$D$5:$D$457,B5,WBS!$E$5:$E$457,C5,WBS!$M$5:$M$457,"Should") -> 0 | G5: =COUNTIFS(WBS!$D$5:$D$457,B5,WBS!$E$5:$E$457,C5,WBS!$M$5:$M$457,"Could") -> 0 | H5: =COUNTIFS(WBS!$D$5:$D$457,B5,WBS!$E$5:$E$457,C5,WBS!$N$5:$N$457,"Pha 1") -> 4 | I5: =COUNTIFS(WBS!$D$5:$D$457,B5,WBS!$E$5:$E$457,C5,WBS!$N$5:$N$457,"Pha 2") -> 0 | J5: =COUNTIFS(WBS!$D$5:$D$457,B5,WBS!$E$5:$E$457,C5,WBS!$N$5:$N$457,"Pha 3") -> 0 | K5: =COUNTIFS(WBS!$D$5:$D$457,B5,WBS!$E$5:$E$457,C5,WBS!$O$5:$O$457,"Cần xác nhận") -> 0 | M5: =SUMIFS(WBS!$U$5:$U$457,WBS!$D$5:$D$457,B5,WBS!$E$5:$E$457,C5) -> 0 | N5: =IF(O5=1,"Done",IF(COUNTIFS(WBS!$D$5:$D$457,B5,WBS!$E$5:$E$457,C5,WBS!$Y$5:$Y$457,"Blocked")>0,"Blocked",IF(COUNTIFS(WBS!$D$5:$D$457,B5,WBS!$E$5:$E$457,C5,WBS!$Y$5:$Y$457,"In Progress")>0,"In Progress","Not Started"))) -> Not Started | O5: =IFERROR(AVERAGEIFS(WBS!$Z$5:$Z$457,WBS!$D$5:$D$457,B5,WBS!$E$5:$E$457,C5),0) -> 0 | P5: =B5&"|"&C5 -> Truy cập, Tổ chức & Phân quyền|Đăng nhập & SSO
A6: 1.01.02 | B6: Truy cập, Tổ chức & Phân quyền | C6: Cơ cấu tổ chức | D6: =COUNTIFS(WBS!$D$5:$D$457,B6,WBS!$E$5:$E$457,C6) -> 8 | E6: =COUNTIFS(WBS!$D$5:$D$457,B6,WBS!$E$5:$E$457,C6,WBS!$M$5:$M$457,"Must") -> 6 | F6: =COUNTIFS(WBS!$D$5:$D$457,B6,WBS!$E$5:$E$457,C6,WBS!$M$5:$M$457,"Should") -> 2 | G6: =COUNTIFS(WBS!$D$5:$D$457,B6,WBS!$E$5:$E$457,C6,WBS!$M$5:$M$457,"Could") -> 0 | H6: =COUNTIFS(WBS!$D$5:$D$457,B6,WBS!$E$5:$E$457,C6,WBS!$N$5:$N$457,"Pha 1") -> 8 | I6: =COUNTIFS(WBS!$D$5:$D$457,B6,WBS!$E$5:$E$457,C6,WBS!$N$5:$N$457,"Pha 2") -> 0 | J6: =COUNTIFS(WBS!$D$5:$D$457,B6,WBS!$E$5:$E$457,C6,WBS!$N$5:$N$457,"Pha 3") -> 0 | K6: =COUNTIFS(WBS!$D$5:$D$457,B6,WBS!$E$5:$E$457,C6,WBS!$O$5:$O$457,"Cần xác nhận") -> 0 | M6: =SUMIFS(WBS!$U$5:$U$457,WBS!$D$5:$D$457,B6,WBS!$E$5:$E$457,C6) -> 0 | N6: =IF(O6=1,"Done",IF(COUNTIFS(WBS!$D$5:$D$457,B6,WBS!$E$5:$E$457,C6,WBS!$Y$5:$Y$457,"Blocked")>0,"Blocked",IF(COUNTIFS(WBS!$D$5:$D$457,B6,WBS!$E$5:$E$457,C6,WBS!$Y$5:$Y$457,"In Progress")>0,"In Progress","Not Started"))) -> Not Started | O6: =IFERROR(AVERAGEIFS(WBS!$Z$5:$Z$457,WBS!$D$5:$D$457,B6,WBS!$E$5:$E$457,C6),0) -> 0 | P6: =B6&"|"&C6 -> Truy cập, Tổ chức & Phân quyền|Cơ cấu tổ chức
A7: 1.01.03 | B7: Truy cập, Tổ chức & Phân quyền | C7: Người dùng & định danh | D7: =COUNTIFS(WBS!$D$5:$D$457,B7,WBS!$E$5:$E$457,C7) -> 9 | E7: =COUNTIFS(WBS!$D$5:$D$457,B7,WBS!$E$5:$E$457,C7,WBS!$M$5:$M$457,"Must") -> 7 | F7: =COUNTIFS(WBS!$D$5:$D$457,B7,WBS!$E$5:$E$457,C7,WBS!$M$5:$M$457,"Should") -> 2 | G7: =COUNTIFS(WBS!$D$5:$D$457,B7,WBS!$E$5:$E$457,C7,WBS!$M$5:$M$457,"Could") -> 0 | H7: =COUNTIFS(WBS!$D$5:$D$457,B7,WBS!$E$5:$E$457,C7,WBS!$N$5:$N$457,"Pha 1") -> 8 | I7: =COUNTIFS(WBS!$D$5:$D$457,B7,WBS!$E$5:$E$457,C7,WBS!$N$5:$N$457,"Pha 2") -> 1 | J7: =COUNTIFS(WBS!$D$5:$D$457,B7,WBS!$E$5:$E$457,C7,WBS!$N$5:$N$457,"Pha 3") -> 0 | K7: =COUNTIFS(WBS!$D$5:$D$457,B7,WBS!$E$5:$E$457,C7,WBS!$O$5:$O$457,"Cần xác nhận") -> 0 | M7: =SUMIFS(WBS!$U$5:$U$457,WBS!$D$5:$D$457,B7,WBS!$E$5:$E$457,C7) -> 0 | N7: =IF(O7=1,"Done",IF(COUNTIFS(WBS!$D$5:$D$457,B7,WBS!$E$5:$E$457,C7,WBS!$Y$5:$Y$457,"Blocked")>0,"Blocked",IF(COUNTIFS(WBS!$D$5:$D$457,B7,WBS!$E$5:$E$457,C7,WBS!$Y$5:$Y$457,"In Progress")>0,"In Progress","Not Started"))) -> Not Started | O7: =IFERROR(AVERAGEIFS(WBS!$Z$5:$Z$457,WBS!$D$5:$D$457,B7,WBS!$E$5:$E$457,C7),0) -> 0 | P7: =B7&"|"&C7 -> Truy cập, Tổ chức & Phân quyền|Người dùng & định danh
A8: 1.01.04 | B8: Truy cập, Tổ chức & Phân quyền | C8: Vai trò & phân quyền | D8: =COUNTIFS(WBS!$D$5:$D$457,B8,WBS!$E$5:$E$457,C8) -> 9 | E8: =COUNTIFS(WBS!$D$5:$D$457,B8,WBS!$E$5:$E$457,C8,WBS!$M$5:$M$457,"Must") -> 7 | F8: =COUNTIFS(WBS!$D$5:$D$457,B8,WBS!$E$5:$E$457,C8,WBS!$M$5:$M$457,"Should") -> 2 | G8: =COUNTIFS(WBS!$D$5:$D$457,B8,WBS!$E$5:$E$457,C8,WBS!$M$5:$M$457,"Could") -> 0 | H8: =COUNTIFS(WBS!$D$5:$D$457,B8,WBS!$E$5:$E$457,C8,WBS!$N$5:$N$457,"Pha 1") -> 8 | I8: =COUNTIFS(WBS!$D$5:$D$457,B8,WBS!$E$5:$E$457,C8,WBS!$N$5:$N$457,"Pha 2") -> 1 | J8: =COUNTIFS(WBS!$D$5:$D$457,B8,WBS!$E$5:$E$457,C8,WBS!$N$5:$N$457,"Pha 3") -> 0 | K8: =COUNTIFS(WBS!$D$5:$D$457,B8,WBS!$E$5:$E$457,C8,WBS!$O$5:$O$457,"Cần xác nhận") -> 0 | M8: =SUMIFS(WBS!$U$5:$U$457,WBS!$D$5:$D$457,B8,WBS!$E$5:$E$457,C8) -> 0 | N8: =IF(O8=1,"Done",IF(COUNTIFS(WBS!$D$5:$D$457,B8,WBS!$E$5:$E$457,C8,WBS!$Y$5:$Y$457,"Blocked")>0,"Blocked",IF(COUNTIFS(WBS!$D$5:$D$457,B8,WBS!$E$5:$E$457,C8,WBS!$Y$5:$Y$457,"In Progress")>0,"In Progress","Not Started"))) -> Not Started | O8: =IFERROR(AVERAGEIFS(WBS!$Z$5:$Z$457,WBS!$D$5:$D$457,B8,WBS!$E$5:$E$457,C8),0) -> 0 | P8: =B8&"|"&C8 -> Truy cập, Tổ chức & Phân quyền|Vai trò & phân quyền
A9: 1.02.01 | B9: Quản lý Nhiệm vụ KHCN | C9: Hồ sơ nhiệm vụ | D9: =COUNTIFS(WBS!$D$5:$D$457,B9,WBS!$E$5:$E$457,C9) -> 15 | E9: =COUNTIFS(WBS!$D$5:$D$457,B9,WBS!$E$5:$E$457,C9,WBS!$M$5:$M$457,"Must") -> 12 | F9: =COUNTIFS(WBS!$D$5:$D$457,B9,WBS!$E$5:$E$457,C9,WBS!$M$5:$M$457,"Should") -> 3 | G9: =COUNTIFS(WBS!$D$5:$D$457,B9,WBS!$E$5:$E$457,C9,WBS!$M$5:$M$457,"Could") -> 0 | H9: =COUNTIFS(WBS!$D$5:$D$457,B9,WBS!$E$5:$E$457,C9,WBS!$N$5:$N$457,"Pha 1") -> 14 | I9: =COUNTIFS(WBS!$D$5:$D$457,B9,WBS!$E$5:$E$457,C9,WBS!$N$5:$N$457,"Pha 2") -> 1 | J9: =COUNTIFS(WBS!$D$5:$D$457,B9,WBS!$E$5:$E$457,C9,WBS!$N$5:$N$457,"Pha 3") -> 0 | K9: =COUNTIFS(WBS!$D$5:$D$457,B9,WBS!$E$5:$E$457,C9,WBS!$O$5:$O$457,"Cần xác nhận") -> 1 | M9: =SUMIFS(WBS!$U$5:$U$457,WBS!$D$5:$D$457,B9,WBS!$E$5:$E$457,C9) -> 0 | N9: =IF(O9=1,"Done",IF(COUNTIFS(WBS!$D$5:$D$457,B9,WBS!$E$5:$E$457,C9,WBS!$Y$5:$Y$457,"Blocked")>0,"Blocked",IF(COUNTIFS(WBS!$D$5:$D$457,B9,WBS!$E$5:$E$457,C9,WBS!$Y$5:$Y$457,"In Progress")>0,"In Progress","Not Started"))) -> Not Started | O9: =IFERROR(AVERAGEIFS(WBS!$Z$5:$Z$457,WBS!$D$5:$D$457,B9,WBS!$E$5:$E$457,C9),0) -> 0 | P9: =B9&"|"&C9 -> Quản lý Nhiệm vụ KHCN|Hồ sơ nhiệm vụ
A10: 1.03.01 | B10: Chủ trương & Xét duyệt | C10: Xét duyệt chủ trương | D10: =COUNTIFS(WBS!$D$5:$D$457,B10,WBS!$E$5:$E$457,C10) -> 10 | E10: =COUNTIFS(WBS!$D$5:$D$457,B10,WBS!$E$5:$E$457,C10,WBS!$M$5:$M$457,"Must") -> 9 | F10: =COUNTIFS(WBS!$D$5:$D$457,B10,WBS!$E$5:$E$457,C10,WBS!$M$5:$M$457,"Should") -> 1 | G10: =COUNTIFS(WBS!$D$5:$D$457,B10,WBS!$E$5:$E$457,C10,WBS!$M$5:$M$457,"Could") -> 0 | H10: =COUNTIFS(WBS!$D$5:$D$457,B10,WBS!$E$5:$E$457,C10,WBS!$N$5:$N$457,"Pha 1") -> 10 | I10: =COUNTIFS(WBS!$D$5:$D$457,B10,WBS!$E$5:$E$457,C10,WBS!$N$5:$N$457,"Pha 2") -> 0 | J10: =COUNTIFS(WBS!$D$5:$D$457,B10,WBS!$E$5:$E$457,C10,WBS!$N$5:$N$457,"Pha 3") -> 0 | K10: =COUNTIFS(WBS!$D$5:$D$457,B10,WBS!$E$5:$E$457,C10,WBS!$O$5:$O$457,"Cần xác nhận") -> 1 | M10: =SUMIFS(WBS!$U$5:$U$457,WBS!$D$5:$D$457,B10,WBS!$E$5:$E$457,C10) -> 0 | N10: =IF(O10=1,"Done",IF(COUNTIFS(WBS!$D$5:$D$457,B10,WBS!$E$5:$E$457,C10,WBS!$Y$5:$Y$457,"Blocked")>0,"Blocked",IF(COUNTIFS(WBS!$D$5:$D$457,B10,WBS!$E$5:$E$457,C10,WBS!$Y$5:$Y$457,"In Progress")>0,"In Progress","Not Started"))) -> Not Started | O10: =IFERROR(AVERAGEIFS(WBS!$Z$5:$Z$457,WBS!$D$5:$D$457,B10,WBS!$E$5:$E$457,C10),0) -> 0 | P10: =B10&"|"&C10 -> Chủ trương & Xét duyệt|Xét duyệt chủ trương
A11: 1.03.02 | B11: Chủ trương & Xét duyệt | C11: Xét duyệt nhiệm vụ | D11: =COUNTIFS(WBS!$D$5:$D$457,B11,WBS!$E$5:$E$457,C11) -> 11 | E11: =COUNTIFS(WBS!$D$5:$D$457,B11,WBS!$E$5:$E$457,C11,WBS!$M$5:$M$457,"Must") -> 10 | F11: =COUNTIFS(WBS!$D$5:$D$457,B11,WBS!$E$5:$E$457,C11,WBS!$M$5:$M$457,"Should") -> 1 | G11: =COUNTIFS(WBS!$D$5:$D$457,B11,WBS!$E$5:$E$457,C11,WBS!$M$5:$M$457,"Could") -> 0 | H11: =COUNTIFS(WBS!$D$5:$D$457,B11,WBS!$E$5:$E$457,C11,WBS!$N$5:$N$457,"Pha 1") -> 11 | I11: =COUNTIFS(WBS!$D$5:$D$457,B11,WBS!$E$5:$E$457,C11,WBS!$N$5:$N$457,"Pha 2") -> 0 | J11: =COUNTIFS(WBS!$D$5:$D$457,B11,WBS!$E$5:$E$457,C11,WBS!$N$5:$N$457,"Pha 3") -> 0 | K11: =COUNTIFS(WBS!$D$5:$D$457,B11,WBS!$E$5:$E$457,C11,WBS!$O$5:$O$457,"Cần xác nhận") -> 1 | M11: =SUMIFS(WBS!$U$5:$U$457,WBS!$D$5:$D$457,B11,WBS!$E$5:$E$457,C11) -> 0 | N11: =IF(O11=1,"Done",IF(COUNTIFS(WBS!$D$5:$D$457,B11,WBS!$E$5:$E$457,C11,WBS!$Y$5:$Y$457,"Blocked")>0,"Blocked",IF(COUNTIFS(WBS!$D$5:$D$457,B11,WBS!$E$5:$E$457,C11,WBS!$Y$5:$Y$457,"In Progress")>0,"In Progress","Not Started"))) -> Not Started | O11: =IFERROR(AVERAGEIFS(WBS!$Z$5:$Z$457,WBS!$D$5:$D$457,B11,WBS!$E$5:$E$457,C11),0) -> 0 | P11: =B11&"|"&C11 -> Chủ trương & Xét duyệt|Xét duyệt nhiệm vụ
A12: 1.04.01 | B12: Không gian làm việc & Task | C12: Việc của tôi | D12: =COUNTIFS(WBS!$D$5:$D$457,B12,WBS!$E$5:$E$457,C12) -> 3 | E12: =COUNTIFS(WBS!$D$5:$D$457,B12,WBS!$E$5:$E$457,C12,WBS!$M$5:$M$457,"Must") -> 3 | F12: =COUNTIFS(WBS!$D$5:$D$457,B12,WBS!$E$5:$E$457,C12,WBS!$M$5:$M$457,"Should") -> 0 | G12: =COUNTIFS(WBS!$D$5:$D$457,B12,WBS!$E$5:$E$457,C12,WBS!$M$5:$M$457,"Could") -> 0 | H12: =COUNTIFS(WBS!$D$5:$D$457,B12,WBS!$E$5:$E$457,C12,WBS!$N$5:$N$457,"Pha 1") -> 3 | I12: =COUNTIFS(WBS!$D$5:$D$457,B12,WBS!$E$5:$E$457,C12,WBS!$N$5:$N$457,"Pha 2") -> 0 | J12: =COUNTIFS(WBS!$D$5:$D$457,B12,WBS!$E$5:$E$457,C12,WBS!$N$5:$N$457,"Pha 3") -> 0 | K12: =COUNTIFS(WBS!$D$5:$D$457,B12,WBS!$E$5:$E$457,C12,WBS!$O$5:$O$457,"Cần xác nhận") -> 0 | M12: =SUMIFS(WBS!$U$5:$U$457,WBS!$D$5:$D$457,B12,WBS!$E$5:$E$457,C12) -> 0 | N12: =IF(O12=1,"Done",IF(COUNTIFS(WBS!$D$5:$D$457,B12,WBS!$E$5:$E$457,C12,WBS!$Y$5:$Y$457,"Blocked")>0,"Blocked",IF(COUNTIFS(WBS!$D$5:$D$457,B12,WBS!$E$5:$E$457,C12,WBS!$Y$5:$Y$457,"In Progress")>0,"In Progress","Not Started"))) -> Not Started | O12: =IFERROR(AVERAGEIFS(WBS!$Z$5:$Z$457,WBS!$D$5:$D$457,B12,WBS!$E$5:$E$457,C12),0) -> 0 | P12: =B12&"|"&C12 -> Không gian làm việc & Task|Việc của tôi
A13: 1.04.02 | B13: Không gian làm việc & Task | C13: Xử lý task | D13: =COUNTIFS(WBS!$D$5:$D$457,B13,WBS!$E$5:$E$457,C13) -> 11 | E13: =COUNTIFS(WBS!$D$5:$D$457,B13,WBS!$E$5:$E$457,C13,WBS!$M$5:$M$457,"Must") -> 11 | F13: =COUNTIFS(WBS!$D$5:$D$457,B13,WBS!$E$5:$E$457,C13,WBS!$M$5:$M$457,"Should") -> 0 | G13: =COUNTIFS(WBS!$D$5:$D$457,B13,WBS!$E$5:$E$457,C13,WBS!$M$5:$M$457,"Could") -> 0 | H13: =COUNTIFS(WBS!$D$5:$D$457,B13,WBS!$E$5:$E$457,C13,WBS!$N$5:$N$457,"Pha 1") -> 11 | I13: =COUNTIFS(WBS!$D$5:$D$457,B13,WBS!$E$5:$E$457,C13,WBS!$N$5:$N$457,"Pha 2") -> 0 | J13: =COUNTIFS(WBS!$D$5:$D$457,B13,WBS!$E$5:$E$457,C13,WBS!$N$5:$N$457,"Pha 3") -> 0 | K13: =COUNTIFS(WBS!$D$5:$D$457,B13,WBS!$E$5:$E$457,C13,WBS!$O$5:$O$457,"Cần xác nhận") -> 0 | M13: =SUMIFS(WBS!$U$5:$U$457,WBS!$D$5:$D$457,B13,WBS!$E$5:$E$457,C13) -> 0 | N13: =IF(O13=1,"Done",IF(COUNTIFS(WBS!$D$5:$D$457,B13,WBS!$E$5:$E$457,C13,WBS!$Y$5:$Y$457,"Blocked")>0,"Blocked",IF(COUNTIFS(WBS!$D$5:$D$457,B13,WBS!$E$5:$E$457,C13,WBS!$Y$5:$Y$457,"In Progress")>0,"In Progress","Not Started"))) -> Not Started | O13: =IFERROR(AVERAGEIFS(WBS!$Z$5:$Z$457,WBS!$D$5:$D$457,B13,WBS!$E$5:$E$457,C13),0) -> 0 | P13: =B13&"|"&C13 -> Không gian làm việc & Task|Xử lý task
A14: 1.04.03 | B14: Không gian làm việc & Task | C14: Nhập liệu thay cấp Tập đoàn | D14: =COUNTIFS(WBS!$D$5:$D$457,B14,WBS!$E$5:$E$457,C14) -> 6 | E14: =COUNTIFS(WBS!$D$5:$D$457,B14,WBS!$E$5:$E$457,C14,WBS!$M$5:$M$457,"Must") -> 6 | F14: =COUNTIFS(WBS!$D$5:$D$457,B14,WBS!$E$5:$E$457,C14,WBS!$M$5:$M$457,"Should") -> 0 | G14: =COUNTIFS(WBS!$D$5:$D$457,B14,WBS!$E$5:$E$457,C14,WBS!$M$5:$M$457,"Could") -> 0 | H14: =COUNTIFS(WBS!$D$5:$D$457,B14,WBS!$E$5:$E$457,C14,WBS!$N$5:$N$457,"Pha 1") -> 6 | I14: =COUNTIFS(WBS!$D$5:$D$457,B14,WBS!$E$5:$E$457,C14,WBS!$N$5:$N$457,"Pha 2") -> 0 | J14: =COUNTIFS(WBS!$D$5:$D$457,B14,WBS!$E$5:$E$457,C14,WBS!$N$5:$N$457,"Pha 3") -> 0 | K14: =COUNTIFS(WBS!$D$5:$D$457,B14,WBS!$E$5:$E$457,C14,WBS!$O$5:$O$457,"Cần xác nhận") -> 0 | M14: =SUMIFS(WBS!$U$5:$U$457,WBS!$D$5:$D$457,B14,WBS!$E$5:$E$457,C14) -> 0 | N14: =IF(O14=1,"Done",IF(COUNTIFS(WBS!$D$5:$D$457,B14,WBS!$E$5:$E$457,C14,WBS!$Y$5:$Y$457,"Blocked")>0,"Blocked",IF(COUNTIFS(WBS!$D$5:$D$457,B14,WBS!$E$5:$E$457,C14,WBS!$Y$5:$Y$457,"In Progress")>0,"In Progress","Not Started"))) -> Not Started | O14: =IFERROR(AVERAGEIFS(WBS!$Z$5:$Z$457,WBS!$D$5:$D$457,B14,WBS!$E$5:$E$457,C14),0) -> 0 | P14: =B14&"|"&C14 -> Không gian làm việc & Task|Nhập liệu thay cấp Tập đoàn
A15: 1.04.04 | B15: Không gian làm việc & Task | C15: Xử lý ngoại lệ có kiểm soát | D15: =COUNTIFS(WBS!$D$5:$D$457,B15,WBS!$E$5:$E$457,C15) -> 8 | E15: =COUNTIFS(WBS!$D$5:$D$457,B15,WBS!$E$5:$E$457,C15,WBS!$M$5:$M$457,"Must") -> 0 | F15: =COUNTIFS(WBS!$D$5:$D$457,B15,WBS!$E$5:$E$457,C15,WBS!$M$5:$M$457,"Should") -> 0 | G15: =COUNTIFS(WBS!$D$5:$D$457,B15,WBS!$E$5:$E$457,C15,WBS!$M$5:$M$457,"Could") -> 8 | H15: =COUNTIFS(WBS!$D$5:$D$457,B15,WBS!$E$5:$E$457,C15,WBS!$N$5:$N$457,"Pha 1") -> 0 | I15: =COUNTIFS(WBS!$D$5:$D$457,B15,WBS!$E$5:$E$457,C15,WBS!$N$5:$N$457,"Pha 2") -> 0 | J15: =COUNTIFS(WBS!$D$5:$D$457,B15,WBS!$E$5:$E$457,C15,WBS!$N$5:$N$457,"Pha 3") -> 8 | K15: =COUNTIFS(WBS!$D$5:$D$457,B15,WBS!$E$5:$E$457,C15,WBS!$O$5:$O$457,"Cần xác nhận") -> 8 | M15: =SUMIFS(WBS!$U$5:$U$457,WBS!$D$5:$D$457,B15,WBS!$E$5:$E$457,C15) -> 0 | N15: =IF(O15=1,"Done",IF(COUNTIFS(WBS!$D$5:$D$457,B15,WBS!$E$5:$E$457,C15,WBS!$Y$5:$Y$457,"Blocked")>0,"Blocked",IF(COUNTIFS(WBS!$D$5:$D$457,B15,WBS!$E$5:$E$457,C15,WBS!$Y$5:$Y$457,"In Progress")>0,"In Progress","Not Started"))) -> Not Started | O15: =IFERROR(AVERAGEIFS(WBS!$Z$5:$Z$457,WBS!$D$5:$D$457,B15,WBS!$E$5:$E$457,C15),0) -> 0 | P15: =B15&"|"&C15 -> Không gian làm việc & Task|Xử lý ngoại lệ có kiểm soát
A16: 1.05.01 | B16: Hồ sơ, Tài liệu & Biểu mẫu | C16: Quản trị hồ sơ | D16: =COUNTIFS(WBS!$D$5:$D$457,B16,WBS!$E$5:$E$457,C16) -> 4 | E16: =COUNTIFS(WBS!$D$5:$D$457,B16,WBS!$E$5:$E$457,C16,WBS!$M$5:$M$457,"Must") -> 3 | F16: =COUNTIFS(WBS!$D$5:$D$457,B16,WBS!$E$5:$E$457,C16,WBS!$M$5:$M$457,"Should") -> 1 | G16: =COUNTIFS(WBS!$D$5:$D$457,B16,WBS!$E$5:$E$457,C16,WBS!$M$5:$M$457,"Could") -> 0 | H16: =COUNTIFS(WBS!$D$5:$D$457,B16,WBS!$E$5:$E$457,C16,WBS!$N$5:$N$457,"Pha 1") -> 3 | I16: =COUNTIFS(WBS!$D$5:$D$457,B16,WBS!$E$5:$E$457,C16,WBS!$N$5:$N$457,"Pha 2") -> 1 | J16: =COUNTIFS(WBS!$D$5:$D$457,B16,WBS!$E$5:$E$457,C16,WBS!$N$5:$N$457,"Pha 3") -> 0 | K16: =COUNTIFS(WBS!$D$5:$D$457,B16,WBS!$E$5:$E$457,C16,WBS!$O$5:$O$457,"Cần xác nhận") -> 0 | M16: =SUMIFS(WBS!$U$5:$U$457,WBS!$D$5:$D$457,B16,WBS!$E$5:$E$457,C16) -> 0 | N16: =IF(O16=1,"Done",IF(COUNTIFS(WBS!$D$5:$D$457,B16,WBS!$E$5:$E$457,C16,WBS!$Y$5:$Y$457,"Blocked")>0,"Blocked",IF(COUNTIFS(WBS!$D$5:$D$457,B16,WBS!$E$5:$E$457,C16,WBS!$Y$5:$Y$457,"In Progress")>0,"In Progress","Not Started"))) -> Not Started | O16: =IFERROR(AVERAGEIFS(WBS!$Z$5:$Z$457,WBS!$D$5:$D$457,B16,WBS!$E$5:$E$457,C16),0) -> 0 | P16: =B16&"|"&C16 -> Hồ sơ, Tài liệu & Biểu mẫu|Quản trị hồ sơ
... A66: 1.19.08 | B66: Trợ lý AI hỗ trợ nghiệp vụ | C66: AI hỗ trợ thẩm định | D66: =COUNTIFS(WBS!$D$5:$D$457,B66,WBS!$E$5:$E$457,C66) -> 4 | E66: =COUNTIFS(WBS!$D$5:$D$457,B66,WBS!$E$5:$E$457,C66,WBS!$M$5:$M$457,"Must") -> 0 | F66: =COUNTIFS(WBS!$D$5:$D$457,B66,WBS!$E$5:$E$457,C66,WBS!$M$5:$M$457,"Should") -> 0 | G66: =COUNTIFS(WBS!$D$5:$D$457,B66,WBS!$E$5:$E$457,C66,WBS!$M$5:$M$457,"Could") -> 4 | H66: =COUNTIFS(WBS!$D$5:$D$457,B66,WBS!$E$5:$E$457,C66,WBS!$N$5:$N$457,"Pha 1") -> 0 | I66: =COUNTIFS(WBS!$D$5:$D$457,B66,WBS!$E$5:$E$457,C66,WBS!$N$5:$N$457,"Pha 2") -> 0 | J66: =COUNTIFS(WBS!$D$5:$D$457,B66,WBS!$E$5:$E$457,C66,WBS!$N$5:$N$457,"Pha 3") -> 4 | K66: =COUNTIFS(WBS!$D$5:$D$457,B66,WBS!$E$5:$E$457,C66,WBS!$O$5:$O$457,"Cần xác nhận") -> 4 | M66: =SUMIFS(WBS!$U$5:$U$457,WBS!$D$5:$D$457,B66,WBS!$E$5:$E$457,C66) -> 0 | N66: =IF(O66=1,"Done",IF(COUNTIFS(WBS!$D$5:$D$457,B66,WBS!$E$5:$E$457,C66,WBS!$Y$5:$Y$457,"Blocked")>0,"Blocked",IF(COUNTIFS(WBS!$D$5:$D$457,B66,WBS!$E$5:$E$457,C66,WBS!$Y$5:$Y$457,"In Progress")>0,"In Progress","Not Started"))) -> Not Started | O66: =IFERROR(AVERAGEIFS(WBS!$Z$5:$Z$457,WBS!$D$5:$D$457,B66,WBS!$E$5:$E$457,C66),0) -> 0 | P66: =B66&"|"&C66 -> Trợ lý AI hỗ trợ nghiệp vụ|AI hỗ trợ thẩm định

Sheet Milestones
A1: MILESTONES & QUALITY GATES
A3: Milestone | B3: Kết quả | C3: Phạm vi work item | D3: Owner | E3: Planned Date | F3: Status | G3: Actual Date | H3: Evidence
A4: M0 — FSL v4 Baseline | B4: 453 Feature ID được xác nhận và đóng các câu hỏi chặn | C4: Toàn bộ FSL v4 | F4: Not Started
A5: M1 — Pha 1 Design Ready | B5: Thiết kế và acceptance criteria Pha 1 được duyệt | C5: Release = Pha 1 | F5: Not Started
A6: M2 — Pha 1 Feature Complete | B6: Toàn bộ work item Pha 1 hoàn thành phát triển | C6: Release = Pha 1 | F6: Not Started
A7: M3 — Pha 1 SIT Accepted | B7: SIT, security và regression đạt | C7: Release = Pha 1 | F7: Not Started
A8: M4 — Pha 1 UAT Accepted | B8: Người dùng nghiệp vụ ký nghiệm thu Pha 1 | C8: Release = Pha 1 | F8: Not Started
A9: M5 — Pha 1 Go-live | B9: Production release và smoke test đạt | C9: Release = Pha 1 | F9: Not Started
A10: M6 — Pha 2 Accepted | B10: Work item Pha 2 và tích hợp nghiệm thu | C10: Release = Pha 2 | F10: Not Started
A11: M7 — Pha 3 Accepted | B11: Work item Pha 3 nghiệm thu | C11: Release = Pha 3 | F11: Not Started

Sheet CAP Coverage
A1: CAPABILITY COVERAGE — FSL V4
A2: Đếm theo chuỗi Capability ID; một feature có thể đóng góp cho nhiều CAP.
A4: CAP | B4: BR | C4: Tổng feature | D4: Must | E4: Should | F4: Could | G4: Pha 1 | H4: Pha 2 | I4: Pha 3 | J4: Cần xác nhận | K4: % Complete
A5: CAP-01 | B5: BR-001 | C5: =COUNTIF(WBS!$L$5:$L$457,"*"&A5&"*") -> 40 | D5: =COUNTIFS(WBS!$L$5:$L$457,"*"&A5&"*",WBS!$M$5:$M$457,"Must") -> 31 | E5: =COUNTIFS(WBS!$L$5:$L$457,"*"&A5&"*",WBS!$M$5:$M$457,"Should") -> 9 | F5: =COUNTIFS(WBS!$L$5:$L$457,"*"&A5&"*",WBS!$M$5:$M$457,"Could") -> 0 | G5: =COUNTIFS(WBS!$L$5:$L$457,"*"&A5&"*",WBS!$N$5:$N$457,"Pha 1") -> 26 | H5: =COUNTIFS(WBS!$L$5:$L$457,"*"&A5&"*",WBS!$N$5:$N$457,"Pha 2") -> 14 | I5: =COUNTIFS(WBS!$L$5:$L$457,"*"&A5&"*",WBS!$N$5:$N$457,"Pha 3") -> 0 | J5: =COUNTIFS(WBS!$L$5:$L$457,"*"&A5&"*",WBS!$O$5:$O$457,"Cần xác nhận") -> 2 | K5: =IFERROR(SUMPRODUCT((ISNUMBER(SEARCH(A5,WBS!$L$5:$L$457)))*WBS!$Z$5:$Z$457)/C5,0) -> 0
A6: CAP-02 | B6: BR-002 | C6: =COUNTIF(WBS!$L$5:$L$457,"*"&A6&"*") -> 15 | D6: =COUNTIFS(WBS!$L$5:$L$457,"*"&A6&"*",WBS!$M$5:$M$457,"Must") -> 12 | E6: =COUNTIFS(WBS!$L$5:$L$457,"*"&A6&"*",WBS!$M$5:$M$457,"Should") -> 3 | F6: =COUNTIFS(WBS!$L$5:$L$457,"*"&A6&"*",WBS!$M$5:$M$457,"Could") -> 0 | G6: =COUNTIFS(WBS!$L$5:$L$457,"*"&A6&"*",WBS!$N$5:$N$457,"Pha 1") -> 14 | H6: =COUNTIFS(WBS!$L$5:$L$457,"*"&A6&"*",WBS!$N$5:$N$457,"Pha 2") -> 1 | I6: =COUNTIFS(WBS!$L$5:$L$457,"*"&A6&"*",WBS!$N$5:$N$457,"Pha 3") -> 0 | J6: =COUNTIFS(WBS!$L$5:$L$457,"*"&A6&"*",WBS!$O$5:$O$457,"Cần xác nhận") -> 1 | K6: =IFERROR(SUMPRODUCT((ISNUMBER(SEARCH(A6,WBS!$L$5:$L$457)))*WBS!$Z$5:$Z$457)/C6,0) -> 0
A7: CAP-03 | B7: BR-003 | C7: =COUNTIF(WBS!$L$5:$L$457,"*"&A7&"*") -> 5 | D7: =COUNTIFS(WBS!$L$5:$L$457,"*"&A7&"*",WBS!$M$5:$M$457,"Must") -> 5 | E7: =COUNTIFS(WBS!$L$5:$L$457,"*"&A7&"*",WBS!$M$5:$M$457,"Should") -> 0 | F7: =COUNTIFS(WBS!$L$5:$L$457,"*"&A7&"*",WBS!$M$5:$M$457,"Could") -> 0 | G7: =COUNTIFS(WBS!$L$5:$L$457,"*"&A7&"*",WBS!$N$5:$N$457,"Pha 1") -> 5 | H7: =COUNTIFS(WBS!$L$5:$L$457,"*"&A7&"*",WBS!$N$5:$N$457,"Pha 2") -> 0 | I7: =COUNTIFS(WBS!$L$5:$L$457,"*"&A7&"*",WBS!$N$5:$N$457,"Pha 3") -> 0 | J7: =COUNTIFS(WBS!$L$5:$L$457,"*"&A7&"*",WBS!$O$5:$O$457,"Cần xác nhận") -> 2 | K7: =IFERROR(SUMPRODUCT((ISNUMBER(SEARCH(A7,WBS!$L$5:$L$457)))*WBS!$Z$5:$Z$457)/C7,0) -> 0
A8: CAP-04 | B8: BR-004 | C8: =COUNTIF(WBS!$L$5:$L$457,"*"&A8&"*") -> 85 | D8: =COUNTIFS(WBS!$L$5:$L$457,"*"&A8&"*",WBS!$M$5:$M$457,"Must") -> 68 | E8: =COUNTIFS(WBS!$L$5:$L$457,"*"&A8&"*",WBS!$M$5:$M$457,"Should") -> 16 | F8: =COUNTIFS(WBS!$L$5:$L$457,"*"&A8&"*",WBS!$M$5:$M$457,"Could") -> 1 | G8: =COUNTIFS(WBS!$L$5:$L$457,"*"&A8&"*",WBS!$N$5:$N$457,"Pha 1") -> 69 | H8: =COUNTIFS(WBS!$L$5:$L$457,"*"&A8&"*",WBS!$N$5:$N$457,"Pha 2") -> 9 | I8: =COUNTIFS(WBS!$L$5:$L$457,"*"&A8&"*",WBS!$N$5:$N$457,"Pha 3") -> 7 | J8: =COUNTIFS(WBS!$L$5:$L$457,"*"&A8&"*",WBS!$O$5:$O$457,"Cần xác nhận") -> 5 | K8: =IFERROR(SUMPRODUCT((ISNUMBER(SEARCH(A8,WBS!$L$5:$L$457)))*WBS!$Z$5:$Z$457)/C8,0) -> 0
A9: CAP-05 | B9: BR-005 | C9: =COUNTIF(WBS!$L$5:$L$457,"*"&A9&"*") -> 13 | D9: =COUNTIFS(WBS!$L$5:$L$457,"*"&A9&"*",WBS!$M$5:$M$457,"Must") -> 11 | E9: =COUNTIFS(WBS!$L$5:$L$457,"*"&A9&"*",WBS!$M$5:$M$457,"Should") -> 2 | F9: =COUNTIFS(WBS!$L$5:$L$457,"*"&A9&"*",WBS!$M$5:$M$457,"Could") -> 0 | G9: =COUNTIFS(WBS!$L$5:$L$457,"*"&A9&"*",WBS!$N$5:$N$457,"Pha 1") -> 13 | H9: =COUNTIFS(WBS!$L$5:$L$457,"*"&A9&"*",WBS!$N$5:$N$457,"Pha 2") -> 0 | I9: =COUNTIFS(WBS!$L$5:$L$457,"*"&A9&"*",WBS!$N$5:$N$457,"Pha 3") -> 0 | J9: =COUNTIFS(WBS!$L$5:$L$457,"*"&A9&"*",WBS!$O$5:$O$457,"Cần xác nhận") -> 0 | K9: =IFERROR(SUMPRODUCT((ISNUMBER(SEARCH(A9,WBS!$L$5:$L$457)))*WBS!$Z$5:$Z$457)/C9,0) -> 0
A10: CAP-06 | B10: BR-006 | C10: =COUNTIF(WBS!$L$5:$L$457,"*"&A10&"*") -> 25 | D10: =COUNTIFS(WBS!$L$5:$L$457,"*"&A10&"*",WBS!$M$5:$M$457,"Must") -> 12 | E10: =COUNTIFS(WBS!$L$5:$L$457,"*"&A10&"*",WBS!$M$5:$M$457,"Should") -> 11 | F10: =COUNTIFS(WBS!$L$5:$L$457,"*"&A10&"*",WBS!$M$5:$M$457,"Could") -> 2 | G10: =COUNTIFS(WBS!$L$5:$L$457,"*"&A10&"*",WBS!$N$5:$N$457,"Pha 1") -> 12 | H10: =COUNTIFS(WBS!$L$5:$L$457,"*"&A10&"*",WBS!$N$5:$N$457,"Pha 2") -> 11 | I10: =COUNTIFS(WBS!$L$5:$L$457,"*"&A10&"*",WBS!$N$5:$N$457,"Pha 3") -> 2 | J10: =COUNTIFS(WBS!$L$5:$L$457,"*"&A10&"*",WBS!$O$5:$O$457,"Cần xác nhận") -> 3 | K10: =IFERROR(SUMPRODUCT((ISNUMBER(SEARCH(A10,WBS!$L$5:$L$457)))*WBS!$Z$5:$Z$457)/C10,0) -> 0
A11: CAP-07 | B11: BR-007 | C11: =COUNTIF(WBS!$L$5:$L$457,"*"&A11&"*") -> 3 | D11: =COUNTIFS(WBS!$L$5:$L$457,"*"&A11&"*",WBS!$M$5:$M$457,"Must") -> 3 | E11: =COUNTIFS(WBS!$L$5:$L$457,"*"&A11&"*",WBS!$M$5:$M$457,"Should") -> 0 | F11: =COUNTIFS(WBS!$L$5:$L$457,"*"&A11&"*",WBS!$M$5:$M$457,"Could") -> 0 | G11: =COUNTIFS(WBS!$L$5:$L$457,"*"&A11&"*",WBS!$N$5:$N$457,"Pha 1") -> 3 | H11: =COUNTIFS(WBS!$L$5:$L$457,"*"&A11&"*",WBS!$N$5:$N$457,"Pha 2") -> 0 | I11: =COUNTIFS(WBS!$L$5:$L$457,"*"&A11&"*",WBS!$N$5:$N$457,"Pha 3") -> 0 | J11: =COUNTIFS(WBS!$L$5:$L$457,"*"&A11&"*",WBS!$O$5:$O$457,"Cần xác nhận") -> 0 | K11: =IFERROR(SUMPRODUCT((ISNUMBER(SEARCH(A11,WBS!$L$5:$L$457)))*WBS!$Z$5:$Z$457)/C11,0) -> 0
A12: CAP-08 | B12: BR-008 | C12: =COUNTIF(WBS!$L$5:$L$457,"*"&A12&"*") -> 75 | D12: =COUNTIFS(WBS!$L$5:$L$457,"*"&A12&"*",WBS!$M$5:$M$457,"Must") -> 65 | E12: =COUNTIFS(WBS!$L$5:$L$457,"*"&A12&"*",WBS!$M$5:$M$457,"Should") -> 10 | F12: =COUNTIFS(WBS!$L$5:$L$457,"*"&A12&"*",WBS!$M$5:$M$457,"Could") -> 0 | G12: =COUNTIFS(WBS!$L$5:$L$457,"*"&A12&"*",WBS!$N$5:$N$457,"Pha 1") -> 74 | H12: =COUNTIFS(WBS!$L$5:$L$457,"*"&A12&"*",WBS!$N$5:$N$457,"Pha 2") -> 1 | I12: =COUNTIFS(WBS!$L$5:$L$457,"*"&A12&"*",WBS!$N$5:$N$457,"Pha 3") -> 0 | J12: =COUNTIFS(WBS!$L$5:$L$457,"*"&A12&"*",WBS!$O$5:$O$457,"Cần xác nhận") -> 2 | K12: =IFERROR(SUMPRODUCT((ISNUMBER(SEARCH(A12,WBS!$L$5:$L$457)))*WBS!$Z$5:$Z$457)/C12,0) -> 0
A13: CAP-09 | B13: BR-009 | C13: =COUNTIF(WBS!$L$5:$L$457,"*"&A13&"*") -> 5 | D13: =COUNTIFS(WBS!$L$5:$L$457,"*"&A13&"*",WBS!$M$5:$M$457,"Must") -> 5 | E13: =COUNTIFS(WBS!$L$5:$L$457,"*"&A13&"*",WBS!$M$5:$M$457,"Should") -> 0 | F13: =COUNTIFS(WBS!$L$5:$L$457,"*"&A13&"*",WBS!$M$5:$M$457,"Could") -> 0 | G13: =COUNTIFS(WBS!$L$5:$L$457,"*"&A13&"*",WBS!$N$5:$N$457,"Pha 1") -> 5 | H13: =COUNTIFS(WBS!$L$5:$L$457,"*"&A13&"*",WBS!$N$5:$N$457,"Pha 2") -> 0 | I13: =COUNTIFS(WBS!$L$5:$L$457,"*"&A13&"*",WBS!$N$5:$N$457,"Pha 3") -> 0 | J13: =COUNTIFS(WBS!$L$5:$L$457,"*"&A13&"*",WBS!$O$5:$O$457,"Cần xác nhận") -> 0 | K13: =IFERROR(SUMPRODUCT((ISNUMBER(SEARCH(A13,WBS!$L$5:$L$457)))*WBS!$Z$5:$Z$457)/C13,0) -> 0
A14: CAP-10 | B14: BR-010 | C14: =COUNTIF(WBS!$L$5:$L$457,"*"&A14&"*") -> 13 | D14: =COUNTIFS(WBS!$L$5:$L$457,"*"&A14&"*",WBS!$M$5:$M$457,"Must") -> 12 | E14: =COUNTIFS(WBS!$L$5:$L$457,"*"&A14&"*",WBS!$M$5:$M$457,"Should") -> 1 | F14: =COUNTIFS(WBS!$L$5:$L$457,"*"&A14&"*",WBS!$M$5:$M$457,"Could") -> 0 | G14: =COUNTIFS(WBS!$L$5:$L$457,"*"&A14&"*",WBS!$N$5:$N$457,"Pha 1") -> 13 | H14: =COUNTIFS(WBS!$L$5:$L$457,"*"&A14&"*",WBS!$N$5:$N$457,"Pha 2") -> 0 | I14: =COUNTIFS(WBS!$L$5:$L$457,"*"&A14&"*",WBS!$N$5:$N$457,"Pha 3") -> 0 | J14: =COUNTIFS(WBS!$L$5:$L$457,"*"&A14&"*",WBS!$O$5:$O$457,"Cần xác nhận") -> 0 | K14: =IFERROR(SUMPRODUCT((ISNUMBER(SEARCH(A14,WBS!$L$5:$L$457)))*WBS!$Z$5:$Z$457)/C14,0) -> 0
A15: CAP-11 | B15: BR-011 | C15: =COUNTIF(WBS!$L$5:$L$457,"*"&A15&"*") -> 3 | D15: =COUNTIFS(WBS!$L$5:$L$457,"*"&A15&"*",WBS!$M$5:$M$457,"Must") -> 3 | E15: =COUNTIFS(WBS!$L$5:$L$457,"*"&A15&"*",WBS!$M$5:$M$457,"Should") -> 0 | F15: =COUNTIFS(WBS!$L$5:$L$457,"*"&A15&"*",WBS!$M$5:$M$457,"Could") -> 0 | G15: =COUNTIFS(WBS!$L$5:$L$457,"*"&A15&"*",WBS!$N$5:$N$457,"Pha 1") -> 3 | H15: =COUNTIFS(WBS!$L$5:$L$457,"*"&A15&"*",WBS!$N$5:$N$457,"Pha 2") -> 0 | I15: =COUNTIFS(WBS!$L$5:$L$457,"*"&A15&"*",WBS!$N$5:$N$457,"Pha 3") -> 0 | J15: =COUNTIFS(WBS!$L$5:$L$457,"*"&A15&"*",WBS!$O$5:$O$457,"Cần xác nhận") -> 2 | K15: =IFERROR(SUMPRODUCT((ISNUMBER(SEARCH(A15,WBS!$L$5:$L$457)))*WBS!$Z$5:$Z$457)/C15,0) -> 0
A16: CAP-12 | B16: BR-012 | C16: =COUNTIF(WBS!$L$5:$L$457,"*"&A16&"*") -> 6 | D16: =COUNTIFS(WBS!$L$5:$L$457,"*"&A16&"*",WBS!$M$5:$M$457,"Must") -> 6 | E16: =COUNTIFS(WBS!$L$5:$L$457,"*"&A16&"*",WBS!$M$5:$M$457,"Should") -> 0 | F16: =COUNTIFS(WBS!$L$5:$L$457,"*"&A16&"*",WBS!$M$5:$M$457,"Could") -> 0 | G16: =COUNTIFS(WBS!$L$5:$L$457,"*"&A16&"*",WBS!$N$5:$N$457,"Pha 1") -> 6 | H16: =COUNTIFS(WBS!$L$5:$L$457,"*"&A16&"*",WBS!$N$5:$N$457,"Pha 2") -> 0 | I16: =COUNTIFS(WBS!$L$5:$L$457,"*"&A16&"*",WBS!$N$5:$N$457,"Pha 3") -> 0 | J16: =COUNTIFS(WBS!$L$5:$L$457,"*"&A16&"*",WBS!$O$5:$O$457,"Cần xác nhận") -> 0 | K16: =IFERROR(SUMPRODUCT((ISNUMBER(SEARCH(A16,WBS!$L$5:$L$457)))*WBS!$Z$5:$Z$457)/C16,0) -> 0
... A25: CAP-21 | B25: BR-021 | C25: =COUNTIF(WBS!$L$5:$L$457,"*"&A25&"*") -> 31 | D25: =COUNTIFS(WBS!$L$5:$L$457,"*"&A25&"*",WBS!$M$5:$M$457,"Must") -> 0 | E25: =COUNTIFS(WBS!$L$5:$L$457,"*"&A25&"*",WBS!$M$5:$M$457,"Should") -> 0 | F25: =COUNTIFS(WBS!$L$5:$L$457,"*"&A25&"*",WBS!$M$5:$M$457,"Could") -> 31 | G25: =COUNTIFS(WBS!$L$5:$L$457,"*"&A25&"*",WBS!$N$5:$N$457,"Pha 1") -> 0 | H25: =COUNTIFS(WBS!$L$5:$L$457,"*"&A25&"*",WBS!$N$5:$N$457,"Pha 2") -> 0 | I25: =COUNTIFS(WBS!$L$5:$L$457,"*"&A25&"*",WBS!$N$5:$N$457,"Pha 3") -> 31 | J25: =COUNTIFS(WBS!$L$5:$L$457,"*"&A25&"*",WBS!$O$5:$O$457,"Cần xác nhận") -> 31 | K25: =IFERROR(SUMPRODUCT((ISNUMBER(SEARCH(A25,WBS!$L$5:$L$457)))*WBS!$Z$5:$Z$457)/C25,0) -> 0

Sheet Dependencies
A1: DEPENDENCIES & BLOCKERS
A3: Dependency | B3: Chuỗi ảnh hưởng | C3: Biện pháp quản trị | D3: Owner | E3: Status | F3: Evidence / Decision
A4: Quyết định A1 về mức tự cấu hình | B4: A1 → Workflow/Admin work item | C4: Chốt trước estimate; nếu chọn T2 phải bổ sung phân hệ Admin và tái baseline WBS | E4: Open
A5: Quyết định A2 về ký số | B5: A2 → eForm/Ký duyệt/Tích hợp | C5: Xác định hình thức ký và môi trường test trước thiết kế chi tiết | E5: Open
A6: Thiếu chi tiết RD08, RD10 | B6: A4/A5 → work item RD08/RD10 | C6: Workshop riêng; không cam kết effort trước sign-off | E6: Open
A7: Nguồn dữ liệu RD03.06 | B7: A3 → Báo cáo/Thực hiện nhiệm vụ | C7: Chốt nhập tay, kéo tích hợp lên Pha 1 hoặc điều chỉnh phạm vi | E7: Open
A8: Hệ thống đối tác | B8: INT work item → Pha 2 | C8: Có owner, contract, sandbox và mock server | E8: Open
A9: NFR chưa có ngưỡng | B9: C1–C5 → Test/Production readiness | C9: Chốt trước capacity planning và NFR test | E9: Open
A10: AI on-premise | B10: A7 → CAP-21/REQ-064–068 | C10: Tách release/budget; AI không làm chặn quy trình lõi | E10: Open

Sheet Gates & Decisions
A1: GATES & OPEN DECISIONS — FSL V4
A2: Nguồn: sheet 05_Cau_hoi_mo; cột Disposition Status/Owner/Due Date/Evidence dùng để quản lý xử lý.
A4: Nhóm | B4: Mã | C4: Nội dung cần xác nhận | D4: Phương án/Đề xuất hiện tại | E4: Ảnh hưởng | F4: Trạng thái nguồn | G4: Owner | H4: Disposition Status | I4: Due Date | J4: Decision / Evidence
A5: A - Chặn phạm vi | B5: A1 | C5: Mức độ VHT tự điều chỉnh quy trình | D5: Mức 1: VHT IT dùng công cụ chuyên dụng; chưa mặc định xây Admin T2. | E5: Rất cao | F5: Chưa chốt | H5: Open
A6: A - Chặn phạm vi | B6: A2 | C6: Ký duyệt là xác nhận điện tử hay ký số | D6: Chưa đưa ký số pháp lý vào phạm vi chắc chắn. | E6: Rất cao | F6: Chưa chốt | H6: Open
A7: A - Chặn phạm vi | B7: A3 | C7: Nguồn dữ liệu báo cáo RD03.06 Pha 1 | D7: Người dùng nhập tay hoặc kéo một phần tích hợp lên Pha 1. | E7: Rất cao | F7: Chưa chốt | H7: Open
A8: A - Chặn phạm vi | B8: A4 | C8: Chi tiết RD08 và RD10 Pha 1 | D8: Yêu cầu khách cung cấp quy trình riêng hoặc thu hẹp cam kết. | E8: Rất cao | F8: Chưa chốt | H8: Open
A9: A - Chặn phạm vi | B9: A5 | C9: RD10 là kho văn bản hay nơi ban hành quy trình chạy | D9: Tạm tách kho tài liệu và quản trị workflow; chờ xác nhận. | E9: Rất cao | F9: Chưa chốt | H9: Open
A10: A - Chặn phạm vi | B10: A6 | C10: Nguyên tắc nghiệm thu hai mức cho CAP-14…CAP-18 | D10: Mức B: nghiệm thu năng lực nền bằng cấu hình mẫu và dữ liệu mô phỏng tại Pha 1; đầy đủ khi tích hợp Pha 2 hoàn thành (BRD 0.9.1 mục 9). | E10: Rất cao | F10: Đề xuất | H10: Open
A11: A - Chặn phạm vi | B11: A7 | C11: Phạm vi trợ lý AI hỗ trợ nghiệp vụ (CAP-21) | D11: Đề xuất pha tùy chọn sau Pha 1; AI chỉ gợi ý, người quyết; mô hình on-premise. Chốt luồng thí điểm, checklist, bộ dữ liệu kiểm thử, người đánh giá và ngưỡng chất lượng trước phát triển. Chưa thuộc phạm vi/nghiệm thu cho đến khi khách chấp thuận (BRD 0.9.3 mục 5.6/9). | E11: Rất cao | F11: Đề xuất | H11: Open
A12: B - Thiết kế | B12: B1 | C12: Phiên bản áp dụng cho hồ sơ đang chạy | D12: Giữ phiên bản có hiệu lực lúc khởi tạo. | E12: Cao | F12: Đề xuất | H12: Open
A13: B - Thiết kế | B13: B2 | C13: Ai xác nhận nội dung đề tài hoàn thành | D13: Người dùng xác nhận; hệ thống chỉ gợi ý từ dữ liệu tích hợp. | E13: Cao | F13: Đề xuất | H13: Open
A14: B - Thiết kế | B14: B3 | C14: Điều chỉnh vượt chủ trương | D14: Quay lại RD01 hoặc tạo luồng riêng theo quyết định khách hàng. | E14: Cao | F14: Chưa chốt | H14: Open
A15: B - Thiết kế | B15: B4 | C15: Quorum và quy tắc kết luận hội đồng | D15: Cấu hình theo loại hội đồng/quy chế. | E15: Cao | F15: Chưa chốt | H15: Open
A16: B - Thiết kế | B16: B5 | C16: Storage là hệ ngoài hay kho nội bộ | D16: Tạm coi là hệ riêng cần connector. | E16: Cao | F16: Chưa chốt | H16: Open
... A31: D - Lỗi nguồn | B31: D6 | C31: Mã hiệu QT.VHT.CLKHCN còn dấu chấm lửng | D31: Đề nghị cung cấp mã đầy đủ. | E31: Thấp | F31: Chưa chốt | H31: Open

Sheet FSL Source
A1: FUNCTIONAL SCOPE LIST – HỆ THỐNG QUẢN LÝ NHIỆM VỤ KHCN
A2: Phiên bản đồng bộ theo BRD 0.9.3 và HLD 3.3-draft: CAP-01…CAP-20, 28 luồng nghiệp vụ, phân pha chính thức, nguyên tắc nghiệm thu hai mức (CAP-14…CAP-18 nghiệm thu năng lực nền tại Pha 1). Phân hệ Trợ lý AI (CAP-21) là đề xuất tùy chọn, chờ khách chốt A7; 23 tính năng nguồn được truy vết qua REQ-064…REQ-068. Đây là danh mục phạm vi chức năng, chưa phải WBS ước lượng.
A4: STT | B4: Feature ID | C4: Phân hệ | D4: Module | E4: Nhóm chức năng | F4: Chức năng | G4: Mô tả phạm vi | H4: Vai trò chính | I4: Loại | J4: Quy trình/RD | K4: Capability ID | L4: Priority | M4: Release đề xuất | N4: Trạng thái phạm vi | O4: Nguồn/Thay đổi | P4: Định hướng nghiệm thu/Ghi chú | Q4: Requirement/NFR ID
A5: 1 | B5: IAM-SSO-001 | C5: Truy cập, Tổ chức & Phân quyền | D5: Đăng nhập & SSO | E5: Xác thực | F5: Đăng nhập qua SSO/OIDC | G5: Chuyển hướng đến Identity Provider, nhận token và tạo phiên làm việc hợp lệ. | H5: Tất cả người dùng | I5: Nền tảng | K5: CAP-20 | L5: Must | M5: Pha 1 | N5: Đề xuất trong phạm vi | O5: Hiệu chỉnh từ VHT_WBS | P5: Đăng nhập thành công bằng tài khoản hợp lệ; lỗi xác thực không làm lộ thông tin nhạy cảm.
A6: 2 | B6: IAM-SSO-002 | C6: Truy cập, Tổ chức & Phân quyền | D6: Đăng nhập & SSO | E6: Xác thực | F6: Đăng xuất tập trung | G6: Kết thúc phiên ứng dụng và phiên SSO theo chính sách tổ chức. | H6: Tất cả người dùng | I6: Nền tảng | K6: CAP-20 | L6: Must | M6: Pha 1 | N6: Đề xuất trong phạm vi | O6: Hiệu chỉnh từ VHT_WBS
A7: 3 | B7: IAM-SSO-003 | C7: Truy cập, Tổ chức & Phân quyền | D7: Đăng nhập & SSO | E7: Bảo mật phiên | F7: Gia hạn và hết hạn phiên | G7: Quản lý refresh token, timeout không hoạt động và bắt buộc đăng nhập lại. | H7: Tất cả người dùng | I7: Bảo mật | K7: CAP-20 | L7: Must | M7: Pha 1 | N7: Đề xuất trong phạm vi | O7: Bổ sung
A8: 4 | B8: IAM-SSO-004 | C8: Truy cập, Tổ chức & Phân quyền | D8: Đăng nhập & SSO | E8: Hồ sơ người dùng | F8: Xem hồ sơ và ngữ cảnh đăng nhập | G8: Hiển thị người dùng, đơn vị, vai trò, phạm vi dữ liệu và quyền hiệu lực. | H8: Tất cả người dùng | I8: Nền tảng | K8: CAP-20 | L8: Must | M8: Pha 1 | N8: Đề xuất trong phạm vi | O8: Bổ sung
A9: 5 | B9: IAM-ORG-001 | C9: Truy cập, Tổ chức & Phân quyền | D9: Cơ cấu tổ chức | E9: Đơn vị tổ chức | F9: Xem danh sách Đơn vị tổ chức | G9: Tra cứu danh sách, phân trang, sắp xếp và lọc Đơn vị tổ chức theo các tiêu chí nghiệp vụ. | H9: Quản trị hệ thống | I9: Nghiệp vụ | K9: CAP-20 | L9: Must | M9: Pha 1 | N9: Đề xuất trong phạm vi | O9: Bổ sung theo EPIC01 | P9: Danh sách hiển thị đúng phạm vi dữ liệu và hỗ trợ lọc/xuất theo quyền.
A10: 6 | B10: IAM-ORG-002 | C10: Truy cập, Tổ chức & Phân quyền | D10: Cơ cấu tổ chức | E10: Đơn vị tổ chức | F10: Tạo mới Đơn vị tổ chức | G10: Khởi tạo Đơn vị tổ chức, kiểm tra dữ liệu bắt buộc và lưu nháp trước khi hoàn tất. | H10: Quản trị hệ thống | I10: Nghiệp vụ | K10: CAP-20 | L10: Must | M10: Pha 1 | N10: Đề xuất trong phạm vi | O10: Bổ sung theo EPIC01 | P10: Dữ liệu hợp lệ được lưu; lỗi validation hiển thị tại trường tương ứng.
A11: 7 | B11: IAM-ORG-003 | C11: Truy cập, Tổ chức & Phân quyền | D11: Cơ cấu tổ chức | E11: Đơn vị tổ chức | F11: Xem chi tiết Đơn vị tổ chức | G11: Hiển thị thông tin tổng quan, dữ liệu chi tiết, tài liệu liên quan và trạng thái của Đơn vị tổ chức. | H11: Quản trị hệ thống | I11: Nghiệp vụ | K11: CAP-20 | L11: Must | M11: Pha 1 | N11: Đề xuất trong phạm vi | O11: Bổ sung theo EPIC01 | P11: Thông tin hiển thị đúng phiên bản và quyền truy cập.
A12: 8 | B12: IAM-ORG-004 | C12: Truy cập, Tổ chức & Phân quyền | D12: Cơ cấu tổ chức | E12: Đơn vị tổ chức | F12: Chỉnh sửa Đơn vị tổ chức | G12: Cập nhật Đơn vị tổ chức khi trạng thái và quyền người dùng cho phép; kiểm soát xung đột cập nhật. | H12: Quản trị hệ thống | I12: Nghiệp vụ | K12: CAP-20 | L12: Must | M12: Pha 1 | N12: Đề xuất trong phạm vi | O12: Bổ sung theo EPIC01 | P12: Chỉ trường được phép sửa có hiệu lực và thay đổi được ghi lịch sử.
A13: 9 | B13: IAM-ORG-005 | C13: Truy cập, Tổ chức & Phân quyền | D13: Cơ cấu tổ chức | E13: Đơn vị tổ chức | F13: Xóa/Ngừng sử dụng Đơn vị tổ chức | G13: Xóa logic hoặc ngừng sử dụng Đơn vị tổ chức sau khi kiểm tra ràng buộc tham chiếu. | H13: Quản trị/Cán bộ nghiệp vụ | I13: Nghiệp vụ | K13: CAP-20 | L13: Should | M13: Pha 1 | N13: Đề xuất trong phạm vi | O13: Bổ sung theo EPIC01 | P13: Không xóa vật lý dữ liệu đã phát sinh giao dịch; cảnh báo rõ quan hệ phụ thuộc.
A14: 10 | B14: IAM-ORG-006 | C14: Truy cập, Tổ chức & Phân quyền | D14: Cơ cấu tổ chức | E14: Đơn vị tổ chức | F14: Xem lịch sử Đơn vị tổ chức | G14: Theo dõi phiên bản, thay đổi dữ liệu, người thực hiện và lịch sử xử lý của Đơn vị tổ chức. | H14: Cán bộ nghiệp vụ/Quản trị | I14: Audit | K14: CAP-20 | L14: Must | M14: Pha 1 | N14: Đề xuất trong phạm vi | O14: Bổ sung theo EPIC01 | P14: Lịch sử không thể sửa và truy vết được trước/sau của thay đổi quan trọng.
A15: 11 | B15: IAM-ORG-007 | C15: Truy cập, Tổ chức & Phân quyền | D15: Cơ cấu tổ chức | E15: Cây tổ chức | F15: Quản lý cây tổ chức đa cấp | G15: Thiết lập quan hệ cha-con, cấp đơn vị, hiệu lực và lịch sử thay đổi cơ cấu. | H15: Quản trị hệ thống | I15: Cấu hình | K15: CAP-20 | L15: Must | M15: Pha 1 | N15: Đề xuất trong phạm vi | O15: Bổ sung
A16: 12 | B16: IAM-ORG-008 | C16: Truy cập, Tổ chức & Phân quyền | D16: Cơ cấu tổ chức | E16: Chức danh | F16: Quản lý chức danh và vị trí công việc | G16: Khai báo chức danh, vị trí, cấp quản lý và ánh xạ dữ liệu nhân sự. | H16: Quản trị hệ thống | I16: Cấu hình | K16: CAP-20 | L16: Should | M16: Pha 1 | N16: Đề xuất trong phạm vi | O16: Bổ sung
A17: 13 | B17: IAM-USR-001 | C17: Truy cập, Tổ chức & Phân quyền | D17: Người dùng & định danh | E17: Người dùng ứng dụng | F17: Xem danh sách Người dùng ứng dụng | G17: Tra cứu danh sách, phân trang, sắp xếp và lọc Người dùng ứng dụng theo các tiêu chí nghiệp vụ. | H17: Quản trị hệ thống | I17: Nghiệp vụ | K17: CAP-20 | L17: Must | M17: Pha 1 | N17: Đề xuất trong phạm vi | O17: Bổ sung theo EPIC02 | P17: Danh sách hiển thị đúng phạm vi dữ liệu và hỗ trợ lọc/xuất theo quyền.
A18: 14 | B18: IAM-USR-002 | C18: Truy cập, Tổ chức & Phân quyền | D18: Người dùng & định danh | E18: Người dùng ứng dụng | F18: Tạo mới Người dùng ứng dụng | G18: Khởi tạo Người dùng ứng dụng, kiểm tra dữ liệu bắt buộc và lưu nháp trước khi hoàn tất. | H18: Quản trị hệ thống | I18: Nghiệp vụ | K18: CAP-20 | L18: Must | M18: Pha 1 | N18: Đề xuất trong phạm vi | O18: Bổ sung theo EPIC02 | P18: Dữ liệu hợp lệ được lưu; lỗi validation hiển thị tại trường tương ứng.
A19: 15 | B19: IAM-USR-003 | C19: Truy cập, Tổ chức & Phân quyền | D19: Người dùng & định danh | E19: Người dùng ứng dụng | F19: Xem chi tiết Người dùng ứng dụng | G19: Hiển thị thông tin tổng quan, dữ liệu chi tiết, tài liệu liên quan và trạng thái của Người dùng ứng dụng. | H19: Quản trị hệ thống | I19: Nghiệp vụ | K19: CAP-20 | L19: Must | M19: Pha 1 | N19: Đề xuất trong phạm vi | O19: Bổ sung theo EPIC02 | P19: Thông tin hiển thị đúng phiên bản và quyền truy cập.
A20: 16 | B20: IAM-USR-004 | C20: Truy cập, Tổ chức & Phân quyền | D20: Người dùng & định danh | E20: Người dùng ứng dụng | F20: Chỉnh sửa Người dùng ứng dụng | G20: Cập nhật Người dùng ứng dụng khi trạng thái và quyền người dùng cho phép; kiểm soát xung đột cập nhật. | H20: Quản trị hệ thống | I20: Nghiệp vụ | K20: CAP-20 | L20: Must | M20: Pha 1 | N20: Đề xuất trong phạm vi | O20: Bổ sung theo EPIC02 | P20: Chỉ trường được phép sửa có hiệu lực và thay đổi được ghi lịch sử.
A21: 17 | B21: IAM-USR-005 | C21: Truy cập, Tổ chức & Phân quyền | D21: Người dùng & định danh | E21: Người dùng ứng dụng | F21: Xóa/Ngừng sử dụng Người dùng ứng dụng | G21: Xóa logic hoặc ngừng sử dụng Người dùng ứng dụng sau khi kiểm tra ràng buộc tham chiếu. | H21: Quản trị/Cán bộ nghiệp vụ | I21: Nghiệp vụ | K21: CAP-20 | L21: Should | M21: Pha 1 | N21: Đề xuất trong phạm vi | O21: Bổ sung theo EPIC02 | P21: Không xóa vật lý dữ liệu đã phát sinh giao dịch; cảnh báo rõ quan hệ phụ thuộc.
A22: 18 | B22: IAM-USR-006 | C22: Truy cập, Tổ chức & Phân quyền | D22: Người dùng & định danh | E22: Người dùng ứng dụng | F22: Xem lịch sử Người dùng ứng dụng | G22: Theo dõi phiên bản, thay đổi dữ liệu, người thực hiện và lịch sử xử lý của Người dùng ứng dụng. | H22: Cán bộ nghiệp vụ/Quản trị | I22: Audit | K22: CAP-20 | L22: Must | M22: Pha 1 | N22: Đề xuất trong phạm vi | O22: Bổ sung theo EPIC02 | P22: Lịch sử không thể sửa và truy vết được trước/sau của thay đổi quan trọng.
A23: 19 | B23: IAM-USR-007 | C23: Truy cập, Tổ chức & Phân quyền | D23: Người dùng & định danh | E23: Đồng bộ | F23: Đồng bộ người dùng từ AD/QLNS | G23: Đồng bộ hồ sơ, đơn vị, chức danh và trạng thái người dùng; ghi nhận sai lệch. | H23: Quản trị hệ thống | I23: Tích hợp | K23: CAP-20 | L23: Must | M23: Pha 1 | N23: Đề xuất trong phạm vi | O23: Bổ sung
A24: 20 | B24: IAM-USR-008 | C24: Truy cập, Tổ chức & Phân quyền | D24: Người dùng & định danh | E24: Phân công | F24: Gán vai trò và phạm vi dữ liệu cho người dùng | G24: Mỗi assignment gồm user, role, data scope, đơn vị/nhiệm vụ và thời hạn hiệu lực. | H24: Quản trị hệ thống | I24: Phân quyền | K24: CAP-20 | L24: Must | M24: Pha 1 | N24: Đề xuất trong phạm vi | O24: Bổ sung theo recfactor-module-user-role
A25: 21 | B25: IAM-USR-009 | C25: Truy cập, Tổ chức & Phân quyền | D25: Người dùng & định danh | E25: Phân công | F25: Ủy quyền và người thay thế | G25: Thiết lập ủy quyền theo thời gian, phạm vi task/quy trình và ngăn xung đột phân quyền. | H25: Người dùng/Quản trị | I25: Phân quyền | K25: CAP-20; CAP-13 | L25: Should | M25: Pha 2 | N25: Đề xuất trong phạm vi | O25: Bổ sung
A26: 22 | B26: IAM-RBAC-001 | C26: Truy cập, Tổ chức & Phân quyền | D26: Vai trò & phân quyền | E26: Vai trò nghiệp vụ | F26: Xem danh sách Vai trò nghiệp vụ | G26: Tra cứu danh sách, phân trang, sắp xếp và lọc Vai trò nghiệp vụ theo các tiêu chí nghiệp vụ. | H26: Quản trị hệ thống | I26: Nghiệp vụ | K26: CAP-20 | L26: Must | M26: Pha 1 | N26: Đề xuất trong phạm vi | O26: Bổ sung theo EPIC03 | P26: Danh sách hiển thị đúng phạm vi dữ liệu và hỗ trợ lọc/xuất theo quyền.
A27: 23 | B27: IAM-RBAC-002 | C27: Truy cập, Tổ chức & Phân quyền | D27: Vai trò & phân quyền | E27: Vai trò nghiệp vụ | F27: Tạo mới Vai trò nghiệp vụ | G27: Khởi tạo Vai trò nghiệp vụ, kiểm tra dữ liệu bắt buộc và lưu nháp trước khi hoàn tất. | H27: Quản trị hệ thống | I27: Nghiệp vụ | K27: CAP-20 | L27: Must | M27: Pha 1 | N27: Đề xuất trong phạm vi | O27: Bổ sung theo EPIC03 | P27: Dữ liệu hợp lệ được lưu; lỗi validation hiển thị tại trường tương ứng.
A28: 24 | B28: IAM-RBAC-003 | C28: Truy cập, Tổ chức & Phân quyền | D28: Vai trò & phân quyền | E28: Vai trò nghiệp vụ | F28: Xem chi tiết Vai trò nghiệp vụ | G28: Hiển thị thông tin tổng quan, dữ liệu chi tiết, tài liệu liên quan và trạng thái của Vai trò nghiệp vụ. | H28: Quản trị hệ thống | I28: Nghiệp vụ | K28: CAP-20 | L28: Must | M28: Pha 1 | N28: Đề xuất trong phạm vi | O28: Bổ sung theo EPIC03 | P28: Thông tin hiển thị đúng phiên bản và quyền truy cập.
A29: 25 | B29: IAM-RBAC-004 | C29: Truy cập, Tổ chức & Phân quyền | D29: Vai trò & phân quyền | E29: Vai trò nghiệp vụ | F29: Chỉnh sửa Vai trò nghiệp vụ | G29: Cập nhật Vai trò nghiệp vụ khi trạng thái và quyền người dùng cho phép; kiểm soát xung đột cập nhật. | H29: Quản trị hệ thống | I29: Nghiệp vụ | K29: CAP-20 | L29: Must | M29: Pha 1 | N29: Đề xuất trong phạm vi | O29: Bổ sung theo EPIC03 | P29: Chỉ trường được phép sửa có hiệu lực và thay đổi được ghi lịch sử.
A30: 26 | B30: IAM-RBAC-005 | C30: Truy cập, Tổ chức & Phân quyền | D30: Vai trò & phân quyền | E30: Vai trò nghiệp vụ | F30: Xóa/Ngừng sử dụng Vai trò nghiệp vụ | G30: Xóa logic hoặc ngừng sử dụng Vai trò nghiệp vụ sau khi kiểm tra ràng buộc tham chiếu. | H30: Quản trị/Cán bộ nghiệp vụ | I30: Nghiệp vụ | K30: CAP-20 | L30: Should | M30: Pha 1 | N30: Đề xuất trong phạm vi | O30: Bổ sung theo EPIC03 | P30: Không xóa vật lý dữ liệu đã phát sinh giao dịch; cảnh báo rõ quan hệ phụ thuộc.
A31: 27 | B31: IAM-RBAC-006 | C31: Truy cập, Tổ chức & Phân quyền | D31: Vai trò & phân quyền | E31: Vai trò nghiệp vụ | F31: Xem lịch sử Vai trò nghiệp vụ | G31: Theo dõi phiên bản, thay đổi dữ liệu, người thực hiện và lịch sử xử lý của Vai trò nghiệp vụ. | H31: Cán bộ nghiệp vụ/Quản trị | I31: Audit | K31: CAP-20 | L31: Must | M31: Pha 1 | N31: Đề xuất trong phạm vi | O31: Bổ sung theo EPIC03 | P31: Lịch sử không thể sửa và truy vết được trước/sau của thay đổi quan trọng.
A32: 28 | B32: IAM-RBAC-007 | C32: Truy cập, Tổ chức & Phân quyền | D32: Vai trò & phân quyền | E32: Ma trận quyền | F32: Cấu hình ma trận Role × Chức năng × Quyền | G32: Quản lý quyền xem, tạo, sửa, xóa, trình, duyệt, xuất và quản trị theo vai trò. | H32: Quản trị hệ thống | I32: Phân quyền | K32: CAP-20 | L32: Must | M32: Pha 1 | N32: Đề xuất trong phạm vi | O32: Bổ sung
A33: 29 | B33: IAM-RBAC-008 | C33: Truy cập, Tổ chức & Phân quyền | D33: Vai trò & phân quyền | E33: Phạm vi dữ liệu | F33: Cấu hình loại phạm vi dữ liệu | G33: Hỗ trợ bản thân, đơn vị, cây đơn vị, nhiệm vụ được giao và toàn hệ thống. | H33: Quản trị hệ thống | I33: Phân quyền | K33: CAP-20 | L33: Must | M33: Pha 1 | N33: Đề xuất trong phạm vi | O33: Bổ sung
A34: 30 | B34: IAM-RBAC-009 | C34: Truy cập, Tổ chức & Phân quyền | D34: Vai trò & phân quyền | E34: Mô phỏng | F34: Mô phỏng quyền hiệu lực | G34: Giải thích quyền thao tác từ role policy và phạm vi dữ liệu từ user assignment. | H34: Quản trị hệ thống/Audit | I34: Phân quyền | K34: CAP-20 | L34: Should | M34: Pha 2 | N34: Đề xuất trong phạm vi | O34: Bổ sung
A35: 31 | B35: MIS-MISSION-001 | C35: Quản lý Nhiệm vụ KHCN | D35: Hồ sơ nhiệm vụ | E35: Nhiệm vụ KHCN | F35: Xem danh sách Nhiệm vụ KHCN | G35: Tra cứu danh sách, phân trang, sắp xếp và lọc Nhiệm vụ KHCN theo các tiêu chí nghiệp vụ. | H35: Cán bộ KHCN/Chủ nhiệm | I35: Nghiệp vụ | K35: CAP-02; CAP-04 | L35: Must | M35: Pha 1 | N35: Đề xuất trong phạm vi | O35: Hiệu chỉnh từ VHT_WBS | P35: Danh sách hiển thị đúng phạm vi dữ liệu và hỗ trợ lọc/xuất theo quyền.
A36: 32 | B36: MIS-MISSION-002 | C36: Quản lý Nhiệm vụ KHCN | D36: Hồ sơ nhiệm vụ | E36: Nhiệm vụ KHCN | F36: Tạo mới Nhiệm vụ KHCN | G36: Khởi tạo Nhiệm vụ KHCN, kiểm tra dữ liệu bắt buộc và lưu nháp trước khi hoàn tất. | H36: Cán bộ KHCN/Chủ nhiệm | I36: Nghiệp vụ | K36: CAP-02; CAP-04 | L36: Must | M36: Pha 1 | N36: Đề xuất trong phạm vi | O36: Hiệu chỉnh từ VHT_WBS | P36: Dữ liệu hợp lệ được lưu; lỗi validation hiển thị tại trường tương ứng.
A37: 33 | B37: MIS-MISSION-003 | C37: Quản lý Nhiệm vụ KHCN | D37: Hồ sơ nhiệm vụ | E37: Nhiệm vụ KHCN | F37: Xem chi tiết Nhiệm vụ KHCN | G37: Hiển thị thông tin tổng quan, dữ liệu chi tiết, tài liệu liên quan và trạng thái của Nhiệm vụ KHCN. | H37: Cán bộ KHCN/Chủ nhiệm | I37: Nghiệp vụ | K37: CAP-02; CAP-04 | L37: Must | M37: Pha 1 | N37: Đề xuất trong phạm vi | O37: Hiệu chỉnh từ VHT_WBS | P37: Thông tin hiển thị đúng phiên bản và quyền truy cập.
A38: 34 | B38: MIS-MISSION-004 | C38: Quản lý Nhiệm vụ KHCN | D38: Hồ sơ nhiệm vụ | E38: Nhiệm vụ KHCN | F38: Chỉnh sửa Nhiệm vụ KHCN | G38: Cập nhật Nhiệm vụ KHCN khi trạng thái và quyền người dùng cho phép; kiểm soát xung đột cập nhật. | H38: Cán bộ KHCN/Chủ nhiệm | I38: Nghiệp vụ | K38: CAP-02; CAP-04 | L38: Must | M38: Pha 1 | N38: Đề xuất trong phạm vi | O38: Hiệu chỉnh từ VHT_WBS | P38: Chỉ trường được phép sửa có hiệu lực và thay đổi được ghi lịch sử.
A39: 35 | B39: MIS-MISSION-005 | C39: Quản lý Nhiệm vụ KHCN | D39: Hồ sơ nhiệm vụ | E39: Nhiệm vụ KHCN | F39: Xóa/Ngừng sử dụng Nhiệm vụ KHCN | G39: Xóa logic hoặc ngừng sử dụng Nhiệm vụ KHCN sau khi kiểm tra ràng buộc tham chiếu. | H39: Quản trị/Cán bộ nghiệp vụ | I39: Nghiệp vụ | K39: CAP-02; CAP-04 | L39: Should | M39: Pha 1 | N39: Đề xuất trong phạm vi | O39: Hiệu chỉnh từ VHT_WBS | P39: Không xóa vật lý dữ liệu đã phát sinh giao dịch; cảnh báo rõ quan hệ phụ thuộc.
A40: 36 | B40: MIS-MISSION-006 | C40: Quản lý Nhiệm vụ KHCN | D40: Hồ sơ nhiệm vụ | E40: Nhiệm vụ KHCN | F40: Xem lịch sử Nhiệm vụ KHCN | G40: Theo dõi phiên bản, thay đổi dữ liệu, người thực hiện và lịch sử xử lý của Nhiệm vụ KHCN. | H40: Cán bộ nghiệp vụ/Quản trị | I40: Audit | K40: CAP-02; CAP-04 | L40: Must | M40: Pha 1 | N40: Đề xuất trong phạm vi | O40: Hiệu chỉnh từ VHT_WBS | P40: Lịch sử không thể sửa và truy vết được trước/sau của thay đổi quan trọng.
A41: 37 | B41: MIS-MISSION-007 | C41: Quản lý Nhiệm vụ KHCN | D41: Hồ sơ nhiệm vụ | E41: Vòng đời | F41: Quản lý trạng thái vòng đời nhiệm vụ | G41: Quản lý chuyển trạng thái từ đề xuất, phê duyệt, thực hiện, điều chỉnh, nghiệm thu, quyết toán đến đóng nhiệm vụ. | H41: Cán bộ KHCN | I41: Nghiệp vụ | J41: RD01-RD10 | K41: CAP-02; CAP-04 | L41: Must | M41: Pha 1 | N41: Đề xuất trong phạm vi | O41: Bổ sung
...

