Workbook
Name _1: #REF!
Name _1: #REF!
Name _1000A01: #N/A
Name _2: #REF!
Name _2: #REF!
Name _CON1: #REF!
Name _CON1: #REF!
Name _CON2: #REF!
Name _CON2: #REF!
Name _ddn400: #REF!
Name _ddn400: #REF!
Name _ddn600: #REF!
Name _ddn600: #REF!
Name _kl1: #REF!
Name _kl1: #REF!
Name _Km36: #REF!
Name _Km36: #REF!
Name _Knc36: #REF!
Name _Knc36: #REF!
Name _Knc57: #REF!
Name _Knc57: #REF!
Name _Kvl36: #REF!
Name _Kvl36: #REF!
Name _Lan1: {"Thuxm2.xls","Sheet1"}
Name _Lan1: {"Thuxm2.xls","Sheet1"}
Name _MAC12: #REF!
Name _MAC12: #REF!
Name _MAC46: #REF!
Name _MAC46: #REF!
Name _NCL100: #REF!
Name _NCL100: #REF!
Name _NCL200: #REF!
Name _NCL200: #REF!
Name _NCL250: #REF!
Name _NCL250: #REF!
Name _NET2: #REF!
Name _NET2: #REF!
Name _nin190: #REF!
Name _nin190: #REF!
Name _sc1: #REF!
Name _sc1: #REF!
Name _SC2: #REF!
Name _SC2: #REF!
Name _sc3: #REF!
Name _sc3: #REF!
Name _SN3: #REF!
Name _SN3: #REF!
Name _TL1: #REF!
Name _TL1: #REF!
Name _TL2: #REF!
Name _TL2: #REF!
Name _TL3: #REF!
Name _TL3: #REF!
Name _TLA120: #REF!
Name _TLA120: #REF!
Name _TLA35: #REF!
Name _TLA35: #REF!
Name _TLA50: #REF!
Name _TLA50: #REF!
Name _TLA70: #REF!

Sheet Tong muc dau tu
A2: TỔNG MỨC ĐẦU TƯ
A3: (Kèm theo Báo cáo đề xuất chủ trương đầu tư “Tên dự án”)
F6: ĐVT: VNĐ
A7: TT | B7: NỘI DUNG CÁC KHOẢN CHI PHÍ | E7: Thành tiền (chưa VAT) | F7: Thuế VAT | G7: Thành tiền (đã có VAT)
A8: 1 | B8: Chi phí thiết bị (*)
A9: 1.1
A10: 1.2
A11: 1.3
A12: 1.4
A13: 1.5
A14: 2 | B14: Chi phí quản lý dự án
A15: 3 | B15: Chi phí khác
A16: 3.1 | B16: ='2.Qlgs va cac chi phi khac'!B9 -> Chi phí kiểm toán | P16: .
A17: 3.2 | B17: ='2.Qlgs va cac chi phi khac'!B10 -> Chi phí thẩm tra quyết toán
A18: 4 | B18: Chi phí dự phòng
B19: TỔNG CỘNG | J19: 50
A20: Bằng chữ: ...đồng./. | J20: 100
A21: Chi phí thiết bị (*): Đã bao gồm chi phí thông quan, chí phí vận chuyển, chi phí lắp đặt và chi phí đào tạo.
A22: Chi phí dự phòng (**): Dự phòng 5% cho phần phát sinh về trượt giá
F23: ĐƠN VỊ THỰC HIỆN

Sheet 1.Thiet bi
A1: PHỤ LỤC 1: CHI PHÍ THIẾT BỊ
A2: (Kèm theo Báo cáo đề xuất chủ trương đầu tư “Tên dự án”)
A3: STT | B3: Hạng mục | C3: Tên máy/ thiết bị/ thành phần | D3: Đơn vị | E3: Số lượng | F3: Đơn giá chưa VAT (VNĐ) | G3: Thành Tiền chưa VAT (VNĐ) | H3: Tỷ suất VAT/ TNCN | I3: VAT (VNĐ) | J3: Thành tiền (VAT) | K3: Ghi chú | L3: Rohde&Schwarz Vietnam Co.,Ltd | Q3: Công ty Cổ phần Công nghệ COMIT | V3: Công ty TNHH TM công nghệ và kỹ thuật TTS | Z3: Công ty CP thiết bị và dịch vụ công nghệ T&M | AD3: Công ty Elinco | AH3: Công ty TNHH dịch vụ Công nghệ Micro Max Việt Nam | AL3: Công ty TNHH Công nghiệp Techno Việt Nam | AP3: Công ty cổ phần ITC | AT3: Công ty Cổ phần TECOTEC Group
L4: Hạng mục | M4: Số lượng | N4: Đơn giá ngoại tệ | O4: Đơn Giá (VNĐ) | P4: Thành Tiền (VNĐ) | Q4: Hạng mục | R4: Số lượng | S4: Đơn giá ngoại tệ | T4: Đơn giá (VNĐ) | U4: Thành Tiền (VNĐ) | V4: Hạng mục | W4: Số lượng | X4: Đơn giá (VNĐ) | Y4: Thành Tiền (VNĐ) | Z4: Hạng mục | AA4: Số lượng | AB4: Đơn giá (VNĐ) | AC4: Thành Tiền (VNĐ) | AD4: Hạng mục | AE4: Số lượng | AF4: Đơn giá (VNĐ) | AG4: Thành Tiền (VNĐ) | AH4: Hạng mục | AI4: Số lượng | AJ4: Đơn giá (VNĐ) | AK4: Thành Tiền (VNĐ) | AL4: Hạng mục | AM4: Số lượng | AN4: Đơn giá (VNĐ) | AO4: Thành Tiền (VNĐ) | AP4: Hạng mục | AQ4: Số lượng | AR4: Đơn giá (VNĐ) | AS4: Thành Tiền (VNĐ) | AT4: Hạng mục | AU4: Số lượng | AV4: Đơn giá (VNĐ) | AW4: Thành Tiền (VNĐ)
A5: Chi phi thiết bị | P5: =SUM(P6:P10) -> 14892362916 | U5: =SUM(U6:U10) -> 9462000000 | Y5: =SUM(Y6:Y10) -> 12907097000 | AC5: =SUM(AC6:AC10) -> 16254100000 | AG5: =SUM(AG6:AG10) -> 16851800000 | AK5: =SUM(AK6:AK10) -> 13620000000 | AO5: =SUM(AO6:AO10) -> 13829000000 | AS5: =SUM(AS6:AS10) -> 13280000000 | AW5: =SUM(AW6:AW10) -> 12000000000
A6: 1 | E6: 1 | L6: =B6 -> 0 | M6: 1 | O6: =13994726241+897636675 -> 14892362916 | P6: =M6*O6 -> 14892362916 | Y6: =W6*X6 -> 0 | Z6: Nâng cấp Lab Đo kiểm tương thích điện từ trường | AA6: 1 | AB6: 16254100000 | AC6: =AB6 -> 16254100000 | AD6: Nâng cấp Lab Đo kiểm tương thích điện từ trường | AE6: 1 | AF6: 16851800000 | AG6: =AE6*AF6 -> 16851800000
A7: 2 | E7: 1 | Q7: =C7 -> 0 | R7: 1 | T7: 6540000000 | U7: =T7*R7 -> 6540000000 | AP7: =C7 -> 0 | AQ7: 1 | AR7: 8800000000 | AS7: =AR7*AQ7 -> 8800000000 | AT7: =C7 -> 0 | AU7: 1 | AV7: 7800000000 | AW7: =AV7*AU7 -> 7800000000
E8: 1 | Q8: =C8 -> 0 | R8: 1 | T8: 2200000000 | U8: =R8*T8 -> 2200000000 | AP8: =C8 -> 0 | AQ8: 1 | AR8: 3600000000 | AS8: =AQ8*AR8 -> 3600000000 | AT8: =C8 -> 0 | AU8: 1 | AV8: 3400000000 | AW8: =AV8*AU8 -> 3400000000
E9: 1 | Q9: =C9 -> 0 | R9: 1 | T9: 722000000 | U9: =R9*T9 -> 722000000 | AC9: =+AA9*AB9 -> 0 | AP9: =C9 -> 0 | AQ9: 1 | AR9: 880000000 | AS9: =AR9*AQ9 -> 880000000 | AT9: =C9 -> 0 | AU9: 1 | AV9: 800000000 | AW9: =AV9*AU9 -> 800000000
E10: 1 | U10: =R10*T10 -> 0 | V10: =C10 -> 0 | W10: 1 | X10: 12907097000 | Y10: =W10*X10 -> 12907097000 | AC10: =+AA10*AB10 -> 0 | AH10: Thiết bị thử nghiệm môi trường kết hợp áp suất thấp (mô phỏng độ cao) | AI10: 1 | AJ10: 13620000000 | AK10: =+AI10*AJ10 -> 13620000000 | AL10: Thiết bị thử nghiệm môi trường kết hợp áp suất thấp (mô phỏng độ cao) | AM10: 1 | AN10: 13829000000 | AO10: =+AM10*AN10 -> 13829000000
P12: TỔNG CÔNG TY VHT

Sheet Thiet bị
B2: STT | C2: Trang thiết bị | D2: Số lượng cần | I2: Đã có (Đảm bảo đo 5G) | J2: Cần nâng cấp | Q2: Mua mới | AC2: Tổng | AE2: Phục vụ đề tài
Q3: Hãng 1 | V3: Tính năng | W3: Hãng 2 | AD3: Tính năng | AF3: USD | AG3: 23600
D4: HW | E4: FPGA | F4: L1 | G4: QA | H4: Tổng | J4: Tên máy | K4: Tên hãng | L4: Số lượng | M4: Đơn giá (Ngoại tệ) | N4: Đơn giá (VNĐ) | O4: Thành Tiền (VNĐ) | P4: Tính năng | Q4: Tên máy | R4: Tên hãng | S4: Số lượng | T4: Đơn Giá (VNĐ) | U4: Giá (VNĐ) | W4: Tên máy | X4: Tên hãng | Y4: Số lượng | Z4: Đơn giá (Ngoại tệ) | AA4: Đơn giá (VNĐ) | AB4: Thành Tiền (VNĐ) | AF4: Euro | AG4: 26650
B5: 1 | C5: Máy phân tích tín hiệu VSA | D5: 1 | E5: 1 | G5: 1 | H5: =SUM(D5:G7) -> 3 | I5: 0 | J5: N9020A | K5: Keysight | L5: 1 | N5: 988974000 | O5: =L5*N5 -> 988974000 | V5: + HW upgrade_N9020AK-MTP_Multi-touch User Interface + FW_upgrade_N9085EM0E_Ứng dụng đo kiểm 5G NR + Support: R-Y5C-001-A, R-Y5C-001-L : 12 tháng hỗ trợ | AD5: + HW_upgrade_FSV-K144/VSE-K144 + FSV-B160 Nâng cấp lên 160 MHz + FW_upgrade_ Thông tin đang cập nhật | AE5: 4G & 5G
B6: 2 | J6: RX MIMO | K6: Keysight | L6: 1 | N6: 8742963500 | O6: =L6*N6 -> 8742963500 | V6: (Software update only, hardware is not updatable) | AD6: (Software update only, hardware is not updatable) | AE6: 4G & 5G
B7: 3 | Q7: N9030 | R7: Keysight | S7: 1 | T7: 4347661560 | U7: =S7*T7 -> 4347661560 | V7: + FSW-K144: Đo kiểm 3gpp 5G NR + FSW-K544: Điều chỉnh đáp ứng tập lệnh tần số SnP file + FSW-B4: (HW option) Tham chiếu tần số chính xác + FSW-B24: (HW option) Pre-Amplifier 30dB, 100kHz to 8/13GHz + FSW-B25: (HW option) Electronic attenuator, 13.6GHz, 1dB steps + FSW-B160: (HW option) Mở rộng Bandwidth 160 MHz | W7: FSW13 | X7: R&S | Y7: 1 | Z7: 164146 | AA7: =Z7*AG4 -> 4374490900 | AB7: =Y7*AA7 -> 4374490900 | AD7: + FSW-K144: Đo kiểm 3gpp 5G NR + FSW-K544: Điều chỉnh đáp ứng tập lệnh tần số SnP file + FSW-B4: (HW option) Tham chiếu tần số chính xác + FSW-B24: (HW option) Pre-Amplifier 30dB, 100kHz to 8/13GHz + FSW-B25: (HW option) Electronic attenuator, 13.6GHz, 1dB steps + FSW-B160: (HW option) Mở rộng Bandwidth 160 MHz | AE7: 4G & 5G | AF7: Nâng cấp FSV13: 39,200 euro nhưng không đo được đầy đủ chỉ tiêu. Cần mua mới thêm FSV8.
B8: 4 | C8: Máy phát tín hiệu VSG | D8: 2 | E8: 2 | F8: 1 | G8: 2 | H8: 7 | I8: 0 | J8: N5182B VSG | K8: Keysight | L8: 5 | N8: 1799959000 | O8: =L8*N8 -> 8999795000 | V8: + License key: N5182BU_657 Tạo tín hiệu RF 160 MHz + License key: N5182BU_656 ARB baseband generator (80MHz RF bandwidth, 32 MSa) + PC Application license: N7631 APPC Signal Studio Pro for 5G NR 2019 + Support: R-Y5C-001-A, R-Y5C-001-L : 12 tháng hỗ trợ | AD8: + FW_upgrade_SMW-K144 Tạo tín hiệu 5G NR R.15 (45,280 €) + HW_upgrade_SMW-B9 Băng thông RF 500 MHz (72,700 €) + HW_upgrade_SMW-B13XT Phần cứng hỗ trợ cho SMW-B9 (7,560 €) + FW_upgrade_SMW-B15 Mô phỏng Fading và Signal Processor + FW_upgrade_SMW-K145 Tạo close loop cho tín hiệu 5G + SW_upgrade: SMW-K19 (software license) + Hiệu chuẩn: Hiệu chuẩn tại Singapore (2,500 €) | AE8: 4G & 5G
B9: 5 | J9: TX MIMO | K9: Keysight | L9: 1 | N9: 24853717500 | O9: =L9*N9 -> 24853717500 | V9: (Update on N5182B) (already have option 506, 657, 657) | AE9: 4G & 5G
B10: 6 | J10: SMW 200A | K10: R&S | L10: 1 | M10: =84100+164530 -> 248630 | N10: =M10*AG4 -> 6625989500 | O10: =L10*N10 -> 6625989500 | P10: Chapter 6: 1 x SMW200A Vector signal generator, base unit; freq.opt.& BBmodule req. 1 x SMW-B107 Frequency range: 100 kHz to 7. 5 GHz, RF path A (HW opt.) 1 x SMW-B13 Baseband main module, one I/Q path to RF section (HW opt.) 1 x SMW-B10 Baseband generator with realtime coder and ARB (HW opt.) 1 x SMW-K144 5G New Radio (SL) Chapter 7: 1 x SMW200A Vector signal generator, base unit; freq.opt.& BBmodule req. 1 x SMW-B107 Frequency range: 100 kHz to 7. 5 GHz, RF path A (HW opt.) 1 x SMW-B207 Frequency range: 100 kHz to 7. 5 GHz, RF path B (HW opt.) 1 x SMW-B13T Baseband main module, two I/Q paths to RF section (HW opt.) 2 x SMW-B10 Baseband generator with realtime coder and ARB (HW opt.) 1 x SMW-K62 Additional white Gaussian noise (SL) 2 x SMW-K144 5G New Radio (SL) | AD10: 1 x SMW-B13XT Wideband baseband main module, two I/Q paths to RF section 2 x SMW-B9 Wideband baseband generator, 500 MHz RF bandwidth, 256 MSaemples, R&S®SMW-B13XT required 4 x SMW-B15 Fading Simulator and Signal Processor 2 x SMW-K144 5G New Radio R&S®SMW-B9/B10 required 2 x SMW-K145 HARQ close loop feedback for 5G 2 x SMW-K19 Digital baseband output for R&S®SMW wideband baseband R&S®SMW-B13XT required (software license) Calibration after changed board | AE10: 4G & 5G | AF10: Chapter 7: 164,530 euro Chapter 6: 84,100 euro
B11: 7 | C11: Nguồn phát cao tần | D11: 0 | E11: 0 | F11: 6 | G11: 0 | H11: 6 | I11: 2 | Q11: N5172B | R11: Keysight | S11: 4 | T11: 1825057000 | U11: =S11*T11 -> 7300228000 | V11: + Tạo tín hiệu RF: SGMA Vector RF Source, 3 GHz RF and baseband HW included + Mở rộng tần số: 6GHz (SL) + Tín hiệu tham chiếu: Reference oscillator OCXO (HW opt) + Digital baseband connectivity (SL) | W11: SGT100A | X11: R&S | Y11: 4 | Z11: 34031.142 | AA11: =Z11*AG4 -> 9.0692993e+08 | AB11: =Y11*AA11 -> 3.6277197e+09 | AD11: 1 x SGT100A SGMA Vector RF Source, 3 GHz RF and baseband HW included 1 x SGT-KB106 Frequency extension 6GHz (SL) 1 x SGT-B1 Reference oscillator OCXO (HW opt.) 1 x SGT-K18 Digital baseband connectivity (SL) | AE11: 4G & 5G
B12: 8 | C12: Nguồn DC | D12: 1 | E12: 1 | F12: 1 | G12: 1 | H12: 4 | I12: 3 | Q12: N5767A Power Supply, 60V, 25A, 1500W | R12: R&S | S12: 1 | T12: 141517000 | U12: =S12*T12 -> 141517000 | V12: Tương đương GW Instek PSU60 - 25: 60V, 25A, 1500W | AE12: 4G & 5G | AF12: R&S Không có
B13: 9 | C13: Connector TMA-A Plug to SMA Femal | D13: 16 | E13: 16 | F13: 8 | G13: 16 | H13: 56 | I13: 0 | Q13: FMC1322085 SMA Female to SMP Female Cable FM-F086 Coax | S13: 56 | T13: 3360500 | U13: =S13*T13 -> 188188000 | V13: Cable TMA-A Plug to N type Femal | AE13: 5G | AF13: R&S Không có
B14: 10 | C14: Cable SMA Male To N Male 12 inch | D14: 16 | E14: 16 | F14: 8 | G14: 16 | H14: 56 | I14: 0 | Q14: PE354-12 SMA Male to N Male cable | R14: Keysight | S14: 56 | T14: 7708000 | U14: =S14*T14 -> 431648000 | V14: 18 Ghz 12 Inch Length (30 cm) | W14: PE354-12 SMA Male to N Male cable | X14: R&S | Y14: =H14 -> 56 | Z14: =161*120% -> 193.2 | AA14: =Z14*AG3 -> 4559520 | AB14: =Y14*AA14 -> 255333120 | AD14: SMA Male to N Male Cable 12 Inch Length Using PE-P141 Coax with HeatShrink, LF Solder, RoHS | AE14: 4G & 5G
B15: 11 | C15: Suy hao | D15: 16 | E15: 16 | F15: 8 | G15: 16 | H15: 56 | I15: 0 | Q15: PE7213-30 | R15: Keysight | S15: 56 | T15: 34192500 | U15: =S15*T15 -> 1914780000 | V15: 30dB 100W 6GHz Attenuator N type | W15: PE7213-30 | X15: R&S | Y15: =H15 -> 56 | Z15: =752*120% -> 902.4 | AA15: =Z15*AG$3 -> 21296640 | AB15: =Y15*AA15 -> 1192611840 | AD15: 30 dB Fixed Attenuator, N Male To N Female Directional Black Anodized Aluminum Heatsink Body Rated To 100 Watts Up To 6 GHz | AE15: 4G & 5G
B16: 12 | C16: Cable SMA Male To N Male 24 inch | D16: 18 | E16: 18 | F16: 9 | G16: 18 | H16: 63 | I16: 0 | Q16: PE354-24 | R16: Keysight | S16: 63 | T16: 13442000 | U16: =S16*T16 -> 846846000 | V16: 18 Ghz 24 Inch Length (60 cm) | W16: PE354-24 | X16: R&S | Y16: =H16 -> 63 | Z16: =172*120% -> 206.4 | AA16: =Z16*AG$3 -> 4871040 | AB16: =Y16*AA16 -> 306875520 | AD16: SMA Male to N Male Cable 24 Inch Length Using PE-P141 Coax with HeatShrink, LF Solder, RoHS | AE16: 4G & 5G
B17: 13 | C17: Switch RF | D17: 6 | E17: 6 | F17: 0 | G17: 6 | H17: 18 | I17: 0 | Q17: ZTVX-16-18 | R17: Keysight | S17: 18 | U17: =S17*T17 -> 0 | V17: 2 by 16 Switch Matrix, 50Ω, USB and Ethernet-TCP/IP control interface, Windows environments Software support | W17: ZTVX-16-18 | X17: R&S | Y17: =H17 -> 18 | Z17: =17000*120% -> 20400 | AA17: =Z17*AG$3 -> 481440000 | AB17: =Y17*AA17 -> 8665920000 | AD17: 2 by 16 Switch Matrix, 50Ω, USB and Ethernet-TCP/IP control interface, Windows environments Software support | AE17: 4G & 5G
B18: 14 | C18: Jig cơ khí | D18: 6 | E18: 6 | F18: 1 | G18: 6 | H18: 19 | I18: 0 | Q18: Tự làm | S18: 19 | U18: =S18*T18 -> 0 | V18: Hỗ trợ di chuyển, gắn suy hao, có thể mở rộng lên 32T32R, … | Y18: =H18 -> 19 | AA18: =Z18*AG$3 -> 0 | AB18: =Y18*AA18 -> 0 | AD18: ? | AE18: 5G
B19: 15 | C19: Cable SMA Male To SMA Male 24 inch | D19: 1 | E19: 1 | F19: 1 | G19: 1 | H19: 4 | I19: 0 | Q19: PE300-24 | R19: Keysight | S19: 4 | T19: 10081500 | U19: =S19*T19 -> 40326000 | V19: 24 Inch Length; 0.6M; PE300-24 | W19: PE300-24 | X19: R&S | Y19: =H19 -> 4 | Z19: =125*120% -> 150 | AA19: =Z19*AG$3 -> 3540000 | AB19: =Y19*AA19 -> 14160000 | AD19: SMA Male to SMA Male Cable 24 Inch Length Using PE-P141 Coax with HeatShrink, LF Solder | AE19: 4G & 5G
B20: 16 | C20: Power Combiner | D20: 1 | E20: 1 | F20: 0 | G20: 1 | H20: 3 | I20: 0 | Q20: ZFRSC-123+ Coaxial Power Splitter/Combiner | R20: Keysight | S20: 3 | T20: 5381500 | U20: =S20*T20 -> 16144500 | V20: Power Combiner | W20: ZFRSC-4-842-S+ | X20: R&S | Y20: =H20 -> 3 | Z20: =170*120% -> 204 | AA20: =Z20*AG$3 -> 4814400 | AB20: =Y20*AA20 -> 14443200 | AD20: 4-way Connectorized Power Splitter, DC-8400MHz | AE20: 5G
B21: 17 | C21: Power Combiner | U21: 5947200 | W21: PE2093 | X21: R&S | Y21: 1 | Z21: =210*120% -> 252 | AA21: =Z21*AG$3 -> 5947200 | AB21: =Y21*AA21 -> 5947200 | AF21: R&S đề xuất sử dụng trong chapter 7
B22: 18 | C22: Power Combiner | U22: 9175680 | W22: PE20DV001 | X22: R&S | Y22: 1 | Z22: =324*120% -> 388.8 | AA22: =Z22*AG$3 -> 9175680 | AB22: =Y22*AA22 -> 9175680 | AF22: R&S đề xuất sử dụng trong chapter 7
B23: 19 | C23: Notch Filter | D23: 2 | E23: 2 | F23: 0 | G23: 2 | H23: 6 | I23: 0 | S23: 6 | U23: =S23*T23 -> 0 | V23: Notch Filter | W23: Notch Filter DL Band n78 (3300-3800) | X23: R&S | Y23: =H23 -> 6 | Z23: =2090*120% -> 2508 | AA23: =Z23*AG$3 -> 59188800 | AB23: =Y23*AA23 -> 355132800 | AD23: TUNABLE BAND REJECT / NOTCH FILTERS FOR 5G NR DL BAND N78 (3300-3800 MHZ) Tuning Range 3000 to 4000 MHz Slopes 7 MHz Bandwidth 10 MHz Attenuation 40 dB min. | AE23: 5G
B24: 20 | C24: Cable trigger BNC To SMA | D24: 0 | E24: 0 | F24: 1 | G24: 0 | H24: 1 | I24: 0 | Q24: PE3M0116-18 MIL-DTL-17 BNC Male to SMA Male Cable 18 Inch Length Using M17/28-RG58 Coax | S24: 1 | T24: 16802500 | U24: =S24*T24 -> 16802500 | W24: PE3M0061-100CM | X24: R&S | Y24: =H24 -> 1 | Z24: =184*120% -> 220.8 | AA24: =Z24*AG$3 -> 5210880 | AB24: =Y24*AA24 -> 5210880 | AD24: MIL-DTL-17 BNC Male to SMA Male Cable 100 cm Length Using M17/128-RG400 Coax | AE24: 4G & 5G
B25: 21 | C25: Termination | U25: 33530880 | W25: PE6039 | X25: R&S | Y25: 2 | Z25: =592*120% -> 710.4 | AA25: =Z25*AG$3 -> 16765440 | AB25: =Y25*AA25 -> 33530880 | AF25: R&S đề xuất sử dụng trong chapter 7
B26: 22 | C26: Máy đo công suất | D26: 3 | E26: 0 | F26: 0 | G26: 0 | H26: 3 | I26: 0 | Q26: U2001A | S26: 1 | T26: 145112500 | U26: =S26*T26 -> 145112500 | V26: USB Power Sensor, -45dBm to +10dBm, 50MHz to 6GHz
B27: 23 | Q27: U2004A | S27: 2 | T27: 163654000 | U27: =S27*T27 -> 327308000 | V27: USB Power Sensor, -30dBm to +20dBm, 1MHz to 6GHz
B28: 24 | C28: High Power Directional Coupler, 35dB | D28: 1 | E28: 0 | F28: 0 | G28: 0 | H28: 1 | I28: 0 | Q28: ZGDC35-93HP+ | S28: =H28 -> 1 | T28: 135595000 | U28: =S28*T28 -> 135595000 | V28: Coupler 35dB | AE28: 4G & 5G
B29: 25 | C29: High Power Bi-Directional Coupler, 16dB | D29: 1 | E29: 0 | F29: 0 | G29: 0 | H29: 1 | I29: 0 | Q29: ZFBDC16-63HP+ | S29: =H29 -> 1 | T29: 287898500 | U29: =S29*T29 -> 287898500 | V29: Coupler 16 dB | AE29: 4G & 5G
B30: 26 | C30: USB SP4T Switch | D30: 5 | E30: 0 | F30: 0 | G30: 0 | H30: 5 | I30: 0 | Q30: USB-SP4T-63 | S30: =H30 -> 5 | T30: 68244000 | U30: =S30*T30 -> 341220000 | V30: RF Switch | AE30: 4G & 5G
B31: 27 | C31: USB RF SPDT Switch Matrix | D31: 1 | E31: 0 | F31: 0 | G31: 0 | H31: 1 | I31: 0 | Q31: USB-2SP2T-DCH | S31: =H31 -> 1 | T31: 68244000 | U31: =S31*T31 -> 68244000 | V31: RF Switch | AE31: 4G & 5G
B32: 28 | C32: UE Emulator | Q32: TM500- VIAVI | R32: VIAVI | S32: 1 | T32: 3.5563158e+10 | U32: =S32*T32 -> 3.5563158e+10 | V32: ? | W32: XAir3 5G Radio Head - Keysight | X32: Keysight | AE32: 4G & 5G
B33: 29 | C33: Core Emulator | Q33: Polaris | R33: Polaris | S33: 1 | T33: 3.9977895e+09 | U33: =S33*T33 -> 3.9977895e+09 | V33: ? | W33: EPC-Sim: X100-5G | X33: Keysight | AE33: 4G & 5G
B34: 30 | C34: Mỏ hàn | D34: 5 | E34: 0 | F34: 0 | G34: 0 | H34: 5 | I34: 0 | U34: =S34*T34 -> 0 | AE34: 4G & 5G
B35: 31 | C35: Máy khò | D35: 5 | E35: 0 | F35: 0 | G35: 0 | H35: 5 | I35: 0 | U35: =S35*T35 -> 0 | AE35: 4G & 5G
B36: 32 | C36: Máy hút thiếc | D36: 5 | E36: 0 | F36: 0 | G36: 0 | H36: 5 | I36: 0 | U36: =S36*T36 -> 0 | AE36: 4G & 5G
B37: 33 | C37: Nguồn AC | D37: 2 | E37: 0 | F37: 0 | G37: 0 | H37: 2 | I37: 0 | Q37: AC6804B Basic AC Power Source, 4000 VA, 310 V, 20 A | R37: Keysight | S37: =H37 -> 2 | T37: 608532500 | U37: =S37*T37 -> 1217065000 | AE37: 4G & 5G
B38: 34 | C38: Nguồn DC | D38: 3 | E38: 3 | F38: 0 | G38: 3 | H38: 9 | I38: 0 | Q38: N5767A DC Power Supply, 60V, 25A, 1500W | R38: Keysight | S38: =H38 -> 9 | T38: 141517000 | U38: =S38*T38 -> 1273653000 | AE38: 4G & 5G
B39: 35 | C39: Máy đo tỷ số sóng đứng | D39: 1 | E39: 0 | F39: 0 | G39: 0 | H39: 1 | I39: 0 | Q39: N9950A FieldFox Handheld Microwave Analyzer, 32 GHz | R39: Keysight | S39: =H39 -> 1 | T39: 2231419000 | U39: =S39*T39 -> 2231419000 | AE39: 4G & 5G
B40: 36 | C40: Tải cao tần | D40: 50 | E40: 0 | F40: 0 | G40: 0 | H40: 50 | I40: 0 | Q40: PE6835 300 Watts High Power WR-112 Waveguide Load 7.05 GHz to 10 GHz | R40: Keysight | S40: =H40 -> 50 | T40: 134302500 | U40: =S40*T40 -> 6715125000 | AE40: 4G & 5G
B41: 37 | C41: Đồng hồ vạn năng | D41: 5 | E41: 0 | F41: 0 | G41: 0 | H41: 5 | I41: 0 | Q41: U1242C Handheld Digital Multimeter, 4 Digit, IP67 | R41: Keysight | S41: =H41 -> 5 | T41: 13136500 | U41: =S41*T41 -> 65682500 | AE41: 4G & 5G
...

Sheet Quotation_Keysight
D1: Báo giá
D2: Số báo giá: | F2: Hiệu lực báo giá:
D3: 43633 | F3: 43693
D4: Ngày báo giá: | E4: 43633
A6: Tên và địa chỉ khách hàng: | D6: Quản lý bán hàng:
A7: TỔNG CÔNG TY CÔNG NGHIỆP CÔNG NGHỆ CAO VIETTEL | D7: Nguyễn Anh Quân
D8: Tel/Fax: +84 974 731286
A9: Tel: | D9: Email: quan.nguyen@asic.vn
A11: Nếu quí khách có yêu cầu/ký hợp đồng đề nghị liên lạc: | D11: CÔNG TY CỔ PHẦN TƯ VẤN VÀ DỊCH VỤ CÔNG NGHỆ ASIC
A12: Trung tâm chăm sóc khách hàng: | D12: Địa chỉ: Phòng 1701 - G3, Vinhomes Green Bay, P. Mễ Trì, Q. Nam Từ Liêm, Hà Nội, Việt Nam
A13: Tel: 024 3748 1504
A14: Cảm ơn Quí khách hàng đã quan tâm đến các sản phẩm mà chúng tôi cung cấp. Thay mặt công ty, chúng tôi xin gửi đến Quí khách hàng bản chào giá sản phẩm như sau:
A16: STT | B16: Mã hiệu | C16: Mô tả sản phẩm | D16: Hãng sản xuất | E16: Đơn giá (VND) | F16: Số lượng | G16: Thành Tiền (VND)
A17: 1 | B17: N9020A Signal Analyzer - Upgrade | D17: Keysight | E17: 988974000 | F17: 1 | G17: 988974000
C18: Tùy chọn nâng cấp:
B19: N9085EM0E | C19: 5G NR Measurement Application | H19: update FW
B20: R-Y5C-001-A | C20: Node-locked perpetual license
B21: R-Y6C-001-L | C21: KeysightCare software support subscription, node-locked - 12 months
A22: 2 | B22: RX MIMO (Software update only, hardware is not updatable) | D22: Keysight | E22: 8742963500 | F22: 1 | G22: 8742963500
C23: VSA Software update
B24: 89601B-BHN | C24: 5G NR/Pre-5G modulation analysis, transportable perpetual license | H24: Phân tích tín hiệu điều chế 5G
B25: 89601BU-012 | C25: 12 month update subscription service, transportable perpetual license | H25: Dịch vụ update trong 12 tháng (trong 1 năm tiêu chuẩn update như nào thì hãng sẽ update tiếp)
C26: SystemVue upgrade
B27: W1465BP | C27: SystemVue System Architect Perpetual bundle license (Node-locked) | H27: Update phần mềm
B28: R-35B-001-A | C28: Node-locked license | H28: Update phần mềm
B29: R-36B-001-L | C29: 12 months upgrades and support - node-locked | H29: Update phần mềm
B30: W1918EP | C30: LTE-A Baseband Verification Library License (Node-locked) | H30: Update phần mềm thư viện Baseband
B31: R-35B-001-A | C31: Node-locked license | H31: Update phần mềm
B32: R-36B-001-L | C32: 12 months upgrades and support - node-locked | H32: Update phần mềm
B33: W1715EP | C33: MIMO Channel Builder License (Node-locked) | H33: Update phần mềm mô hình hóa kênh truyền dẫn đa đường
B34: R-35B-001-A | C34: Node-locked license | H34: Update phần mềm
B35: R-36B-001-L | C35: 12 months upgrades and support - node-locked | H35: Update phần mềm
B36: W1716EP | C36: DPD Builder License (Node-locked) | H36: Update phần mềm (Digital pre Distotion-méo trước)
B37: R-35B-001-A | C37: Node-locked license | H37: Update phần mềm
B38: R-36B-001-L | C38: 12 months upgrades and support - node-locked | H38: Update phần mềm
B39: W1916EP | C39: 3G Baseband Verification Library License (Node-locked) | H39: Update phần mềm ()
B40: R-35B-001-A | C40: Node-locked license
B41: R-36B-001-L | C41: 12 months upgrades and support - node-locked
C42: System Vue 5G library with 1 year support
B43: W1906EP | C43: 5G Baseband Verification Library for SystemVue element software license R-35B-001-A Node-locked license
...

Sheet Quotation_R&S conducted
A1: 1 | B1: CHAPTER 6 - Sub 6 GHz
A2: TT | B2: Loại máy | C2: Model | D2: Số lượng | E2: Đơn giá | H2: Tổng giá | I2: Hạng mục | J2: Ghi chú | K2: Cấu hình
A3: 1 | B3: Máy phân tích tín hiệu VSA, mỗi máy gồm: | C3: FSW8 | D3: 1 | F3: =SUM(F4:F11) -> 157000 | H3: =F3*D3 -> 157000 | I3: Mua mới | J3: Máy FSW8 tới 8 GHz, vẫn cần dùng máy FSV13 tới 13 GHz để thực hiện bài đo Spurious Emisson (yêu cầu tới 12.75 GHz) --> tận dụng máy FSV13 có sẵn, máy FSW13 đắt tiền hơn | K3: 1 x FSW8 Signal- and Spectrum Analyzer 2 Hz to 8 GHz 1 x FSW-K144 3GPP 5G-NR DL Measurements (SL) 1 x FSW-K544 User defined frequency response correction by SnP file (SL) 1 x FSW-B4 OCXO, precision frequency reference (hw opt.) 1 x FSW-B24 RF preamplifier, 30dB, 100kHz to 8GHz (hw opt.) 1 x FSW-B25 Electronic attenuator, 8GHz, 1dB steps (hw opt.) 1 x FSW-B160 Extension to 160 MHz signal analysis bandwidth (HW opt.)
B4: Signal- and Spectrum Analyzer 2 Hz to 8 GHz | C4: FSW8 | D4: 1 | E4: 76709 | F4: =E4*D4 -> 76709
B5: 3GPP 5G-NR DL Measurements (SL) | C5: FSW-K144 | D5: 1 | E5: 12526 | F5: =E5*D5 -> 12526
B6: User defined frequency response correction by SnP file (SL) | C6: FSW-K544 | D6: 1 | E6: 7035 | F6: =E6*D6 -> 7035
B7: Documentation of calibration values | C7: DCV-2 | D7: 1 | E7: 500 | F7: =E7*D7 -> 500
B8: OCXO, precision frequency reference (hw opt.) | C8: FSW-B4 | D8: 1 | E8: 5005 | F8: =E8*D8 -> 5005
B9: RF preamplifier, 30dB, 100kHz to 8/13GHz (hw opt.) | C9: FSW-B24 | D9: 1 | E9: 7736 | F9: =E9*D9 -> 7736
B10: Electronic attenuator, 13.6GHz, 1dB steps (hw opt.) | C10: FSW-B25 | D10: 1 | E10: 6420 | F10: =E10*D10 -> 6420
B11: Extension to 160 MHz signal analysis bandwidth (HW opt.) | C11: FSW-B160 | D11: 1 | E11: 41069 | F11: =E11*D11 -> 41069
C12: FSV13 | D12: 1 | F12: 39200 | H12: =F12*D12 -> 39200 | I12: Nâng cấp FSV13 hiện có | J12: Giới hạn tính năng: không đo được đầy đủ hết bộ chỉ tiêu | K12: 1x FSV-K144 3GPP 5G-NR DL Measurements (SL) 1 x Extension to 160MHz signal analysis bandwidth (HW opt.) Calibration in Singapore after hardware changed
A13: 1 (Tùy chọn thay thế) | B13: Máy phân tích tín hiệu VSA, mỗi máy gồm: | C13: FSW13 | D13: 1 | F13: =SUM(F14:F21) -> 164146 | H13: =F13*D13 -> 164146 | I13: Mua mới | J13: Sử dụng FSW13 là đủ, không cần thêm FSV13
B14: Signal- and Spectrum Analyzer 2 Hz to 13.6 GHz | C14: FSW13 | D14: 1 | E14: 83855 | F14: =E14*D14 -> 83855
B15: 3GPP 5G-NR DL Measurements (SL) | C15: FSW-K144 | D15: 1 | E15: 12526 | F15: =E15*D15 -> 12526
B16: User defined frequency response correction by SnP file (SL) | C16: FSW-K544 | D16: 1 | E16: 7035 | F16: =E16*D16 -> 7035
B17: Documentation of calibration values | C17: DCV-2 | D17: 1 | E17: 500 | F17: =E17*D17 -> 500
B18: OCXO, precision frequency reference (hw opt.) | C18: FSW-B4 | D18: 1 | E18: 5005 | F18: =E18*D18 -> 5005
B19: RF preamplifier, 30dB, 100kHz to 8/13GHz (hw opt.) | C19: FSW-B24 | D19: 1 | E19: 7736 | F19: =E19*D19 -> 7736
B20: Electronic attenuator, 13.6GHz, 1dB steps (hw opt.) | C20: FSW-B25 | D20: 1 | E20: 6420 | F20: =E20*D20 -> 6420
B21: Extension to 160 MHz signal analysis bandwidth (HW opt.) | C21: FSW-B160 | D21: 1 | E21: 41069 | F21: =E21*D21 -> 41069
A23: 2 | B23: Nguồn DC | I23: Đã có đủ cho 5G
A24: 3 | B24: Máy phát tín hiệu, mỗi máy gồm: | C24: SMW200A | D24: 1 | F24: =SUM(F25:F29) -> 84100 | H24: =F24*D24 -> 84100 | I24: Mua mới | J24: Tạo tín hiệu 5G cho bài đo Intermodulation | K24: 1 x SMW200A Vector signal generator, base unit; freq.opt.& BBmodule req. 1 x SMW-B107 Frequency range: 100 kHz to 7. 5 GHz, RF path A (HW opt.) 1 x SMW-B13 Baseband main module, one I/Q path to RF section (HW opt.) 1 x SMW-B10 Baseband generator with realtime coder and ARB (HW opt.) 1 x SMW-K144 5G New Radio (SL)
B25: Vector signal generator, base unit; freq.opt.& BBmodule req. | C25: SMW200A | D25: 1 | E25: 5020 | F25: =E25*D25 -> 5020
B26: Frequency range: 100 kHz to 7. 5 GHz, RF path A (HW opt.) | C26: SMW-B107 | D26: 1 | E26: 47133 | F26: =E26*D26 -> 47133
B27: Baseband main module, one I/Q path to RF section (HW opt.) | C27: SMW-B13 | D27: 1 | E27: 2503 | F27: =E27*D27 -> 2503
B28: Baseband generator with realtime coder and ARB (HW opt.) | C28: SMW-B10 | D28: 1 | E28: 13385 | F28: =E28*D28 -> 13385
B29: 5G New Radio (SL) | C29: SMW-K144 | D29: 1 | E29: 16059 | F29: =E29*D29 -> 16059
A30: 4 | B30: Suy hao | C30: PE7213-30 | D30: 1 | F30: =1.1*752 -> 827.2 | H30: =F30*D30 -> 827.2 | I30: Mua mới | J30: https://www.pasternack.com/30db-fixed-n-male-n-female-100-watts-attenuator-pe7213-30-p.aspx | K30: 30 dB Fixed Attenuator, N Male To N Female Directional Black Anodized Aluminum Heatsink Body Rated To 100 Watts Up To 6 GHz
A31: 5 | B31: Connector TMA-A Plug to SMA Femal | J31: Không có thông tin về loại cáp này
A32: 6 | B32: Cable SMA Male To N Male 12 inch | C32: PE354-12 | D32: 1 | F32: =1.1*161 -> 177.1 | H32: =F32*D32 -> 177.1 | I32: Mua mới | J32: https://www.pasternack.com/sma-male-n-male-pe-p141-cable-assembly-pe354-12-p.aspx | K32: SMA Male to N Male Cable 12 Inch Length Using PE-P141 Coax with HeatShrink, LF Solder, RoHS
A33: 7 | B33: Cable SMA Male To N Male 24 inch | C33: PE354-24 | D33: 1 | F33: =1.1*172 -> 189.2 | H33: =F33*D33 -> 189.2 | I33: Mua mới | J33: https://www.pasternack.com/sma-male-n-male-pe-p141-cable-assembly-pe354-24-p.aspx | K33: SMA Male to N Male Cable 24 Inch Length Using PE-P141 Coax with HeatShrink, LF Solder, RoHS
A34: 8 | B34: Notch Filter | C34: Notch Filter DL Band n78 (3300-3800) | D34: 5 | F34: =1.1*2090 -> 2299 | H34: =F34*D34 -> 11495 | I34: Mua mới | J34: Cần xác định rõ dải tần, band và băng thông đo để mua bộ Notch Filter phù hợp. Không có 1 bộ cho full band | K34: TUNABLE BAND REJECT / NOTCH FILTERS FOR 5G NR DL BAND N78 (3300-3800 MHZ) Tuning Range 3000 to 4000 MHz Slopes 7 MHz Bandwidth 10 MHz Attenuation 40 dB min.
A35: 9 | B35: Switch RF | C35: ZTVX-16-18-s | D35: 3 | F35: =1.1*17000 -> 18700 | H35: =F35*D35 -> 56100 | I35: Mua mới | K35: 2 by 16 Switch Matrix, 50Ω, USB and Ethernet-TCP/IP control interface, Windows environments Software support
A36: 10 | B36: Jig cơ khí
A37: 11 | B37: Hybrid combiner | C37: ZFRSC-4-842-S+ | D37: 1 | F37: =1.1*170 -> 187 | H37: =F37*D37 -> 187 | I37: Mua mới | K37: 4-way Connectorized Power Splitter, DC-8400MHz
A38: 12 | B38: Circulator | C38: PE83CR1004 | D38: 1 | F38: =1.1*651 -> 716.1 | H38: =F38*D38 -> 716.1 | I38: Mua mới | K38: High Power Circulator With 20 dB Isolation From 2 GHz to 4 GHz, 50 Watts And SMA Female
C39: PE83CR1000 | D39: 1 | F39: =1.1*1155 -> 1270.5 | H39: =F39*D39 -> 1270.5 | I39: Mua mới | J39: https://www.pasternack.com/high-power-circulator-18db-isolation-2-ghz-50-watts-sma-female-pe83cr1000-p.aspx | K39: High Power Circulator with 18 dB Isolation from 1 GHz to 2 GHz, 50 Watts and SMA Female
A41: 2 | B41: CHAPTER 7
A42: TT | B42: Loại máy | C42: Model | D42: Số lượng | E42: Đơn giá | H42: Tổng giá | I42: Hạng mục | J42: Ghi chú | K42: Cấu hình
...

Sheet Quotation_OTA
A2: TT | B2: Loại máy | C2: Model | D2: Số lượng | E2: Đơn giá | F2: Tổng giá | G2: Hạng mục | H2: Ghi chú | I2: Cấu hình
A3: 1 | B3: Calibration of multiple active antenna modules (beamforming applications in sub-6 GHz frequency range)
B4: Power Sensor | C4: NRQ6 | D4: 8 | E4: 29530 | F4: 236240 | G4: Mua mới | H4: Dùng để cân chỉnh pha của anten mảng (antenna array) - Dải tần dưới 6 GHz | I4: 1 x NRQ6 Freq. sel. power sensor;50MHz to 6GHz;-130 to +20dBm;N(m) 1 x NRQ6-K1 IQ-DATA INTERFACE (SL) 1 x NRQ6-K3 Phase coherent measurements (SL) 1 x NRP-ZAP1 8-port GbE switch, 4 ports GbE PoE+, 4 ports GbE
A5: 2 | B5: OTA power measurement ( TX beamforming verification - mmWave)
B6: Power sensor | C6: NRPM | D6: 3 | E6: 27206 | F6: =E6*D6 -> 81618 | G6: Mua mới | H6: Đo công suất qua vô tuyến, để kiểm tra việc điều khiển beamforming. Dải tần mmWave > 18 GHz | I6: 3 x NRPM-A90 Antenna mod.; single polarized; OTA power meas.; 18-90 GHz 1 x NRPM-Z3 OTA 3-channel interface module; for OTA power measurement 1 x NRPM3 Sensor module for OTA power measurements 1 x NRP-ZKU USB cable(5.0m) for NRPxxS/T/A/SN/TN/AN;for Laptop/PC;(acc.)
H7: Cần thêm chamber
A8: 3 | B8: OTA Antenna measurement | H8: Chamber + test system Dải tần dưới 6 GHz
A9: 1 | B9: R6 CATR Measurement System | D9: 1 | E9: 1950000 | H9: Đo antenna của trạm gốc 5G, đường kính tối đa 0.9m
A10: 1.1 | B10: Anechoic Chamber - Dimension: 6.2 X 3.15 X 3.15m (L/W/H) - Shielding effective: 1 - 18GHz >100dB - Absorber walkway: 5 set - Honeycomb vent: 4 set - Shielding door: Swinging auto-Launching - Shielding door dimension: 1.0 X 2.0m (W/H) - Power filter: 220VAC, 16A, - Positioner cameras: 1 set - Cross laser marker: 1 set - Lighting: LED, 2 set - Meets CNS-14705S - Steel sheet: Modular steel pan type shielded enclosure by 2mm galvanized - Absorber
A11: 1.2 | B11: CATR Antenna System - Reflector Size: 2.0 X 2.0m (W/H) - Reflector Edge: Rolled edge - Feed antenna location: Corner feed - Quiet zone size: 0.9m - Quiet zone shape: Circular cylinder - Frequency range: 6 - 100GHz - Cross polarization: -30dB - Amplitude taper: 1dB - Amplitude ripple: ±0.5dB - Amplitude variation: 2.1dB - Phase taper: ±4degree @6 - 40GHz - Phase ripple: ±5 degree @6 - 40GHz - Dynamic Range: 70dB @6 - 40GHz - Clutter image: -35dBc - Fixture for reflector: Adjustable - Material: Aluminum - F/D: 1.5
A12: 1.3 | B12: RF Circuit -RF cable up to 40GHz -SMA rotary joint up to 40GHz, 2 set -RF path: passive only -Feed horn for 2.6 - 3.95GHz(S band) -Feed horn for 8.2 - 12.4GHz(X band) -Feed horn for 26.5 - 40GHz(Ka band) -Standard gain horn for 2.6 - 3.95GHz(S band) -Standard gain horn for 8.2 - 12.4GHz(X band) -Standard gain horn for 26.5 - 40GHz(Ka band) -Low noise amplifier: 1 to 40GHz, Gain 20dB, NF 4.5dB
A13: 1.4 | B13: System Controller & Miscellaneous -Control unit: Adventech IPC -CPU: Intel -OS: Win7 English -MS Excel included -GPIB PCI card included -3 axis DUT positioner: Roll/ Z / Azimuth -Loading: 100 kg @30 cm depth -Roll axis: Accuracy 0.1° for 0°-360°, max speed 20°/sec -Z axis: Travel length 0~600 mm -Azimuth axis: Accuracy 0.1° for 0°-360°, max speed 12° /sec -Fixture for feed antenna: Z axis Adjustable, manually operation -Fixture for standard gain horn
A14: 1.5 | B14: Test equipment
B15: OSP130 OSP Open Switch and Control Unit
B16: FSW8 Signal- and Spectrum analyzer 2Hz to 8GHz
B17: SMW200A Vector signal generator Frequency range : 100kHz to 6GHz
B18: ZVA8 Vector network analyzer, 2 ports, 300 kHz - 8 GHz
A19: 1.6 | B19: OTA Software -2D/3D antenna pattern measurement -Viewer software license
A20: 1.7 | B20: Calibration and Acceptance -Amplitude Testing Amplitude ripple: ± 0.5dB @ 3 - 40GHz Amplitude taper: 1dB @ 3 - 40GHz Cross polarization: -28dB Test frequency depend on purchased feed horn's middle frequency Scanning along XY plane at Z =0 -Phase Testing Phase ripple: ± 5 degree @ 3 - 40GHz Phase taper: ± 5 degree @ 3 - 40GHz Test frequency depend on purchased feed horn's middle frequency Scanning along XY plane at Z =0 -Passive Path LossAccording purchased feed and standard gain horn antenna -Passive check: Performing 1 rounds antenna pattern test with standard gain horn to make sure the OTA system works

Sheet Quotation_R&S ZNBT8
A2: TT | B2: Loại máy | C2: Model | D2: Số lượng | E2: Đơn giá | F2: Tổng giá | G2: Hạng mục | H2: Ghi chú | I2: Cấu hình
A3: 1 | B3: Máy phân tích mạng 8 cổng | C3: ZNBT8 | D3: 1 | E3: 137800 | F3: =E3*D3 -> 137800 | G3: Mua mới | H3: Đo dẫn các phần tử anten của anten mảng pha 5G | I3: 1 x ZNBT8 Vector Network Analyzer, 4(24max)ports, 9kHz - 8.5GHz, N(f) 1 x ZNBT-T81 4 DC inputs, 3 voltage ranges 1 x ZNBT8-B108 Adds ports 5 to 8 (HW opt.) 1 x ZNBT8-B504 Extended Dynamic Range R&S®ZNBT8, P 1-4 1 x ZNBT-K2 Time domain analysis (SL) 1 x ZNBT-K20 Extended Time Domain Analysis for R&S®ZNBT (SL) 8 x ZV-Z191 RF cable 50 Ohm; N(m) to N(m); DC-18GHz,910mm(36 inch)(acc.) 1 x ZN-Z51 Calibration unit 50 Ohm,100kHz-8.5GHz,4 ports, N(f) (acc.)

Sheet So cu 5G team
A1: STT | B1: Trang thiết bị | G1: Số lượng hiện có | H1: Số lượng cần đáp ứng (1) | I1: Số lượng đảm bảo đo 5G (2) | J1: Danh mục đầu tư (3) = (1) - (2) | N1: Giá (1 TB) | O1: Thành tiền | P1: Tính năng | Q1: Phục vụ đề tài
C2: Số lượng cần | J2: Nâng cấp | L2: Mua mới
C3: HW | D3: FPGA | E3: L1 | F3: QA | J3: Tên máy | K3: Số lượng | L3: Tên máy | M3: Số lượng | S3: Chương 6 | T3: Chương 7 | U3: Chương 8
A4: 1 | B4: Máy phân tích tín hiệu VSA | C4: 1 | D4: 1 | F4: 1 | G4: 3 | H4: =SUM(C4:F7) -> 3 | I4: 0 | J4: N9020A | K4: 1 | N4: 65,000 $ | O4: 65,000 $ | P4: + HW upgrade_N9020AK-MTP_Multi-touch User Interface + FW_upgrade_N9085EM0E_Ứng dụng đo kiểm 5G NR + Support: R-Y5C-001-A, R-Y5C-001-L : 12 tháng hỗ trợ | Q4: 4G & 5G | S4: #NAME? | T4: #NAME?
J5: FSV13 | K5: 1 | N5: Liên hệ | O5: Liên hệ | P5: + FSV-K144/VSE-K144: Đo kiểm 5G NR + FSV-B160 (HW) : Nâng cấp băng thông 160 MHz + Chỉ tiêu Transmit ON/OFF Power: Cần thêm thông tin từ hãng | Q5: 4G & 5G
J6: MIMO | K6: 1 | N6: Liên hệ | O6: Liên hệ | P6: + Nâng cấp bộ thư viện 5G cho SystemVue + VSA + Nâng cấp MIMO 4x4 + Phục vụ quá trình R&D, chưa đo full được các chỉ tiêu chương 6,7 (SEM, Spurious Emissions,…) | Q6: 4G & 5G
L7: FSW8 (nếu FSV13 không đáp ứng được) | M7: (1) | N7: 157000 | O7: 157000 | P7: + FSW-K144: Đo kiểm 3gpp 5G NR + FSW-K544: Điều chỉnh đáp ứng tập lệnh tần số SnP file + FSW-B4: (HW option) Tham chiếu tần số chính xác + FSW-B24: (HW option) Pre-Amplifier 30dB, 100kHz to 8/13GHz + FSW-B25: (HW option) Electronic attenuator, 13.6GHz, 1dB steps + FSW-B160: (HW option) Mở rộng Bandwidth 160 MHz | Q7: 4G & 5G
A8: 2 | B8: Máy phát tín hiệu VSG | C8: 2 | D8: 2 | E8: 1 | F8: 2 | G8: 7 | H8: 7 | I8: 0 | J8: SMW 200A | K8: 1 | N8: 338,447 $ | O8: 338,447 $ | P8: + FW_upgrade_SMW-K144 Tạo tín hiệu 5G NR R.15 (45,280 €) + HW_upgrade_SMW-B9 Băng thông RF 500 MHz (72,700 €) + HW_upgrade_SMW-B13XT Phần cứng hỗ trợ cho SMW-B9 (7,560 €) + FW_upgrade_SMW-B15 Mô phỏng Fading và Signal Processor + FW_upgrade_SMW-K145 Tạo close loop cho tín hiệu 5G + SW_upgrade: SMW-K19 (software license) + Hiệu chuẩn: Hiệu chuẩn tại Singapore (2,500 €) | Q8: 4G & 5G | S8: #NAME? | T8: #NAME?
J9: MIMO | K9: 1 | N9: Liên hệ | O9: Liên hệ | P9: + Nâng cấp bộ thư viện 5G cho SystemVue + VSA + Nâng cấp MIMO 4x4 + Phục vụ quá trình R&D, chưa đo full được các chỉ tiêu chương 6,7 (SEM, Spurious Emissions,…) | Q9: 4G & 5G
J10: N5182B VSG | K10: 5 | N10: 62,500 $ | O10: 312,500$ | P10: + License key: N5182BU_657 Tạo tín hiệu RF 160 MHz + License key: N5182BU_656 ARB baseband generator (80MHz RF bandwidth, 32 MSa) + PC Application license: N7631 APPC Signal Studio Pro for 5G NR 2019 + Support: R-Y5C-001-A, R-Y5C-001-L : 12 tháng hỗ trợ | Q10: 4G & 5G
A11: 3 | B11: Nguồn phát cao tần | C11: 0 | D11: 0 | E11: 6 | F11: 0 | G11: 2 | H11: 6 | I11: 2 | L11: SGT100A | M11: 4 | N11: 34,031.142 $ | O11: 136,124.568 $ | P11: + Tạo tín hiệu RF: SGMA Vector RF Source, 3 GHz RF and baseband HW included + Mở rộng tần số: 6GHz (SL) + Tín hiệu tham chiếu: Reference oscillator OCXO (HW opt) + Digital baseband connectivity (SL) | Q11: 4G & 5G | S11: #NAME? | T11: #NAME?
A12: 4 | B12: Nguồn DC | C12: 1 | D12: 1 | E12: 1 | F12: 1 | G12: 3 | H12: 4 | I12: 3 | L12: GW Instek PSU60 | M12: 1 | N12: 1,995 $ | O12: 1,995 $ | P12: GW Instek PSU60 - 25: 60V, 25A, 1500W | Q12: 4G & 5G | S12: #NAME? | T12: #NAME?
A13: 5 | B13: Connector TMA-A Plug to SMA Femal | C13: 16 | D13: 16 | E13: 8 | F13: 16 | G13: 0 | H13: 56 | I13: 0 | L13: Liên hệ | M13: 56 | N13: Liên hệ | O13: Liên hệ | P13: Cable TMA-A Plug to N type Femal | Q13: 5G | S13: #NAME? | T13: #NAME?
A14: 6 | B14: Cable SMA Male To N Male 12 inch | C14: 16 | D14: 16 | E14: 8 | F14: 16 | G14: 0 | H14: 56 | I14: 0 | L14: PE354-12 | M14: 56 | N14: 152.81 $ | O14: 8557.36 $ | P14: 18 Ghz 12 Inch Length (30 cm) | Q14: 4G & 5G | S14: #NAME? | T14: #NAME?
A15: 7 | B15: Suy hao | C15: 16 | D15: 16 | E15: 8 | F15: 16 | G15: 0 | H15: 56 | I15: 0 | L15: PE7213-30 | M15: 56 | N15: 676.29 $ | O15: 37872.24 $ | P15: 30dB 100W 6GHz Attenuator N type | Q15: 4G & 5G | S15: #NAME? | T15: #NAME?
A16: 8 | B16: Cable SMA Male To N Male 24 inch | C16: 18 | D16: 18 | E16: 9 | F16: 18 | G16: 0 | H16: 63 | I16: 0 | L16: PE354-24 | M16: 63 | N16: 163.18 $ | O16: 10280.34 $ | P16: 18 Ghz 24 Inch Length (60 cm) | Q16: 4G & 5G | S16: #NAME? | T16: #NAME?
A17: 9 | B17: Switch RF | C17: 2 | D17: 2 | E17: 0 | F17: 2 | G17: 0 | H17: 6 | I17: 0 | L17: ZTVX-16-18 | M17: 6 | N17: Liên hệ | O17: Liên hệ | P17: 2 by 16 Switch Matrix, 50Ω, USB and Ethernet-TCP/IP control interface, Windows environments Software support | Q17: 4G & 5G | S17: #NAME? | T17: #NAME?
A18: 10 | B18: Giá đỡ hỗ trợ đo kiểm | C18: 2 | D18: 2 | E18: 1 | F18: 2 | G18: 0 | H18: 7 | I18: 0 | L18: Tự làm | M18: 7 | N18: Liên hệ | O18: Liên hệ | P18: Hỗ trợ di chuyển, gắn suy hao, có thể mở rộng lên 32T32R, … | Q18: 5G | S18: #NAME? | T18: #NAME?
A19: 11 | B19: Cable SMA Male To SMA Male 24 inch | C19: 1 | D19: 1 | E19: 1 | F19: 1 | G19: 0 | H19: 4 | I19: 0 | L19: PE300-24 | M19: 4 | N19: 124.83 $ | O19: 499.32 $ | P19: 24 Inch Length; 0.6M; PE300-24 | Q19: 4G & 5G | S19: #NAME? | T19: #NAME?
A20: 12 | B20: Power Combiner | C20: 1 | D20: 1 | E20: 0 | F20: 1 | G20: 0 | H20: 3 | I20: 0 | L20: Liên hệ | M20: 3 | N20: Liên hệ | O20: Liên hệ | P20: Power Combiner | Q20: 5G | S20: #NAME? | T20: #NAME?
A21: 13 | B21: Notch Filter | C21: 2 | D21: 2 | E21: 0 | F21: 2 | G21: 0 | H21: 6 | I21: 0 | L21: Liên hệ | M21: 6 | N21: Liên hệ | O21: Liên hệ | P21: Notch Filter | Q21: 5G | S21: #NAME? | T21: #NAME?
A22: 14 | B22: Cable trigger BNC To SMA | C22: 0 | D22: 0 | E22: 1 | F22: 0 | G22: 0 | H22: 1 | I22: 0 | L22: Liên hệ | M22: 1 | N22: Liên hệ | O22: Liên hệ | Q22: 4G & 5G | S22: #NAME? | T22: #NAME?
A23: 15 | B23: Vivaldi antenna | C23: 1 | D23: 0 | E23: 0 | F23: 0 | G23: 0 | H23: 1 | I23: 0 | L23: NRPM-A90/A90D | M23: 1 | N23: Liên hệ | O23: Liên hệ | Q23: 5G | S23: #NAME? | T23: #NAME?
L24: NRPM-ZD3 | M24: 1 | N24: Liên hệ | O24: Liên hệ | Q24: 5G | S24: #NAME? | T24: #NAME?
L25: NRPM3 | M25: 1 | N25: Liên hệ | O25: Liên hệ | Q25: 5G | S25: #NAME? | T25: #NAME?
L26: NRPM-ZDK3 | M26: 1 | N26: Liên hệ | O26: Liên hệ | Q26: 5G | S26: #NAME? | T26: #NAME?
A27: 16 | B27: Buồng câm | C27: 1 | D27: 0 | E27: 0 | F27: 0 | G27: 0 | H27: 1 | I27: 0 | L27: Chamber | M27: 1 | N27: Liên hệ | O27: Liên hệ | Q27: 5G | S27: #NAME? | T27: #NAME?
A28: 17 | B28: Máy đo công suất | C28: 3 | D28: 0 | E28: 0 | F28: 0 | G28: 0 | H28: 3 | I28: 0 | L28: PWR-6LGHS | M28: 1 | N28: Liên hệ | O28: Liên hệ | P28: USB Power Sensor, -45dBm to +10dBm, 50MHz to 6GHz | Q28: 5G | S28: #NAME? | T28: #NAME?
L29: PWR-6GHS | M29: 2 | N29: Liên hệ | O29: Liên hệ | P29: USB Power Sensor, -30dBm to +20dBm, 1MHz to 6GHz | Q29: 5G | S29: #NAME? | T29: #NAME?
A30: 18 | B30: High Power Directional Coupler, 35dB | C30: 1 | D30: 0 | E30: 0 | F30: 0 | G30: 0 | H30: 1 | I30: 0 | L30: ZGDC35-93HP+ | M30: 1 | N30: Liên hệ | O30: Liên hệ | P30: Coupler 35dB | Q30: 4G & 5G | S30: #NAME? | T30: #NAME?
A31: 19 | B31: High Power Bi-Directional Coupler, 16dB | C31: 1 | D31: 0 | E31: 0 | F31: 0 | G31: 0 | H31: 1 | I31: 0 | L31: ZFBDC16-63HP+ | M31: 1 | N31: Liên hệ | O31: Liên hệ | P31: Coupler 16 dB | Q31: 4G & 5G | S31: #NAME? | T31: #NAME?
A32: 20 | B32: USB SP4T Switch | C32: 5 | D32: 0 | E32: 0 | F32: 0 | G32: 0 | H32: 5 | I32: 0 | L32: USB-SP4T-63 | M32: 5 | N32: Liên hệ | O32: Liên hệ | P32: RF Switch | Q32: 4G & 5G | S32: #NAME? | T32: #NAME?
A33: 21 | B33: USB RF SPDT Switch Matrix | C33: 1 | D33: 0 | E33: 0 | F33: 0 | G33: 0 | H33: 1 | I33: 0 | L33: USB-2SP2T-DCH | M33: 1 | N33: Liên hệ | O33: Liên hệ | P33: RF Switch | Q33: 4G & 5G | S33: #NAME? | T33: #NAME?
A34: 22 | B34: Mỏ hàn | C34: 5 | D34: 0 | E34: 0 | F34: 0 | G34: 0 | H34: 5 | I34: 0 | L34: Liên hệ | M34: 5 | N34: Liên hệ | O34: Liên hệ | Q34: 4G & 5G | S34: #NAME? | T34: #NAME?
A35: 23 | B35: Máy khò | C35: 5 | D35: 0 | E35: 0 | F35: 0 | G35: 0 | H35: 5 | I35: 0 | L35: Liên hệ | M35: 5 | N35: Liên hệ | O35: Liên hệ | Q35: 4G & 5G | S35: #NAME? | T35: #NAME?
A36: 24 | B36: Máy hút thiếc | C36: 5 | D36: 0 | E36: 0 | F36: 0 | G36: 0 | H36: 5 | I36: 0 | L36: Liên hệ | M36: 5 | N36: Liên hệ | O36: Liên hệ | Q36: 4G & 5G | S36: #NAME? | T36: #NAME?
A37: 25 | B37: Nguồn AC | C37: 2 | D37: 0 | E37: 0 | F37: 0 | G37: 0 | H37: 2 | I37: 0 | L37: Liên hệ | M37: 2 | N37: Liên hệ | O37: Liên hệ | Q37: 4G & 5G | S37: #NAME? | T37: #NAME?
A38: 26 | B38: Máy phân tích Logic Analyzer | C38: 1 | D38: 0 | E38: 0 | F38: 0 | G38: 0 | H38: 1 | I38: 0 | L38: Liên hệ | M38: 1 | N38: Liên hệ | O38: Liên hệ | Q38: 4G & 5G | S38: #NAME? | T38: #NAME?
A39: 27 | B39: Máy đo tỷ số sóng đứng | C39: 50 | D39: 0 | E39: 0 | F39: 0 | G39: 0 | H39: 1 | I39: 0 | L39: Liên hệ | M39: 50 | N39: Liên hệ | O39: Liên hệ | Q39: 4G & 5G | S39: #NAME? | T39: #NAME?
A40: 28 | B40: Tải cao tần | C40: 5 | D40: 0 | E40: 0 | F40: 0 | G40: 0 | H40: 50 | I40: 0 | L40: Liên hệ | M40: 5 | N40: Liên hệ | O40: Liên hệ | Q40: 4G & 5G | S40: #NAME? | T40: #NAME?
...

Sheet Sheet1
A1: 1 | B1: CHAPTER 6 - Sub 6 GHz
A2: TT | B2: Loại máy | C2: Model | D2: Số lượng | E2: Đơn giá | G2: Tổng giá | H2: Hạng mục | I2: Ghi chú | J2: Cấu hình
A3: 1 | B3: Máy phân tích tín hiệu VSA, mỗi máy gồm: | C3: FSW8 | D3: 1 | F3: =SUM(F4:F11) -> 157000 | G3: =F3*D3 -> 157000 | H3: Mua mới | I3: Máy FSW8 tới 8 GHz, vẫn cần dùng máy FSV13 tới 13 GHz để thực hiện bài đo Spurious Emisson (yêu cầu tới 12.75 GHz) --> tận dụng máy FSV13 có sẵn, máy FSW13 đắt tiền hơn | J3: 1 x FSW8 Signal- and Spectrum Analyzer 2 Hz to 8 GHz 1 x FSW-K144 3GPP 5G-NR DL Measurements (SL) 1 x FSW-K544 User defined frequency response correction by SnP file (SL) 1 x FSW-B4 OCXO, precision frequency reference (hw opt.) 1 x FSW-B24 RF preamplifier, 30dB, 100kHz to 8GHz (hw opt.) 1 x FSW-B25 Electronic attenuator, 8GHz, 1dB steps (hw opt.) 1 x FSW-B160 Extension to 160 MHz signal analysis bandwidth (HW opt.)
B4: Signal- and Spectrum Analyzer 2 Hz to 8 GHz | C4: FSW8 | D4: 1 | E4: 76709 | F4: =E4*D4 -> 76709
B5: 3GPP 5G-NR DL Measurements (SL) | C5: FSW-K144 | D5: 1 | E5: 12526 | F5: =E5*D5 -> 12526
B6: User defined frequency response correction by SnP file (SL) | C6: FSW-K544 | D6: 1 | E6: 7035 | F6: =E6*D6 -> 7035
B7: Documentation of calibration values | C7: DCV-2 | D7: 1 | E7: 500 | F7: =E7*D7 -> 500
B8: OCXO, precision frequency reference (hw opt.) | C8: FSW-B4 | D8: 1 | E8: 5005 | F8: =E8*D8 -> 5005
B9: RF preamplifier, 30dB, 100kHz to 8/13GHz (hw opt.) | C9: FSW-B24 | D9: 1 | E9: 7736 | F9: =E9*D9 -> 7736
B10: Electronic attenuator, 13.6GHz, 1dB steps (hw opt.) | C10: FSW-B25 | D10: 1 | E10: 6420 | F10: =E10*D10 -> 6420
B11: Extension to 160 MHz signal analysis bandwidth (HW opt.) | C11: FSW-B160 | D11: 1 | E11: 41069 | F11: =E11*D11 -> 41069
C12: FSV13 | D12: 1 | F12: 39200 | G12: =F12*D12 -> 39200 | H12: Nâng cấp FSV13 hiện có | I12: Giới hạn tính năng: không đo được đầy đủ hết bộ chỉ tiêu | J12: 1x FSV-K144 3GPP 5G-NR DL Measurements (SL) 1 x Extension to 160MHz signal analysis bandwidth (HW opt.) Calibration in Singapore after hardware changed
A13: 1 | B13: Máy phân tích tín hiệu VSA, mỗi máy gồm: | C13: FSW13 | D13: 1 | F13: =SUM(F14:F21) -> 164146 | G13: =F13*D13 -> 164146 | H13: Mua mới | I13: Sử dụng FSW13 là đủ, không cần thêm FSV13
B14: Signal- and Spectrum Analyzer 2 Hz to 13.6 GHz | C14: FSW13 | D14: 1 | E14: 83855 | F14: =E14*D14 -> 83855
B15: 3GPP 5G-NR DL Measurements (SL) | C15: FSW-K144 | D15: 1 | E15: 12526 | F15: =E15*D15 -> 12526
B16: User defined frequency response correction by SnP file (SL) | C16: FSW-K544 | D16: 1 | E16: 7035 | F16: =E16*D16 -> 7035
B17: Documentation of calibration values | C17: DCV-2 | D17: 1 | E17: 500 | F17: =E17*D17 -> 500
B18: OCXO, precision frequency reference (hw opt.) | C18: FSW-B4 | D18: 1 | E18: 5005 | F18: =E18*D18 -> 5005
B19: RF preamplifier, 30dB, 100kHz to 8/13GHz (hw opt.) | C19: FSW-B24 | D19: 1 | E19: 7736 | F19: =E19*D19 -> 7736
B20: Electronic attenuator, 13.6GHz, 1dB steps (hw opt.) | C20: FSW-B25 | D20: 1 | E20: 6420 | F20: =E20*D20 -> 6420
B21: Extension to 160 MHz signal analysis bandwidth (HW opt.) | C21: FSW-B160 | D21: 1 | E21: 41069 | F21: =E21*D21 -> 41069
A23: 2 | B23: Nguồn DC | H23: Đã có đủ cho 5G
A24: 3 | B24: Máy phát tín hiệu, mỗi máy gồm: | C24: SMW200A | D24: 1 | F24: =SUM(F25:F29) -> 84100 | G24: =F24*D24 -> 84100 | H24: Mua mới | I24: Tạo tín hiệu 5G cho bài đo Intermodulation | J24: 1 x SMW200A Vector signal generator, base unit; freq.opt.& BBmodule req. 1 x SMW-B107 Frequency range: 100 kHz to 7. 5 GHz, RF path A (HW opt.) 1 x SMW-B13 Baseband main module, one I/Q path to RF section (HW opt.) 1 x SMW-B10 Baseband generator with realtime coder and ARB (HW opt.) 1 x SMW-K144 5G New Radio (SL)
B25: Vector signal generator, base unit; freq.opt.& BBmodule req. | C25: SMW200A | D25: 1 | E25: 5020 | F25: =E25*D25 -> 5020
B26: Frequency range: 100 kHz to 7. 5 GHz, RF path A (HW opt.) | C26: SMW-B107 | D26: 1 | E26: 47133 | F26: =E26*D26 -> 47133
B27: Baseband main module, one I/Q path to RF section (HW opt.) | C27: SMW-B13 | D27: 1 | E27: 2503 | F27: =E27*D27 -> 2503
B28: Baseband generator with realtime coder and ARB (HW opt.) | C28: SMW-B10 | D28: 1 | E28: 13385 | F28: =E28*D28 -> 13385
B29: 5G New Radio (SL) | C29: SMW-K144 | D29: 1 | E29: 16059 | F29: =E29*D29 -> 16059
A30: 4 | B30: Suy hao | C30: PE7213-30 | D30: 1 | F30: =1.1*752 -> 827.2 | G30: =F30*D30 -> 827.2 | H30: Mua mới | I30: https://www.pasternack.com/30db-fixed-n-male-n-female-100-watts-attenuator-pe7213-30-p.aspx | J30: 30 dB Fixed Attenuator, N Male To N Female Directional Black Anodized Aluminum Heatsink Body Rated To 100 Watts Up To 6 GHz
A31: 5 | B31: Connector TMA-A Plug to SMA Femal | I31: Không có thông tin về loại cáp này
A32: 6 | B32: Cable SMA Male To N Male 12 inch | C32: PE354-12 | D32: 1 | F32: =1.1*161 -> 177.1 | G32: =F32*D32 -> 177.1 | H32: Mua mới | I32: https://www.pasternack.com/sma-male-n-male-pe-p141-cable-assembly-pe354-12-p.aspx | J32: SMA Male to N Male Cable 12 Inch Length Using PE-P141 Coax with HeatShrink, LF Solder, RoHS
A33: 7 | B33: Cable SMA Male To N Male 24 inch | C33: PE354-24 | D33: 1 | F33: =1.1*172 -> 189.2 | G33: =F33*D33 -> 189.2 | H33: Mua mới | I33: https://www.pasternack.com/sma-male-n-male-pe-p141-cable-assembly-pe354-24-p.aspx | J33: SMA Male to N Male Cable 24 Inch Length Using PE-P141 Coax with HeatShrink, LF Solder, RoHS
A34: 8 | B34: Notch Filter | C34: Notch Filter DL Band n78 (3300-3800) | D34: 5 | F34: =1.1*2090 -> 2299 | G34: =F34*D34 -> 11495 | H34: Mua mới | I34: Cần xác định rõ dải tần, band và băng thông đo để mua bộ Notch Filter phù hợp. Không có 1 bộ cho full band | J34: TUNABLE BAND REJECT / NOTCH FILTERS FOR 5G NR DL BAND N78 (3300-3800 MHZ) Tuning Range 3000 to 4000 MHz Slopes 7 MHz Bandwidth 10 MHz Attenuation 40 dB min.
A35: 9 | B35: Switch RF | C35: ZTVX-16-18-s | D35: 3 | F35: =1.1*17000 -> 18700 | G35: =F35*D35 -> 56100 | H35: Mua mới | J35: 2 by 16 Switch Matrix, 50Ω, USB and Ethernet-TCP/IP control interface, Windows environments Software support
A36: 10 | B36: Jig cơ khí
A37: 11 | B37: Hybrid combiner | C37: ZFRSC-4-842-S+ | D37: 1 | F37: =1.1*170 -> 187 | G37: =F37*D37 -> 187 | H37: Mua mới | J37: 4-way Connectorized Power Splitter, DC-8400MHz
A38: 12 | B38: Circulator | C38: PE83CR1004 | D38: 1 | F38: =1.1*651 -> 716.1 | G38: =F38*D38 -> 716.1 | H38: Mua mới | J38: High Power Circulator With 20 dB Isolation From 2 GHz to 4 GHz, 50 Watts And SMA Female
C39: PE83CR1000 | D39: 1 | F39: =1.1*1155 -> 1270.5 | G39: =F39*D39 -> 1270.5 | H39: Mua mới | I39: https://www.pasternack.com/high-power-circulator-18db-isolation-2-ghz-50-watts-sma-female-pe83cr1000-p.aspx | J39: High Power Circulator with 18 dB Isolation from 1 GHz to 2 GHz, 50 Watts and SMA Female
A41: 2 | B41: CHAPTER 7
A42: TT | B42: Loại máy | C42: Model | D42: Số lượng | E42: Đơn giá | G42: Tổng giá | H42: Hạng mục | I42: Ghi chú | J42: Cấu hình
...

Sheet PL_chi phi giam sat
A3: Căn cứ Mục IX: Hướng dẫn áp dụng định mức chi phí giám sát- quyết định 79/QĐ-BXD
B24: Công thức nội suy định mức | H24: Áp dụng theo hướng dẫn của Quyết định 79/ QĐ-BXD- Loại công trình công nghiệp
H25: Chi phí trang thiết bị và công dụng cụ | I25: ='Tong muc dau tu'!E8/1000000000 -> 0
H26: Cận dưới | I26: =F36 -> 100 | J26: 0.811
H27: Cận trên | I27: =F35 -> 200 | J27: 0.49
H28: Nt | J28: =(J27-(J27-J26)*(I27-I25)/(I27-I26))% -> 0.01132
B32: Trong đó:
B33: Nt | C33: Định mức cần tính | F33: ?
B34: Ct | C34: Chi phí | F34: ='Tong muc dau tu'!E8/1000000000 -> 0
B35: Ca | C35: Cận trên | F35: 200
B36: Cb | C36: Cận dưới | F36: 100
B37: Na | C37: Định mức chi phí tương ứng Ca | F37: 0.49
B38: Nb | C38: Định mức chi phí tương ứng Cb | F38: 0.422

Sheet 2.Qlgs va cac chi phi khac
A2: PHỤ LỤC 2:
A3: CHI PHÍ QUẢN LÝ, CHI PHÍ TƯ VẤN VÀ CÁC CHI PHÍ KHÁC
A4: (Kèm theo Báo cáo đề xuất chủ trương đầu tư “”)
J6: ĐVT: VNĐ
A7: TT | B7: Khoản mục | C7: ĐVT | D7: Số lượng | E7: Đơn giá | F7: Thành tiền (chưa VAT) | G7: Tỷ suất VAT | H7: Thuế VAT | I7: Thành tiền (đã có VAT) | J7: Ghi chú
A8: 1 | B8: Chi phí quản lý dự án | C8: Gói | D8: 1
A9: 2 | B9: Chi phí kiểm toán | C9: Gói | D9: 1
A10: 3 | B10: Chi phí thẩm tra quyết toán | C10: Gói | D10: 1
B11: Tổng cộng

Sheet PL_Kiem toan
B3: A | C3: Tính chi phí kiểm toán
C5: Mức đầu tư | D5: Gi | E5: ='Tong muc dau tu'!H17/1000000000 -> 0 | F5: tỷ đồng
C6: Định mức chi phí ktoan cận trên | D6: Ka | E6: 0.45
C7: Định mức chi phí ktoan cận dưới | D7: Kb | E7: 0.645
C8: Tổng mức đầu tư dự án cận trên | D8: Ga | E8: 50
C9: Tổng mức đầu tư dự án cận dưới | D9: Gb | E9: 10
B10: Tính | C10: (Kb-Ka) | D10: Kb-Ka | E10: =E7-E6 -> 0.195
C11: Gi-Gb (đầu tư- cận dưới) | D11: Gi-Gb | E11: =E5-E9 -> -10
C12: Ga-Gb (cận trên - cận dưới) | D12: Ga-Gb | E12: =E8-E9 -> 40
C13: (Kb-Ka)*(Gi-Ga)/(Ga-Gb) | D13: (Kb-Ka)*(Gi-Ga)/(Ga-Gb) | E13: =(E10*E11)/E12 -> -0.04875
C14: Ki | D14: Ki | E14: =E7-E13 -> 0.69375 | F14: đơn vị %
C15: Chi phí kiểm toán | E15: =E14*E5/100 -> 0 | F15: tỷ đồng
C17: Tổng mức chi phí kiểm toán chưa gồm VAT | E17: =SUM(E15:E16) -> 0
C18: Thiết bị >51% (kiểm toán = 70%, hệ số 0,7) | E18: =0.7*E15 -> 0 | F18: tỷ đồng
C19: Chi phí kiểm toán (chưa tính VAT) | E19: =0.7*E17 -> 0 | F19: tỷ đồng
E20: =E14/100*0.7*'Tong muc dau tu'!G19 -> 0
B26: A | C26: Tính chi phí thẩm tra, phê duyệt quyết toán
C28: Mức đầu tư | D28: Gi | E28: =E5 -> 0 | F28: tỷ đồng
C29: Định mức chi phí thẩm tra cận trên | D29: Ka | E29: 0.285
C30: Định mức chi phí thẩm tra cận dưới | D30: Kb | E30: 0.39
C31: Tổng mức đầu tư dự án cận trên | D31: Ga | E31: =E8 -> 50
C32: Tổng mức đầu tư dự án cận dưới | D32: Gb | E32: =E9 -> 10
B33: Tính | C33: (Kb-Ka) | D33: Kb-Ka | E33: =E30-E29 -> 0.105
C34: Gi-Gb (đầu tư- cận dưới) | D34: Gi-Gb | E34: =E28-E32 -> -10
C35: Ga-Gb (cận trên - cận dưới) | D35: Ga-Gb | E35: =E31-E32 -> 40
C36: (Kb-Ka)*(Gi-Ga)/(Ga-Gb) | D36: (Kb-Ka)*(Gi-Ga)/(Ga-Gb) | E36: =(E33*E34)/E35 -> -0.02625
C37: Ki | D37: Ki | E37: =E30-E36 -> 0.41625
C38: Chi phí thẩm tra quyết toán (tính toán) | E38: =E37*E28/100 -> 0 | F38: tỷ đồng
C39: Thiết bị >51% (kiểm toán = 70%, hệ số 0,7) | E39: 0.7
C40: Trường hợp dự án đã kiểm toán chi phí thẩm tra quyết toán bằng 50% (Hệ số 0,5) | E40: 0.5
C41: Chi phí thẩm tra quyết toán thực tế | E41: =E38*E39*E40 -> 0 | F41: tỷ đồng
C42: Tổng chi phí thẩm tra quyết toán | E42: =E41 -> 0

Sheet PL_Quan ly du an
B31: Công thức nội suy định mức | H31: Vận dụng theo Thông tư số 12/2021/TT-BXD ngày 31/8/2021 của Bộ Xây dựng Ban hành định mức xây dựng
H32: Chi phí trang thiết bị và công dụng cụ | M32: =F41 -> 0
H33: Cận dưới | M33: 20 | N33: =F45 -> 2.461
H34: Cận trên | M34: =F42 -> 50 | N34: =F44 -> 2.198
H35: Nt (Trước hs k) | N35: =(N34-(N34-N33)*(M34-M32)/(M34-M33))% -> 0.026363333
H36: Hệ số K (*) (**) | N36: =0.8*0.8 -> 0.64
H37: Nt (Sau hs k) | N37: =N35*N36 -> 0.016872533
B39: Trong đó: | H39: (*) Chủ đầu tư sử dụng bộ máy chuyên môn trực thuộc để trực tiếp quản lý dựa án
B40: Nt | C40: Định mức cần tính | F40: ? | H40: (**) Tổng chi phí thiết bị chiếm tỷ trọng >50% tổng mức đầu tư
B41: Gt | C41: Chi phí | F41: ='Tong muc dau tu'!E8/1000000000 -> 0
B42: Ga | C42: Cận trên | F42: 50
B43: Gb | C43: Cận dưới | F43: 20
B44: Na | C44: Định mức chi phí tương ứng Ca | F44: 2.198 | G44: Công trình hạ tầng kỹ thuật
B45: Nb | C45: Định mức chi phí tương ứng Cb | F45: 2.461

Sheet Nhu cau von
B1: NHU CẦU SỬ DỤNG VỐN THEO TIẾN ĐỘ DỰ KIẾN
F3: ĐVT: VNĐ
A4: STT | B4: Nội dung | C4: Quý II/2024 | D4: Quý I/2025 | E4: Quý II/2025 | F4: Quý III/2025 | G4: Quý IV/2025
A5: 1 | B5: Chi phí thiết bị đo và dự phòng thiết bị đo | C5: 0.1 | D5: 0.3 | F5: 0.6
B6: =ROUND('Tong muc dau tu'!G8*1.05,0) -> 0 | C6: =ROUND(C5*B6,0) -> 0 | D6: =ROUND(('Tong muc dau tu'!G9+'Tong muc dau tu'!G10+'Tong muc dau tu'!G11+'Tong muc dau tu'!G12)*D5*1.05,0) -> 0 | E6: =ROUND(B6*D5-D6,0) -> 0 | F6: =ROUND(('Tong muc dau tu'!G9+'Tong muc dau tu'!G10+'Tong muc dau tu'!G11+'Tong muc dau tu'!G12)*F5*1.05,0) -> 0 | G6: =ROUND(B6-C6-D6-E6-F6,0) -> 0
A7: 2 | B7: Chi phí quản lý dự án và dự phòng | C7: 0.2 | D7: 0.2 | E7: 0.2 | F7: 0.2 | G7: 0.2
B8: =ROUNDUP('Tong muc dau tu'!G14*1.05,0) -> 0 | C8: =ROUND(C7*$B8,3) -> 0 | D8: =ROUND(D7*$B8,3) -> 0 | E8: =ROUND(E7*$B8,3) -> 0 | F8: =ROUND(F7*$B8,3) -> 0 | G8: =ROUND(G7*$B8,3) -> 0
A9: 3 | B9: Chi phí kiểm tra, thẩm tra quyết toán và dự phòng | C9: 0 | D9: 0 | E9: 0 | F9: 0.5 | G9: 0.5
B10: =ROUND('Tong muc dau tu'!G15*1.05,0) -> 0 | C10: =C9*B10 -> 0 | D10: =$B$10*D9 -> 0 | E10: =$B$10*E9 -> 0 | F10: =ROUND($B$10*F9,0) -> 0 | G10: =B10-F10 -> 0
A11: Tổng theo quý | C11: =ROUND(C6+C8+C10,0) -> 0 | D11: =ROUND(D6+D8+D10,0) -> 0 | E11: =ROUND(E6+E8+E10,0) -> 0 | F11: =ROUND(F6+F8+F10,0) -> 0 | G11: =ROUND(G6+G8+G10,0) -> 0
A12: Tổng dự án | F12: =SUM(C11:G11) -> 0
A14: Các mốc kế hoạch tương ứng | C14: Ký kết hợp đồng | D14: Hoàn thành lắp đặt | F14: Thanh quyết toán

Sheet So sanh giai phap
A1: STT | B1: Nội dung | C1: Yêu cầu | D1: Hãng 1 | L1: Hãng 2 | U1: USD | V1: 23600
D2: Tên máy | E2: Tên hãng | F2: Số lượng | H2: Đơn Giá (VNĐ) | I2: Thành Tiền (VNĐ) | K2: Ghi chú | L2: Tên máy | M2: Tên hãng | N2: Số lượng | O2: Đơn giá (Ngoại tệ) | P2: Đơn giá (VNĐ) | Q2: Thành Tiền (VNĐ) | T2: Ghi chú | U2: Euro | V2: 26650
A3: 1 | B3: Chương 6/3GPP | C3: Máy phát tín hiệu ghép nhiễu | D3: N9020A | E3: Keysight | F3: 1 | H3: 1750256500 | I3: =F3*H3 -> 1750256500 | K3: Nâng cấp | L3: FSW26 | M3: R&S | N3: 1 | P3: 4594509000 | Q3: =N3*P3 -> 4594509000 | T3: Đầu tư mới
C4: Máy phân tích tín hiệu | D4: N5182B | E4: Keysight | F4: 1 | H4: 1799959000 | I4: =F4*H4 -> 1799959000 | K4: Nâng cấp | L4: SMW200A | M4: R&S | N4: 1 | P4: 2270700000 | Q4: =N4*P4 -> 2270700000 | T4: Nâng cấp
A5: 2 | B5: Chương 7/3GPP | C5: Máy phát tín hiệu | D5: N5182B | E5: Keysight | F5: 2 | H5: 1799959000 | I5: =F5*H5 -> 3599918000 | K5: Nâng cấp | L5: FSV13 | M5: R&S | N5: 1 | P5: 1058400000 | Q5: =N5*P5 -> 1058400000 | T5: Nâng cấp
L6: SMW200A | M6: R&S | N6: 1 | P6: 4442310000 | Q6: =N6*P6 -> 4442310000 | T6: Nâng cấp
L7: SGS100A | M7: R&S | N7: 1 | P7: 1026000000 | Q7: =N7*P7 -> 1026000000 | T7: Đầu tư mới
A8: 3 | B8: Chương 8/3GPP | C8: Hệ thống đo kiểm hiệu năng | D8: TX MIMO | E8: Keysight | F8: 1 | H8: 28818379000 | I8: =F8*H8 -> 28818379000 | K8: Nâng cấp | L8: SMW200A | M8: R&S | N8: 1 | P8: 7316595000 | Q8: =N8*P8 -> 7316595000 | T8: Nâng cấp
D9: RX MIMO | E9: Keysight | F9: 1 | H9: 8742963500 | I9: =F9*H9 -> 8742963500 | K9: Nâng cấp | L9: SMW200A | M9: R&S | N9: 1 | P9: 11526624000 | Q9: =N9*P9 -> 11526624000 | T9: Đầu tư mới
J10: + HW upgrade_N9020AK-MTP_Multi-touch User Interface + FW_upgrade_N9085EM0E_Ứng dụng đo kiểm 5G NR + Support: R-Y5C-001-A, R-Y5C-001-L : 12 tháng hỗ trợ | L10: SGT100A | M10: R&S | N10: 2 | P10: 856764000 | Q10: =N10*P10 -> 1713528000 | R10: + HW_upgrade_FSV-K144/VSE-K144 + FSV-B160 Nâng cấp lên 160 MHz + FW_upgrade_ Thông tin đang cập nhật | S10: 4G & 5G | T10: Nhu cầu cần 4 chiếc, trong đó đã có 2 chiếc và cần đầu tư mới 2 chiếc nữa
J11: (Software update only, hardware is not updatable) | R11: (Software update only, hardware is not updatable) | S11: 4G & 5G
I17: =SUM(I3:I9) -> 44711476000 | Q17: =SUM(Q7:Q10,Q5,Q3) -> 27235656000
I32: TỔNG CÔNG TY VHT

Sheet SS giai phap
A1: STT | B1: Yêu cầu | C1: Hãng Keysight | N1: STT | O1: Yêu cầu | P1: Hãng R&S | Z1: USD | AA1: 23600
C2: Tên máy | D2: Tên hãng | E2: Số lượng | G2: Đơn Giá (VNĐ) | H2: Thành Tiền (VNĐ) | I2: Máy mới tương đương | J2: Số lượng | K2: Đơn Giá mua mới (VNĐ) | L2: Thành Tiền (VNĐ) | M2: Ghi chú | P2: Tên máy | Q2: Tên hãng | R2: Số lượng | S2: Đơn giá (VNĐ) | T2: Thành Tiền (VNĐ) | U2: Máy mới tương đương | V2: Số lượng | W2: Đơn Giá mua mới (VNĐ) | X2: Thành Tiền (VNĐ) | Y2: Ghi chú | Z2: Euro | AA2: 26650
A3: 1 | B3: Đáp ứng Chương 6/3GPP | C3: N9020A | D3: Keysight | E3: 1 | G3: 1750256500 | H3: =E3*G3 -> 1750256500 | I3: N9020B | J3: 1 | K3: 5151999000 | L3: =J3*K3 -> 5151999000 | M3: Đã có sẵn 1 máy cũ cho đo kiểm 4G | N3: 1 | O3: Đáp ứng Chương 6/3GPP | P3: FSW26 | Q3: R&S | R3: 1 | S3: 4594509000 | T3: =R3*S3 -> 4594509000 | Y3: Đầu tư mới
C4: N5182B | D4: Keysight | E4: 1 | G4: 1799959000 | H4: =E4*G4 -> 1799959000 | M4: Đã có sẵn 1 máy cũ cho đo kiểm 4G | P4: SMW200A | Q4: R&S | R4: 1 | S4: 2270700000 | T4: =R4*S4 -> 2270700000 | U4: SMW200A | V4: 1 | W4: 14402961000 | X4: =V4*W4 -> 14402961000 | Y4: Đã có sẵn 1 máy cũ cho đo kiểm 4G
